Workbook

Sheet Cover
A1: CADENCE DESIGN SYSTEMS (NASDAQ: CDNS) — DCF VALUATION & 3-STATEMENT OPERATING MODEL
A2: Prepared July 20, 2026 · $ millions except per-share · Calendar fiscal year
A4: CONTENTS
A5: Assumptions | C5: Scenario switch & levers (edit yellow cells)
A6: Historicals | C6: FY2022–FY2025 actuals, Q1-2026, FY2026E guidance build
A7: Model_3S | C7: Linked IS/BS/CF FY2026E–FY2035E: working capital, capex, debt schedule, buybacks, Hexagon acquisition
A8: WACC | C8: CAPM with current market data (beta 1.13, 10Y 4.55%)
A9: DCF | C9: Unlevered FCF, Gordon + exit-multiple terminal values, sensitivities
A10: Comps | C10: EDA / design-software peers (SNPS, ADSK, MSFT, ORCL)
A11: Precedents | C11: EDA & engineering-software M&A (Synopsys–Ansys, Siemens–Altair, Renesas–Altium…)
A12: LBO | C12: Leveraged buyout at 6.5x; max price at 15/20/25/30% IRR
A13: Monte_Carlo | C13: 500 live trials + scenario probability weights
A14: Football_Field | C14: Valuation summary chart vs. current price
A16: LEGEND
A17: Blue font / yellow fill | C17: Hardcoded input or scenario lever — edit these
A18: Black font | C18: Formula — do not overwrite
A19: Green font | C19: Link to another sheet
A20: 'e' | C20: Estimated figure — see notes
A22: KEY MODELING NOTES
A23: 1. | C23: FY2026E revenue $6,175mm = guidance midpoint ($6,125–6,225mm, ~17% growth incl. ~$160mm Hexagon contribution). Non-GAAP EPS guide $7.85–7.95.
A24: 2. | C24: The Hexagon acquisition is modeled as a $3.1B(e) FY2026 cash outflow landing in goodwill, funded partly by ~$0.6B(e) new debt — both editable inputs.
A25: 3. | C25: The model is GAAP-normalized: EBITDA excludes SBC (~8.5% of revenue, shown separately); consensus non-GAAP EPS adds SBC/amortization back, so it runs higher than model EPS.
A26: 4. | C26: Share price ambiguity at build time: stockanalysis.com stats imply ~$330 (mkt cap $91.05B / 275.8mm shares) while a same-week Zacks note quotes $373. $330.10 used — edit Assumptions!B49.
A28: KEY SOURCES
A29: Q1-2026 results & FY26 guidance (8-K, 4/27/2026) | C29: sec.gov/Archives/edgar/data/0000813672/000081367226000044/cfocommentary04272026ex9902.htm; tradingview 10-Q summary
A30: FY2025 results | C30: investor.cadence.com FY2025 press release: revenue $5,296.8mm, op income $1,649.8mm, net income $1,108.9mm
A31: FY2024 10-K | C31: sec.gov CDNS 10-K: debt $2.5B ('27 $0.5B / '29 $1B / '34 $1B); TA $8,974mm
A32: Market data | C32: stockanalysis.com/stocks/cdns/statistics (mkt cap $91.05B, 275.8mm shares, beta 1.13, cash $1.55B, debt $3.08B); macrotrends 52-wk $262.75–$416.69; 32-analyst avg target $387
A33: 10Y UST 4.55% (7/17/2026) | C33: tradingeconomics.com / FRED DGS10
A35: DISCLAIMER | C35: Educational model, not investment advice. Estimated cells flagged on-sheet; verify against Cadence filings.

Sheet Assumptions
A1: ASSUMPTIONS & SCENARIO LEVERS — CADENCE
A2: Edit yellow cells. Switch drives Model_3S, DCF, LBO, Monte Carlo.
A4: SCENARIO SWITCH (1 = Base, 2 = Bull, 3 = Bear) | B4: 1 | C4: =CHOOSE($B$4,"BASE — durable low-teens EDA growth","BULL — AI/agentic design supercycle","BEAR — semis downcycle + China restrictions") -> BASE — durable low-teens EDA growth
A6: Scenario probability weights
B7: Base | C7: Bull | D7: Bear | E7: Total
A8: Probability | B8: 0.5 | C8: 0.3 | D8: 0.2 | E8: =SUM(B8:D8) -> 1
A10: Revenue growth — decays linearly FY2027 → FY2035
B11: Base | C11: Bull | D11: Bear | E11: Selected
A12: FY2027 revenue growth | B12: 0.13 | C12: 0.17 | D12: 0.07 | E12: =CHOOSE($B$4,B12,C12,D12) -> 0.13
A13: FY2035 revenue growth (terminal-year) | B13: 0.08 | C13: 0.11 | D13: 0.03 | E13: =CHOOSE($B$4,B13,C13,D13) -> 0.08
A14: Base ≈ EDA secular growth (design activity, AI compute, backlog $8.0B). Bull +4pp; Bear −6pp. FY2026E = guidance $6,175mm.
A15: Operating drivers — FY2026 start ramps linearly to FY2035 target
A16: Driver | B16: FY26 start | C16: Base target | D16: Bull target | E16: Bear target | F16: Selected
A17: Gross margin (excl. D&A) | B17: 0.88 | C17: 0.89 | D17: 0.9 | E17: 0.87 | F17: =CHOOSE($B$4,C17,D17,E17) -> 0.89
A18: Cash opex — R&D + SG&A (% revenue) | B18: 0.425 | C18: 0.39 | D18: 0.355 | E18: 0.45 | F18: =CHOOSE($B$4,C18,D18,E18) -> 0.39
A19: Stock-based compensation (% revenue) | B19: 0.085 | C19: 0.07 | D19: 0.07 | E19: 0.08 | F19: =CHOOSE($B$4,C19,D19,E19) -> 0.07
A20: D&A incl. acquisition amortization (% revenue) | B20: 0.03 | C20: 0.03 | D20: 0.03 | E20: 0.03 | F20: =CHOOSE($B$4,C20,D20,E20) -> 0.03
A21: Capex incl. emulation hardware (% revenue) | B21: 0.03 | C21: 0.025 | D21: 0.03 | E21: 0.02 | F21: =CHOOSE($B$4,C21,D21,E21) -> 0.025
A22: Cash tax rate | B22: 0.2 | C22: 0.22 | D22: 0.22 | E22: 0.2 | F22: =CHOOSE($B$4,C22,D22,E22) -> 0.22
A23: Other current assets (% revenue) | B23: 0.11 | C23: 0.11 | D23: 0.11 | E23: 0.11 | F23: =CHOOSE($B$4,C23,D23,E23) -> 0.11
A24: Deferred revenue (% revenue) | B24: 0.155 | C24: 0.16 | D24: 0.16 | E24: 0.15 | F24: =CHOOSE($B$4,C24,D24,E24) -> 0.16
A25: Implied Adj. EBITDA margin (pre-SBC): FY26 45.5% (ties to ~43.5% non-GAAP op margin guide + D&A) → Base 50% / Bull 54.5% / Bear 42% by FY2035.
A26: Working capital (held constant)
A27: Days sales outstanding (DSO) | B27: 60
A28: Days inventory — emulation hardware (DIO, on COGS) | B28: 150
A29: Days payable (DPO, on COGS + cash opex) | B29: 45
A33: Capital & shareholder returns
A34: Interest earned on cash | B34: 0.04
A35: Revolver interest rate | B35: 0.06
A36: Minimum cash balance ($mm) | B36: 500
A37: Diluted shares outstanding (mm) | B37: 275.8
A38: Marginal tax rate (valuation) | B38: 0.22
A39: Average rate on debt | B39: 0.048
A40: Share buybacks per year ($mm) | B40: 1300
A41: Acquisitions FY2026 — Hexagon, net cash (e, $mm) | B41: 3100 | C41: Deal size estimated from disclosed $160mm revenue contribution and $0.28 EPS dilution incl. financing costs; edit when terms are confirmed
A42: New debt issued FY2026 (Hexagon financing, e, $mm) | B42: 600
A46: Terminal value & market inputs
A47: Terminal (perpetuity) growth rate g | B47: 0.035
A48: Exit EV / Adj. EBITDA multiple (FY2035) | B48: 20
A49: Current share price (7/17/2026, see Cover note 4) | B49: 330.1

Sheet Historicals
A1: HISTORICAL FINANCIALS ($mm)
B4: FY2022A | C4: FY2023A | D4: FY2024A | E4: FY2025A | G4: Q1-26A | H4: FY2026E
A5: Revenue | B5: 3562 | C5: 4090 | D5: 4641 | E5: 5297 | G5: 1474 | H5: 6175 | I5: FY2026E = guidance midpoint $6,125–6,225mm incl. ~$160mm Hexagon
A6: Operating income (GAAP) | D6: 1383 | E6: 1650
A7: Net income (GAAP) | D7: 1055 | E7: 1109
A8: % revenue growth y/y | C8: =C5/B5-1 -> 0.14823133 | D8: =D5/C5-1 -> 0.13471883 | E8: =E5/D5-1 -> 0.14134885 | H8: =H5/E5-1 -> 0.1657542
A10: Q1-26: revenue / GAAP EPS / non-GAAP EPS | B10: $1,474mm · $1.23 · $1.96 (+19% y/y)
A11: Backlog (Q1-26, record) | B11: $8.0B
A12: FY2026 non-GAAP EPS guidance | B12: $7.85 – $7.95 (incl. ~$0.28 Hexagon dilution)
A13: Debt (7/2026) | B13: $3.08B — '27 notes $0.5B, '29 $1.0B, '34 $1.0B + Hexagon financing (e)
A14: Cash (7/2026) | B14: $1.55B (stockanalysis.com)
A15: Non-GAAP operating margin FY2024 | B15: 42.5%
A17: Opening balance sheet, 12/31/2025 (partly estimated):
A18: Cash + short-term investments e | B18: 2800
A19: Receivables e | B19: 1650
A20: Inventory e | B20: 300
A21: Other current assets e | B21: 700
A22: PP&E net e | B22: 480
A23: Goodwill + intangibles + other LT e | B23: 4970
A24: AP + accrued e | B24: 900
A25: Deferred revenue e | B25: 950
A26: Total debt | B26: 2480
A27: Other LT liabilities e | B27: 1070
A29: FY2024 10-K anchors: TA $8,974mm, TL $4,301mm, equity $4,674mm, debt $2,476mm carrying. FY2025 items estimated from those + FY25 cash generation. Sources on Cover.

Sheet Model_3S
A1: 3-STATEMENT OPERATING MODEL — FY2026E–FY2035E ($mm)
A2: =CONCATENATE("Active scenario: ",CHOOSE(Assumptions!$B$4,"BASE","BULL","BEAR")) -> Active scenario: BASE
B4: FY2025A | C4: FY2026E | D4: FY2027E | E4: FY2028E | F4: FY2029E | G4: FY2030E | H4: FY2031E | I4: FY2032E | J4: FY2033E | K4: FY2034E | L4: FY2035E
A6: DRIVERS (linked to Assumptions; linear ramps FY26 → FY35)
A7: Revenue growth % | C7: =C18/B18-1 -> 0.1657542 | D7: =Assumptions!$E$12+(Assumptions!$E$13-Assumptions!$E$12)*0/8 -> 0.13 | E7: =Assumptions!$E$12+(Assumptions!$E$13-Assumptions!$E$12)*1/8 -> 0.12375 | F7: =Assumptions!$E$12+(Assumptions!$E$13-Assumptions!$E$12)*2/8 -> 0.1175 | G7: =Assumptions!$E$12+(Assumptions!$E$13-Assumptions!$E$12)*3/8 -> 0.11125 | H7: =Assumptions!$E$12+(Assumptions!$E$13-Assumptions!$E$12)*4/8 -> 0.105 | I7: =Assumptions!$E$12+(Assumptions!$E$13-Assumptions!$E$12)*5/8 -> 0.09875 | J7: =Assumptions!$E$12+(Assumptions!$E$13-Assumptions!$E$12)*6/8 -> 0.0925 | K7: =Assumptions!$E$12+(Assumptions!$E$13-Assumptions!$E$12)*7/8 -> 0.08625 | L7: =Assumptions!$E$12+(Assumptions!$E$13-Assumptions!$E$12)*8/8 -> 0.08
A8: Gross margin % | C8: =Assumptions!$B$17 -> 0.88 | D8: =Assumptions!$B$17+(Assumptions!$F$17-Assumptions!$B$17)*1/9 -> 0.88111111 | E8: =Assumptions!$B$17+(Assumptions!$F$17-Assumptions!$B$17)*2/9 -> 0.88222222 | F8: =Assumptions!$B$17+(Assumptions!$F$17-Assumptions!$B$17)*3/9 -> 0.88333333 | G8: =Assumptions!$B$17+(Assumptions!$F$17-Assumptions!$B$17)*4/9 -> 0.88444444 | H8: =Assumptions!$B$17+(Assumptions!$F$17-Assumptions!$B$17)*5/9 -> 0.88555556 | I8: =Assumptions!$B$17+(Assumptions!$F$17-Assumptions!$B$17)*6/9 -> 0.88666667 | J8: =Assumptions!$B$17+(Assumptions!$F$17-Assumptions!$B$17)*7/9 -> 0.88777778 | K8: =Assumptions!$B$17+(Assumptions!$F$17-Assumptions!$B$17)*8/9 -> 0.88888889 | L8: =Assumptions!$B$17+(Assumptions!$F$17-Assumptions!$B$17)*9/9 -> 0.89
A9: Cash opex % rev | C9: =Assumptions!$B$18 -> 0.425 | D9: =Assumptions!$B$18+(Assumptions!$F$18-Assumptions!$B$18)*1/9 -> 0.42111111 | E9: =Assumptions!$B$18+(Assumptions!$F$18-Assumptions!$B$18)*2/9 -> 0.41722222 | F9: =Assumptions!$B$18+(Assumptions!$F$18-Assumptions!$B$18)*3/9 -> 0.41333333 | G9: =Assumptions!$B$18+(Assumptions!$F$18-Assumptions!$B$18)*4/9 -> 0.40944444 | H9: =Assumptions!$B$18+(Assumptions!$F$18-Assumptions!$B$18)*5/9 -> 0.40555556 | I9: =Assumptions!$B$18+(Assumptions!$F$18-Assumptions!$B$18)*6/9 -> 0.40166667 | J9: =Assumptions!$B$18+(Assumptions!$F$18-Assumptions!$B$18)*7/9 -> 0.39777778 | K9: =Assumptions!$B$18+(Assumptions!$F$18-Assumptions!$B$18)*8/9 -> 0.39388889 | L9: =Assumptions!$B$18+(Assumptions!$F$18-Assumptions!$B$18)*9/9 -> 0.39
A10: SBC % rev | C10: =Assumptions!$B$19 -> 0.085 | D10: =Assumptions!$B$19+(Assumptions!$F$19-Assumptions!$B$19)*1/9 -> 0.083333333 | E10: =Assumptions!$B$19+(Assumptions!$F$19-Assumptions!$B$19)*2/9 -> 0.081666667 | F10: =Assumptions!$B$19+(Assumptions!$F$19-Assumptions!$B$19)*3/9 -> 0.08 | G10: =Assumptions!$B$19+(Assumptions!$F$19-Assumptions!$B$19)*4/9 -> 0.078333333 | H10: =Assumptions!$B$19+(Assumptions!$F$19-Assumptions!$B$19)*5/9 -> 0.076666667 | I10: =Assumptions!$B$19+(Assumptions!$F$19-Assumptions!$B$19)*6/9 -> 0.075 | J10: =Assumptions!$B$19+(Assumptions!$F$19-Assumptions!$B$19)*7/9 -> 0.073333333 | K10: =Assumptions!$B$19+(Assumptions!$F$19-Assumptions!$B$19)*8/9 -> 0.071666667 | L10: =Assumptions!$B$19+(Assumptions!$F$19-Assumptions!$B$19)*9/9 -> 0.07
A11: D&A % rev | C11: =Assumptions!$B$20 -> 0.03 | D11: =Assumptions!$B$20+(Assumptions!$F$20-Assumptions!$B$20)*1/9 -> 0.03 | E11: =Assumptions!$B$20+(Assumptions!$F$20-Assumptions!$B$20)*2/9 -> 0.03 | F11: =Assumptions!$B$20+(Assumptions!$F$20-Assumptions!$B$20)*3/9 -> 0.03 | G11: =Assumptions!$B$20+(Assumptions!$F$20-Assumptions!$B$20)*4/9 -> 0.03 | H11: =Assumptions!$B$20+(Assumptions!$F$20-Assumptions!$B$20)*5/9 -> 0.03 | I11: =Assumptions!$B$20+(Assumptions!$F$20-Assumptions!$B$20)*6/9 -> 0.03 | J11: =Assumptions!$B$20+(Assumptions!$F$20-Assumptions!$B$20)*7/9 -> 0.03 | K11: =Assumptions!$B$20+(Assumptions!$F$20-Assumptions!$B$20)*8/9 -> 0.03 | L11: =Assumptions!$B$20+(Assumptions!$F$20-Assumptions!$B$20)*9/9 -> 0.03
A12: Capex % rev | C12: =Assumptions!$B$21 -> 0.03 | D12: =Assumptions!$B$21+(Assumptions!$F$21-Assumptions!$B$21)*1/9 -> 0.029444444 | E12: =Assumptions!$B$21+(Assumptions!$F$21-Assumptions!$B$21)*2/9 -> 0.028888889 | F12: =Assumptions!$B$21+(Assumptions!$F$21-Assumptions!$B$21)*3/9 -> 0.028333333 | G12: =Assumptions!$B$21+(Assumptions!$F$21-Assumptions!$B$21)*4/9 -> 0.027777778 | H12: =Assumptions!$B$21+(Assumptions!$F$21-Assumptions!$B$21)*5/9 -> 0.027222222 | I12: =Assumptions!$B$21+(Assumptions!$F$21-Assumptions!$B$21)*6/9 -> 0.026666667 | J12: =Assumptions!$B$21+(Assumptions!$F$21-Assumptions!$B$21)*7/9 -> 0.026111111 | K12: =Assumptions!$B$21+(Assumptions!$F$21-Assumptions!$B$21)*8/9 -> 0.025555556 | L12: =Assumptions!$B$21+(Assumptions!$F$21-Assumptions!$B$21)*9/9 -> 0.025
A13: Cash tax rate % | C13: =Assumptions!$B$22 -> 0.2 | D13: =Assumptions!$B$22+(Assumptions!$F$22-Assumptions!$B$22)*1/9 -> 0.20222222 | E13: =Assumptions!$B$22+(Assumptions!$F$22-Assumptions!$B$22)*2/9 -> 0.20444444 | F13: =Assumptions!$B$22+(Assumptions!$F$22-Assumptions!$B$22)*3/9 -> 0.20666667 | G13: =Assumptions!$B$22+(Assumptions!$F$22-Assumptions!$B$22)*4/9 -> 0.20888889 | H13: =Assumptions!$B$22+(Assumptions!$F$22-Assumptions!$B$22)*5/9 -> 0.21111111 | I13: =Assumptions!$B$22+(Assumptions!$F$22-Assumptions!$B$22)*6/9 -> 0.21333333 | J13: =Assumptions!$B$22+(Assumptions!$F$22-Assumptions!$B$22)*7/9 -> 0.21555556 | K13: =Assumptions!$B$22+(Assumptions!$F$22-Assumptions!$B$22)*8/9 -> 0.21777778 | L13: =Assumptions!$B$22+(Assumptions!$F$22-Assumptions!$B$22)*9/9 -> 0.22
A14: Other current assets % rev | C14: =Assumptions!$B$23 -> 0.11 | D14: =Assumptions!$B$23+(Assumptions!$F$23-Assumptions!$B$23)*1/9 -> 0.11 | E14: =Assumptions!$B$23+(Assumptions!$F$23-Assumptions!$B$23)*2/9 -> 0.11 | F14: =Assumptions!$B$23+(Assumptions!$F$23-Assumptions!$B$23)*3/9 -> 0.11 | G14: =Assumptions!$B$23+(Assumptions!$F$23-Assumptions!$B$23)*4/9 -> 0.11 | H14: =Assumptions!$B$23+(Assumptions!$F$23-Assumptions!$B$23)*5/9 -> 0.11 | I14: =Assumptions!$B$23+(Assumptions!$F$23-Assumptions!$B$23)*6/9 -> 0.11 | J14: =Assumptions!$B$23+(Assumptions!$F$23-Assumptions!$B$23)*7/9 -> 0.11 | K14: =Assumptions!$B$23+(Assumptions!$F$23-Assumptions!$B$23)*8/9 -> 0.11 | L14: =Assumptions!$B$23+(Assumptions!$F$23-Assumptions!$B$23)*9/9 -> 0.11
A15: Deferred revenue % rev | C15: =Assumptions!$B$24 -> 0.155 | D15: =Assumptions!$B$24+(Assumptions!$F$24-Assumptions!$B$24)*1/9 -> 0.15555556 | E15: =Assumptions!$B$24+(Assumptions!$F$24-Assumptions!$B$24)*2/9 -> 0.15611111 | F15: =Assumptions!$B$24+(Assumptions!$F$24-Assumptions!$B$24)*3/9 -> 0.15666667 | G15: =Assumptions!$B$24+(Assumptions!$F$24-Assumptions!$B$24)*4/9 -> 0.15722222 | H15: =Assumptions!$B$24+(Assumptions!$F$24-Assumptions!$B$24)*5/9 -> 0.15777778 | I15: =Assumptions!$B$24+(Assumptions!$F$24-Assumptions!$B$24)*6/9 -> 0.15833333 | J15: =Assumptions!$B$24+(Assumptions!$F$24-Assumptions!$B$24)*7/9 -> 0.15888889 | K15: =Assumptions!$B$24+(Assumptions!$F$24-Assumptions!$B$24)*8/9 -> 0.15944444 | L15: =Assumptions!$B$24+(Assumptions!$F$24-Assumptions!$B$24)*9/9 -> 0.16
A17: INCOME STATEMENT
A18: Revenue | B18: =Historicals!E5 -> 5297 | C18: =Historicals!H5 -> 6175 | D18: =C18*(1+D7) -> 6977.75 | E18: =D18*(1+E7) -> 7841.2466 | F18: =E18*(1+F7) -> 8762.593 | G18: =F18*(1+G7) -> 9737.4315 | H18: =G18*(1+H7) -> 10759.862 | I18: =H18*(1+I7) -> 11822.398 | J18: =I18*(1+J7) -> 12915.97 | K18: =J18*(1+K7) -> 14029.972 | L18: =K18*(1+L7) -> 15152.37
A19: Cost of revenue (excl. D&A) | C19: =-C18*(1-C8) -> -741 | D19: =-D18*(1-D8) -> -829.57694 | E19: =-E18*(1-E8) -> -923.5246 | F19: =-F18*(1-F8) -> -1022.3025 | G19: =-G18*(1-G8) -> -1125.2143 | H19: =-H18*(1-H8) -> -1231.4064 | I19: =-I18*(1-I8) -> -1339.8718 | J19: =-J18*(1-J8) -> -1449.4589 | ... L19: =-L18*(1-L8) -> -1666.7607
A20: Gross profit | C20: =C18+C19 -> 5434 | D20: =D18+D19 -> 6148.1731 | E20: =E18+E19 -> 6917.722 | F20: =F18+F19 -> 7740.2905 | G20: =G18+G19 -> 8612.2172 | H20: =H18+H19 -> 9528.4554 | I20: =I18+I19 -> 10482.526 | J20: =J18+J19 -> 11466.511 | ... L20: =L18+L19 -> 13485.609
A21: Cash opex (R&D + SG&A) | C21: =-C18*C9 -> -2624.375 | D21: =-D18*D9 -> -2938.4081 | E21: =-E18*E9 -> -3271.5423 | F21: =-F18*F9 -> -3621.8718 | G21: =-G18*G9 -> -3986.9372 | H21: =-H18*H9 -> -4363.7217 | I21: =-I18*I9 -> -4748.6633 | J21: =-J18*J9 -> -5137.6858 | ... L21: =-L18*L9 -> -5909.4244
A22: Adjusted EBITDA (pre-SBC) | C22: =C20+C21 -> 2809.625 | D22: =D20+D21 -> 3209.765 | E22: =E20+E21 -> 3646.1797 | F22: =F20+F21 -> 4118.4187 | G22: =G20+G21 -> 4625.28 | H22: =H20+H21 -> 5164.7337 | I22: =I20+I21 -> 5733.8631 | J22: =J20+J21 -> 6328.8253 | ... L22: =L20+L21 -> 7576.1851
A23: Stock-based compensation | C23: =-C18*C10 -> -524.875 | D23: =-D18*D10 -> -581.47917 | E23: =-E18*E10 -> -640.36847 | F23: =-F18*F10 -> -701.00744 | G23: =-G18*G10 -> -762.76547 | H23: =-H18*H10 -> -824.92274 | I23: =-I18*I10 -> -886.67986 | J23: =-J18*J10 -> -947.17113 | ... L23: =-L18*L10 -> -1060.6659
A24: D&A incl. acquisition amortization | C24: =-C18*C11 -> -185.25 | D24: =-D18*D11 -> -209.3325 | E24: =-E18*E11 -> -235.2374 | F24: =-F18*F11 -> -262.87779 | G24: =-G18*G11 -> -292.12295 | H24: =-H18*H11 -> -322.79585 | I24: =-I18*I11 -> -354.67195 | J24: =-J18*J11 -> -387.4791 | ... L24: =-L18*L11 -> -454.57111
A25: EBIT | C25: =C22+C23+C24 -> 2099.5 | D25: =D22+D23+D24 -> 2418.9533 | E25: =E22+E23+E24 -> 2770.5738 | F25: =F22+F23+F24 -> 3154.5335 | G25: =G22+G23+G24 -> 3570.3916 | H25: =H22+H23+H24 -> 4017.0151 | I25: =I22+I23+I24 -> 4492.5113 | J25: =J22+J23+J24 -> 4994.1751 | ... L25: =L22+L23+L24 -> 6060.9481
A26: Interest income (on beginning cash) | C26: =B70*Assumptions!$B$34 -> 112 | D26: =C70*Assumptions!$B$34 -> 54.881528 | E26: =D70*Assumptions!$B$34 -> 97.371906 | F26: =E70*Assumptions!$B$34 -> 154.52671 | G26: =F70*Assumptions!$B$34 -> 227.89419 | H26: =G70*Assumptions!$B$34 -> 319.02901 | I26: =H70*Assumptions!$B$34 -> 429.46628 | J26: =I70*Assumptions!$B$34 -> 560.69304 | ... L26: =K70*Assumptions!$B$34 -> 891.03808
A27: Interest expense (beginning debt) | C27: =-(B50*Assumptions!$B$39+B54*Assumptions!$B$35) -> -119.04 | D27: =-(C50*Assumptions!$B$39+C54*Assumptions!$B$35) -> -147.84 | E27: =-(D50*Assumptions!$B$39+D54*Assumptions!$B$35) -> -147.84 | F27: =-(E50*Assumptions!$B$39+E54*Assumptions!$B$35) -> -147.84 | G27: =-(F50*Assumptions!$B$39+F54*Assumptions!$B$35) -> -147.84 | H27: =-(G50*Assumptions!$B$39+G54*Assumptions!$B$35) -> -147.84 | I27: =-(H50*Assumptions!$B$39+H54*Assumptions!$B$35) -> -147.84 | J27: =-(I50*Assumptions!$B$39+I54*Assumptions!$B$35) -> -147.84 | ... L27: =-(K50*Assumptions!$B$39+K54*Assumptions!$B$35) -> -147.84
A28: Pre-tax income | C28: =C25+C26+C27 -> 2092.46 | D28: =D25+D26+D27 -> 2325.9949 | E28: =E25+E26+E27 -> 2720.1057 | F28: =F25+F26+F27 -> 3161.2202 | G28: =G25+G26+G27 -> 3650.4457 | H28: =H25+H26+H27 -> 4188.2041 | I28: =I25+I26+I27 -> 4774.1376 | J28: =J25+J26+J27 -> 5407.0281 | ... L28: =L25+L26+L27 -> 6804.1462
A29: Taxes | C29: =-MAX(0,C28)*C13 -> -418.492 | D29: =-MAX(0,D28)*D13 -> -470.36785 | E29: =-MAX(0,E28)*E13 -> -556.1105 | F29: =-MAX(0,F28)*F13 -> -653.31884 | G29: =-MAX(0,G28)*G13 -> -762.53756 | H29: =-MAX(0,H28)*H13 -> -884.17642 | I29: =-MAX(0,I28)*I13 -> -1018.4827 | J29: =-MAX(0,J28)*J13 -> -1165.5149 | ... L29: =-MAX(0,L28)*L13 -> -1496.9122
A30: Net income (GAAP-normalized) | C30: =C28+C29 -> 1673.968 | D30: =D28+D29 -> 1855.627 | E30: =E28+E29 -> 2163.9952 | F30: =F28+F29 -> 2507.9014 | G30: =G28+G29 -> 2887.9082 | H30: =H28+H29 -> 3304.0277 | I30: =I28+I29 -> 3755.6549 | J30: =J28+J29 -> 4241.5132 | ... L30: =L28+L29 -> 5307.234
A31: EPS (constant shares; non-GAAP consensus is higher) | C31: =C30/Assumptions!$B$37 -> 6.0694996 | D31: =D30/Assumptions!$B$37 -> 6.7281618 | E31: =E30/Assumptions!$B$37 -> 7.846248 | F31: =F30/Assumptions!$B$37 -> 9.0931884 | G31: =G30/Assumptions!$B$37 -> 10.471023 | H31: =H30/Assumptions!$B$37 -> 11.979796 | I31: =I30/Assumptions!$B$37 -> 13.617313 | J31: =J30/Assumptions!$B$37 -> 15.378945 | ... L31: =L30/Assumptions!$B$37 -> 19.243053
A32: Adj. EBITDA margin % | C32: =C22/C18 -> 0.455 | D32: =D22/D18 -> 0.46 | E32: =E22/E18 -> 0.465 | F32: =F22/F18 -> 0.47 | G32: =G22/G18 -> 0.475 | H32: =H22/H18 -> 0.48 | I32: =I22/I18 -> 0.485 | J32: =J22/J18 -> 0.49 | ... L32: =L22/L18 -> 0.5
A34: WORKING CAPITAL
A35: Accounts receivable | B35: 1650 | C35: =C18*Assumptions!$B$27/365 -> 1015.0685 | D35: =D18*Assumptions!$B$27/365 -> 1147.0274 | E35: =E18*Assumptions!$B$27/365 -> 1288.972 | F35: =F18*Assumptions!$B$27/365 -> 1440.4263 | G35: =G18*Assumptions!$B$27/365 -> 1600.6737 | H35: =H18*Assumptions!$B$27/365 -> 1768.7444 | I35: =I18*Assumptions!$B$27/365 -> 1943.4079 | J35: =J18*Assumptions!$B$27/365 -> 2123.1732 | ... L35: =L18*Assumptions!$B$27/365 -> 2490.8006
A36: Inventory (emulation hardware) | B36: 300 | C36: =-C19*Assumptions!$B$28/365 -> 304.52055 | D36: =-D19*Assumptions!$B$28/365 -> 340.92203 | E36: =-E19*Assumptions!$B$28/365 -> 379.53066 | F36: =-F19*Assumptions!$B$28/365 -> 420.12432 | G36: =-G19*Assumptions!$B$28/365 -> 462.41684 | H36: =-H19*Assumptions!$B$28/365 -> 506.05743 | I36: =-I19*Assumptions!$B$28/365 -> 550.63224 | J36: =-J19*Assumptions!$B$28/365 -> 595.66802 | ... L36: =-L19*Assumptions!$B$28/365 -> 684.97016
A37: Other current assets | B37: 700 | C37: =C18*C14 -> 679.25 | D37: =D18*D14 -> 767.5525 | E37: =E18*E14 -> 862.53712 | F37: =F18*F14 -> 963.88523 | G37: =G18*G14 -> 1071.1175 | H37: =H18*H14 -> 1183.5848 | I37: =I18*I14 -> 1300.4638 | J37: =J18*J14 -> 1420.7567 | ... L37: =L18*L14 -> 1666.7607
A38: AP + accrued | B38: -900 | C38: =(C19+C21)*Assumptions!$B$29/365 -> -414.90925 | D38: =(D19+D21)*Assumptions!$B$29/365 -> -464.5461 | E38: =(E19+E21)*Assumptions!$B$29/365 -> -517.20003 | F38: =(F19+F21)*Assumptions!$B$29/365 -> -572.56944 | G38: =(G19+G21)*Assumptions!$B$29/365 -> -630.26526 | H38: =(H19+H21)*Assumptions!$B$29/365 -> -689.81032 | I38: =(I19+I21)*Assumptions!$B$29/365 -> -750.64131 | J38: =(J19+J21)*Assumptions!$B$29/365 -> -812.11373 | ... L38: =(L19+L21)*Assumptions!$B$29/365 -> -934.05022
A39: Deferred revenue | B39: -950 | C39: =-C18*C15 -> -957.125 | D39: =-D18*D15 -> -1085.4278 | E39: =-E18*E15 -> -1224.1057 | F39: =-F18*F15 -> -1372.8062 | G39: =-G18*G15 -> -1530.9406 | H39: =-H18*H15 -> -1697.6671 | I39: =-I18*I15 -> -1871.8797 | J39: =-J18*J15 -> -2052.2041 | ... L39: =-L18*L15 -> -2424.3792
A40: Net working capital | B40: =SUM(B35:B39) -> 800 | C40: =SUM(C35:C39) -> 626.80479 | D40: =SUM(D35:D39) -> 705.52806 | E40: =SUM(E35:E39) -> 789.73407 | F40: =SUM(F35:F39) -> 879.06013 | G40: =SUM(G35:G39) -> 973.0021 | H40: =SUM(H35:H39) -> 1070.9092 | I40: =SUM(I35:I39) -> 1171.9829 | ... L40: =SUM(L35:L39) -> 1484.102
A41: (Increase) / decrease in NWC — cash impact | C41: =-(C40-B40) -> 173.19521 | D41: =-(D40-C40) -> -78.723261 | E41: =-(E40-D40) -> -84.206016 | F41: =-(F40-E40) -> -89.326061 | G41: =-(G40-F40) -> -93.941966 | H41: =-(H40-G40) -> -97.907132 | I41: =-(I40-H40) -> -101.07371 | J41: =-(J40-I40) -> -103.29708 | ... L41: =-(L40-K40) -> -104.38129
A43: CAPEX & PP&E
A44: Capex | C44: =C18*C12 -> 185.25 | D44: =D18*D12 -> 205.45597 | E44: =E18*E12 -> 226.5249 | F44: =F18*F12 -> 248.27347 | G44: =G18*G12 -> 270.48421 | H44: =H18*H12 -> 292.90735 | I44: =I18*I12 -> 315.26395 | J44: =J18*J12 -> 337.25033 | ... L44: =L18*L12 -> 378.80926
A45: PP&E, net | B45: 480 | C45: =B45+C44+C24*0.4 -> 591.15 | D45: =C45+D44+D24*0.4 -> 712.87297 | E45: =D45+E44+E24*0.4 -> 845.30291 | F45: =E45+F44+F24*0.4 -> 988.42527 | G45: =F45+G44+G24*0.4 -> 1142.0603 | H45: =G45+H44+H24*0.4 -> 1305.8493 | I45: =H45+I44+I24*0.4 -> 1479.2445 | J45: =I45+J44+J24*0.4 -> 1661.5032 | ... L45: =K45+L44+L24*0.4 -> 2048.668 | M45: 60% of D&A assumed to be acquisition amortization (hits the goodwill/intangibles line), 40% depreciation of PP&E
...

Sheet WACC
A1: WEIGHTED AVERAGE COST OF CAPITAL — CURRENT MARKET DATA (JULY 2026)
A4: COST OF EQUITY (CAPM)
A5: Risk-free rate — 10Y UST, 7/17/2026 | B5: 0.0455 | C5: tradingeconomics.com / FRED DGS10
A6: Levered beta | B6: 1.13 | C6: stockanalysis.com statistics, July 2026
A7: Equity risk premium | B7: 0.0475 | C7: Damodaran implied ERP, mid-2026
A8: Company-specific premium | B8: 0
A9: Cost of equity | B9: =B5+B6*B7+B8 -> 0.099175
A11: COST OF DEBT
A12: Pre-tax cost of debt | B12: 0.048 | C12: Blended '27/'29/'34 notes + Hexagon financing
A13: Tax rate | B13: =Assumptions!B38 -> 0.22
A14: After-tax cost of debt | B14: =B12*(1-B13) -> 0.03744
A16: CAPITAL STRUCTURE (market weights)
A17: Debt / total capitalization | B17: 0.03 | C17: $3.08B debt vs ~$91B market cap
A18: Equity / total capitalization | B18: =1-B17 -> 0.97
A20: WACC | B20: =B18*B9+B17*B14 -> 0.09732295
A22: WACC ≈ 9.7%. Sensitivity range in DCF tables: 8.75% – 10.75%.

Sheet DCF
A1: DISCOUNTED CASH FLOW — UNLEVERED FCF ($mm; valuation as of FY2026 year-end, mid-year convention)
B4: FY2027E | C4: FY2028E | D4: FY2029E | E4: FY2030E | F4: FY2031E | G4: FY2032E | H4: FY2033E | I4: FY2034E | J4: FY2035E
A5: EBIT (post-SBC) | B5: =Model_3S!D25 -> 2418.9533 | C5: =Model_3S!E25 -> 2770.5738 | D5: =Model_3S!F25 -> 3154.5335 | E5: =Model_3S!G25 -> 3570.3916 | F5: =Model_3S!H25 -> 4017.0151 | G5: =Model_3S!I25 -> 4492.5113 | H5: =Model_3S!J25 -> 4994.1751 | I5: =Model_3S!K25 -> 5518.4558 | J5: =Model_3S!L25 -> 6060.9481
A6: Cash taxes on EBIT | B6: =-MAX(0,B5)*Model_3S!D13 -> -489.16612 | C6: =-MAX(0,C5)*Model_3S!E13 -> -566.42842 | D6: =-MAX(0,D5)*Model_3S!F13 -> -651.93692 | E6: =-MAX(0,E5)*Model_3S!G13 -> -745.81512 | F6: =-MAX(0,F5)*Model_3S!H13 -> -848.03652 | G6: =-MAX(0,G5)*Model_3S!I13 -> -958.40241 | H6: =-MAX(0,H5)*Model_3S!J13 -> -1076.5222 | I6: =-MAX(0,I5)*Model_3S!K13 -> -1201.797 | J6: =-MAX(0,J5)*Model_3S!L13 -> -1333.4086
A7: + D&A | B7: =-Model_3S!D24 -> 209.3325 | C7: =-Model_3S!E24 -> 235.2374 | D7: =-Model_3S!F24 -> 262.87779 | E7: =-Model_3S!G24 -> 292.12295 | F7: =-Model_3S!H24 -> 322.79585 | G7: =-Model_3S!I24 -> 354.67195 | H7: =-Model_3S!J24 -> 387.4791 | I7: =-Model_3S!K24 -> 420.89917 | J7: =-Model_3S!L24 -> 454.57111
A8: − Capex | B8: =-Model_3S!D44 -> -205.45597 | C8: =-Model_3S!E44 -> -226.5249 | D8: =-Model_3S!F44 -> -248.27347 | E8: =-Model_3S!G44 -> -270.48421 | F8: =-Model_3S!H44 -> -292.90735 | G8: =-Model_3S!I44 -> -315.26395 | H8: =-Model_3S!J44 -> -337.25033 | I8: =-Model_3S!K44 -> -358.54374 | J8: =-Model_3S!L44 -> -378.80926
A9: +/− Change in NWC | B9: =Model_3S!D41 -> -78.723261 | C9: =Model_3S!E41 -> -84.206016 | D9: =Model_3S!F41 -> -89.326061 | E9: =Model_3S!G41 -> -93.941966 | F9: =Model_3S!H41 -> -97.907132 | G9: =Model_3S!I41 -> -101.07371 | H9: =Model_3S!J41 -> -103.29708 | I9: =Model_3S!K41 -> -104.44071 | J9: =Model_3S!L41 -> -104.38129
A10: Unlevered free cash flow | B10: =SUM(B5:B9) -> 1854.9405 | C10: =SUM(C5:C9) -> 2128.6518 | D10: =SUM(D5:D9) -> 2427.8748 | E10: =SUM(E5:E9) -> 2752.2732 | F10: =SUM(F5:F9) -> 3100.9599 | G10: =SUM(G5:G9) -> 3472.4432 | H10: =SUM(H5:H9) -> 3864.5846 | I10: =SUM(I5:I9) -> 4274.5735 | J10: =SUM(J5:J9) -> 4698.9201
A11: Discount period (mid-year) | B11: 0.5 | C11: 1.5 | D11: 2.5 | E11: 3.5 | F11: 4.5 | G11: 5.5 | H11: 6.5 | I11: 7.5 | J11: 8.5
A12: Discount factor @ WACC | B12: =(1+$B$16)^-B11 -> 0.95462492 | C12: =(1+$B$16)^-C11 -> 0.86995804 | D12: =(1+$B$16)^-D11 -> 0.79280037 | E12: =(1+$B$16)^-E11 -> 0.72248591 | F12: =(1+$B$16)^-F11 -> 0.65840773 | G12: =(1+$B$16)^-G11 -> 0.60001272 | H12: =(1+$B$16)^-H11 -> 0.54679684 | I12: =(1+$B$16)^-I11 -> 0.49830074 | J12: =(1+$B$16)^-J11 -> 0.45410582
A13: PV of FCF | B13: =B10*B12 -> 1770.7724 | C13: =C10*C12 -> 1851.8378 | D13: =D10*D12 -> 1924.8201 | E13: =E10*E12 -> 1988.4786 | F13: =F10*F12 -> 2041.696 | G13: =G10*G12 -> 2083.5101 | H13: =H10*H12 -> 2113.1426 | I13: =I10*I12 -> 2130.0231 | J13: =J10*J12 -> 2133.807
A14: SBC deducted in EBIT (not added back) with a constant share count — conservative.
A15: Sum of PV of explicit FCF (FY27–35) | B15: =SUM(B13:J13) -> 18038.088
A16: WACC | B16: =WACC!B20 -> 0.09732295
A18: TERMINAL VALUE — METHOD 1: GORDON GROWTH
A19: Terminal growth g | B19: =Assumptions!B47 -> 0.035
A20: Terminal value | B20: =J10*(1+B19)/(B16-B19) -> 78035.174
A21: PV of terminal value (9.0 yrs) | B21: =B20/(1+B16)^9 -> 33828.306
A22: Implied exit EV/EBITDA | B22: =B20/Model_3S!L22 -> 10.300062
A24: TERMINAL VALUE — METHOD 2: EXIT MULTIPLE
A25: Exit EV/Adj. EBITDA multiple | B25: =Assumptions!B48 -> 20
A26: Terminal value | B26: =B25*Model_3S!L22 -> 151523.7
A27: PV of terminal value | B27: =B26/(1+B16)^9 -> 65685.636
A28: Implied perpetuity growth | B28: =(B16*B26-J10)/(B26+J10) -> 0.064317277
A30: ENTERPRISE → EQUITY VALUE BRIDGE
A31: Net debt, FY2026E year-end (debt − cash) | B31: =Model_3S!C55-Model_3S!C70 -> 1707.9618
A32: Diluted shares (mm) | B32: =Assumptions!B37 -> 275.8
B33: Gordon growth | C33: Exit multiple | D33: Average
A34: Enterprise value | B34: =B15+B21 -> 51866.393 | C34: =B15+B27 -> 83723.724 | D34: =AVERAGE(B34:C34) -> 67795.059
A35: − Net debt | B35: =-$B$31 -> -1707.9618 | C35: =-$B$31 -> -1707.9618 | D35: =-$B$31 -> -1707.9618
A36: Equity value | B36: =B34+B35 -> 50158.431 | C36: =C34+C35 -> 82015.762 | D36: =D34+D35 -> 66087.097
A37: Implied value per share | B37: =B36/$B$32 -> 181.86523 | C37: =C36/$B$32 -> 297.37405 | D37: =D36/$B$32 -> 239.61964
A38: Upside / (downside) vs current price | B38: =B37/Assumptions!$B$49-1 -> -0.44906018 | C38: =C37/Assumptions!$B$49-1 -> -0.099139512 | D38: =D37/Assumptions!$B$49-1 -> -0.27409985
A42: SENSITIVITY — VALUE PER SHARE: WACC × TERMINAL GROWTH (Gordon)
B43: WACC \ g | C43: 0.025 | D43: 0.03 | E43: 0.035 | F43: 0.04 | G43: 0.045
B44: 0.0875 | C44: =(SUMPRODUCT($B$10:$J$10,(1+$B$44)^-($B$11:$J$11))+$J$10*(1+C$43)/($B$44-C$43)/(1+$B$44)^9-$B$31)/$B$32 -> 193.35867 | D44: =(SUMPRODUCT($B$10:$J$10,(1+$B$44)^-($B$11:$J$11))+$J$10*(1+D$43)/($B$44-D$43)/(1+$B$44)^9-$B$31)/$B$32 -> 205.47558 | E44: =(SUMPRODUCT($B$10:$J$10,(1+$B$44)^-($B$11:$J$11))+$J$10*(1+E$43)/($B$44-E$43)/(1+$B$44)^9-$B$31)/$B$32 -> 219.90047 | F44: =(SUMPRODUCT($B$10:$J$10,(1+$B$44)^-($B$11:$J$11))+$J$10*(1+F$43)/($B$44-F$43)/(1+$B$44)^9-$B$31)/$B$32 -> 237.36218 | G44: =(SUMPRODUCT($B$10:$J$10,(1+$B$44)^-($B$11:$J$11))+$J$10*(1+G$43)/($B$44-G$43)/(1+$B$44)^9-$B$31)/$B$32 -> 258.93253
B45: 0.0925 | C45: =(SUMPRODUCT($B$10:$J$10,(1+$B$45)^-($B$11:$J$11))+$J$10*(1+C$43)/($B$45-C$43)/(1+$B$45)^9-$B$31)/$B$32 -> 177.25782 | D45: =(SUMPRODUCT($B$10:$J$10,(1+$B$45)^-($B$11:$J$11))+$J$10*(1+D$43)/($B$45-D$43)/(1+$B$45)^9-$B$31)/$B$32 -> 187.20772 | E45: =(SUMPRODUCT($B$10:$J$10,(1+$B$45)^-($B$11:$J$11))+$J$10*(1+E$43)/($B$45-E$43)/(1+$B$45)^9-$B$31)/$B$32 -> 198.88803 | F45: =(SUMPRODUCT($B$10:$J$10,(1+$B$45)^-($B$11:$J$11))+$J$10*(1+F$43)/($B$45-F$43)/(1+$B$45)^9-$B$31)/$B$32 -> 212.79316 | G45: =(SUMPRODUCT($B$10:$J$10,(1+$B$45)^-($B$11:$J$11))+$J$10*(1+G$43)/($B$45-G$43)/(1+$B$45)^9-$B$31)/$B$32 -> 229.62569
B46: 0.097 | C46: =(SUMPRODUCT($B$10:$J$10,(1+$B$46)^-($B$11:$J$11))+$J$10*(1+C$43)/($B$46-C$43)/(1+$B$46)^9-$B$31)/$B$32 -> 164.72272 | D46: =(SUMPRODUCT($B$10:$J$10,(1+$B$46)^-($B$11:$J$11))+$J$10*(1+D$43)/($B$46-D$43)/(1+$B$46)^9-$B$31)/$B$32 -> 173.14275 | E46: =(SUMPRODUCT($B$10:$J$10,(1+$B$46)^-($B$11:$J$11))+$J$10*(1+E$43)/($B$46-E$43)/(1+$B$46)^9-$B$31)/$B$32 -> 182.92084 | F46: =(SUMPRODUCT($B$10:$J$10,(1+$B$46)^-($B$11:$J$11))+$J$10*(1+F$43)/($B$46-F$43)/(1+$B$46)^9-$B$31)/$B$32 -> 194.41439 | G46: =(SUMPRODUCT($B$10:$J$10,(1+$B$46)^-($B$11:$J$11))+$J$10*(1+G$43)/($B$46-G$43)/(1+$B$46)^9-$B$31)/$B$32 -> 208.11824
B47: 0.1025 | C47: =(SUMPRODUCT($B$10:$J$10,(1+$B$47)^-($B$11:$J$11))+$J$10*(1+C$43)/($B$47-C$43)/(1+$B$47)^9-$B$31)/$B$32 -> 151.42866 | D47: =(SUMPRODUCT($B$10:$J$10,(1+$B$47)^-($B$11:$J$11))+$J$10*(1+D$43)/($B$47-D$43)/(1+$B$47)^9-$B$31)/$B$32 -> 158.37419 | E47: =(SUMPRODUCT($B$10:$J$10,(1+$B$47)^-($B$11:$J$11))+$J$10*(1+E$43)/($B$47-E$43)/(1+$B$47)^9-$B$31)/$B$32 -> 166.34869 | F47: =(SUMPRODUCT($B$10:$J$10,(1+$B$47)^-($B$11:$J$11))+$J$10*(1+F$43)/($B$47-F$43)/(1+$B$47)^9-$B$31)/$B$32 -> 175.5991 | G47: =(SUMPRODUCT($B$10:$J$10,(1+$B$47)^-($B$11:$J$11))+$J$10*(1+G$43)/($B$47-G$43)/(1+$B$47)^9-$B$31)/$B$32 -> 186.45829
B48: 0.1075 | C48: =(SUMPRODUCT($B$10:$J$10,(1+$B$48)^-($B$11:$J$11))+$J$10*(1+C$43)/($B$48-C$43)/(1+$B$48)^9-$B$31)/$B$32 -> 140.92387 | D48: =(SUMPRODUCT($B$10:$J$10,(1+$B$48)^-($B$11:$J$11))+$J$10*(1+D$43)/($B$48-D$43)/(1+$B$48)^9-$B$31)/$B$32 -> 146.81052 | E48: =(SUMPRODUCT($B$10:$J$10,(1+$B$48)^-($B$11:$J$11))+$J$10*(1+E$43)/($B$48-E$43)/(1+$B$48)^9-$B$31)/$B$32 -> 153.50912 | F48: =(SUMPRODUCT($B$10:$J$10,(1+$B$48)^-($B$11:$J$11))+$J$10*(1+F$43)/($B$48-F$43)/(1+$B$48)^9-$B$31)/$B$32 -> 161.20011 | G48: =(SUMPRODUCT($B$10:$J$10,(1+$B$48)^-($B$11:$J$11))+$J$10*(1+G$43)/($B$48-G$43)/(1+$B$48)^9-$B$31)/$B$32 -> 170.12166
...

Sheet Comps
A1: TRADING COMPARABLES — EDA / DESIGN SOFTWARE (July 2026; peer multiples estimated from public data)
A4: Company | B4: Ticker | C4: EV/Revenue | D4: EV/EBITDA | E4: Note
A5: Synopsys (incl. Ansys) | B5: SNPS | C5: 11 | D5: 28 | E5: e — closest comp; post-Ansys integration
A6: Autodesk | B6: ADSK | C6: 7 | D6: 25 | E6: e — design software, similar margin structure
A7: Microsoft | B7: MSFT | C7: 11.5 | D7: 22 | E7: e — mega-cap software quality benchmark
A8: Oracle | B8: ORCL | C8: 9 | D8: 18 | E8: e — mature enterprise software
A9: Cadence (self, current) | B9: CDNS | C9: =(Assumptions!B49*Assumptions!B37+DCF!B31)/Model_3S!C18 -> 15.020169 | D9: =(Assumptions!B49*Assumptions!B37+DCF!B31)/Model_3S!C22 -> 33.01136 | E9: computed below
A10: Peer median (ex-CDNS) | C10: =MEDIAN(C5:C8) -> 10 | D10: =MEDIAN(D5:D8) -> 23.5
A12: IMPLIED VALUE PER SHARE
A13: Method | B13: Low x | C13: High x | D13: Metric | E13: $/sh low | F13: $/sh high
A14: EV/Adj. EBITDA × FY2026E ($mm) | B14: 25 | C14: 35 | D14: =Model_3S!C22 -> 2809.625 | E14: =(B14*D14-DCF!$B$31)/Assumptions!$B$37 -> 248.48681 | F14: =(C14*D14-DCF!$B$31)/Assumptions!$B$37 -> 350.35864
A15: P/E × FY2026E non-GAAP EPS guide ($7.90) | B15: 35 | C15: 45 | D15: 7.9 | E15: =B15*D15 -> 276.5 | F15: =C15*D15 -> 355.5
A17: CDNS has traded 35-50x forward non-GAAP EPS for most of the AI-design cycle; band reflects that history and SNPS parity.

Sheet Precedents
A1: PRECEDENT TRANSACTIONS — EDA & ENGINEERING SOFTWARE M&A
A4: Date | B4: Acquirer | C4: Target | D4: EV ($mm) | E4: EV/Revenue | F4: Note
A5: Jan-2024 | B5: Synopsys | C5: Ansys | D5: 35000 | E5: 15.4 | F5: ~$2.27B revenue; closed 2025
A6: Oct-2024 | B6: Siemens | C6: Altair Engineering | D6: 10600 | E6: 15 | F6: e — simulation software
A7: Feb-2024 | B7: Renesas | C7: Altium | D7: 5900 | E7: 20 | F7: e — PCB design SaaS
A8: Mar-2024 | B8: Cadence | C8: BETA CAE | D8: 1240 | E8: 14 | F8: e — CAE simulation
A9: Nov-2016 | B9: Siemens | C9: Mentor Graphics | D9: 4500 | E9: 3.7 | F9: pre-AI-cycle EDA benchmark
A10: 2026 | B10: Cadence | C10: Hexagon (e) | D10: 3100 | E10: 19.4 | F10: e — implied from $160mm revenue contribution
A11: Median EV/Revenue | E11: =MEDIAN(E5:E10) -> 15.2
A13: APPLIED RANGE
A14: Modern EDA/engineering-software control deals cluster at 14–20x revenue — but those are for $1-35B targets. A CDNS takeover (~$100B+) has no real precedent; the band is applied at a size discount.
B15: Low | C15: High
A16: EV/Revenue applied to FY2026E | B16: 10 | C16: 15
A17: Implied EV | B17: =B16*Model_3S!C18 -> 61750 | C17: =C16*Model_3S!C18 -> 92625
A18: Implied value per share | B18: =(B17-DCF!$B$31)/Assumptions!$B$37 -> 217.70137 | C18: =(C17-DCF!$B$31)/Assumptions!$B$37 -> 329.64843

Sheet LBO
A1: LBO ANALYSIS — 5-YEAR HOLD (ENTRY END-FY2026, EXIT END-FY2031) ($mm)
A4: ENTRY & FINANCING
A5: Entry premium to current price | B5: 0.2
A6: Entry price per share | B6: =Assumptions!B49*(1+B5) -> 396.12
A7: Diluted shares (mm) | B7: =Assumptions!B37 -> 275.8
A8: Equity purchase price | B8: =B6*B7 -> 109249.9
A9: Plus: net debt assumed/refinanced | B9: =DCF!B31 -> 1707.9618
A10: Entry enterprise value | B10: =B8+B9 -> 110957.86
A11: Transaction fees (% of EV) | B11: 0.02
A12: FY2026E Adj. EBITDA (debt sizing basis) | B12: =Model_3S!C22 -> 2809.625
A13: Entry EV / EBITDA | B13: =B10/B12 -> 39.492052
A14: Debt tranche | B14: Multiple | C14: Rate | D14: Amount
A15: Term Loan B | B15: 4.5 | C15: 0.075 | D15: =B15*$B$12 -> 12643.312
A16: Senior notes | B16: 2 | C16: 0.09 | D16: =B16*$B$12 -> 5619.25
A17: Total new debt | B17: =B15+B16 -> 6.5 | D17: =D15+D16 -> 18262.562
A18: Sponsor equity = EV×(1+fees) − debt | B18: =B10*(1+B11)-D17 -> 94914.452
A20: DEBT PAYDOWN — 100% FCF SWEEP
B21: FY2027E | C21: FY2028E | D21: FY2029E | E21: FY2030E | F21: FY2031E
A22: Unlevered FCF (DCF sheet) | B22: =DCF!B10 -> 1854.9405 | C22: =DCF!C10 -> 2128.6518 | D22: =DCF!D10 -> 2427.8748 | E22: =DCF!E10 -> 2752.2732 | F22: =DCF!F10 -> 3100.9599
A23: Cash interest — TLB (beginning) | B23: =-$D$15*$C$15 -> -948.24844 | C23: =-B29*$C$15 -> -894.18579 | D23: =-C29*$C$15 -> -816.43212 | E23: =-D29*$C$15 -> -711.68814 | F23: =-E29*$C$15 -> -576.48675
A24: Cash interest — notes | B24: =-$D$16*$C$16 -> -505.7325 | C24: =-$D$16*$C$16 -> -505.7325 | D24: =-$D$16*$C$16 -> -505.7325 | E24: =-$D$16*$C$16 -> -505.7325 | F24: =-$D$16*$C$16 -> -505.7325
A25: Interest tax shield | B25: =-(B23+B24)*Assumptions!$B$38 -> 319.87581 | C25: =-(C23+C24)*Assumptions!$B$38 -> 307.98202 | D25: =-(D23+D24)*Assumptions!$B$38 -> 290.87622 | E25: =-(E23+E24)*Assumptions!$B$38 -> 267.83254 | F25: =-(F23+F24)*Assumptions!$B$38 -> 238.08824
A26: Levered FCF for paydown | B26: =MAX(0,B22+B23+B24+B25) -> 720.83535 | C26: =MAX(0,C22+C23+C24+C25) -> 1036.7156 | D26: =MAX(0,D22+D23+D24+D25) -> 1396.5864 | E26: =MAX(0,E22+E23+E24+E25) -> 1802.6851 | F26: =MAX(0,F22+F23+F24+F25) -> 2256.8289
A27: TLB — beginning | B27: =$D$15 -> 12643.312 | C27: =B29 -> 11922.477 | D27: =C29 -> 10885.762 | E27: =D29 -> 9489.1751 | F27: =E29 -> 7686.49
A28: TLB — (paydown) | B28: =-MIN(B27,B26) -> -720.83535 | C28: =-MIN(C27,C26) -> -1036.7156 | D28: =-MIN(D27,D26) -> -1396.5864 | E28: =-MIN(E27,E26) -> -1802.6851 | F28: =-MIN(F27,F26) -> -2256.8289
A29: TLB — ending | B29: =B27+B28 -> 11922.477 | C29: =C27+C28 -> 10885.762 | D29: =D27+D28 -> 9489.1751 | E29: =E27+E28 -> 7686.49 | F29: =F27+F28 -> 5429.6611
A30: Notes — ending (bullet) | B30: =$D$16 -> 5619.25 | C30: =$D$16 -> 5619.25 | D30: =$D$16 -> 5619.25 | E30: =$D$16 -> 5619.25 | F30: =$D$16 -> 5619.25
A31: Total debt — ending | B31: =B29+B30 -> 17541.727 | C31: =C29+C30 -> 16505.012 | D31: =D29+D30 -> 15108.425 | E31: =E29+E30 -> 13305.74 | F31: =F29+F30 -> 11048.911
A33: EXIT & RETURNS
A34: FY2031E Adj. EBITDA | B34: =Model_3S!H22 -> 5164.7337
A35: Exit EV/EBITDA multiple | B35: 20
A36: Exit enterprise value | B36: =B34*B35 -> 103294.67
A37: Less: exit net debt | B37: =-F31 -> -11048.911
A38: Exit equity value | B38: =B36+B37 -> 92245.762
A39: MOIC | B39: =B38/B18 -> 0.97188321
A40: IRR (5-yr) | B40: =(B38/B18)^(1/5)-1 -> -0.0056876916
A42: MAXIMUM ENTRY PRICE AT TARGET IRR THRESHOLDS (exit equity constant — debt sized on EBITDA, not price)
A43: Target IRR | B43: Max sponsor equity | C43: Implied entry EV | D43: Implied price/share | E43: Prem/(disc) to market
A44: 0.15 | B44: =$B$38/(1+A44)^5 -> 45862.447 | C44: =(B44+$D$17)/(1+$B$11) -> 62867.656 | D44: =(C44-$B$9)/$B$7 -> 221.75379 | E44: =D44/Assumptions!$B$49-1 -> -0.3282224
A45: 0.2 | B45: =$B$38/(1+A45)^5 -> 37071.503 | C45: =(B45+$D$17)/(1+$B$11) -> 54249.084 | D45: =(C45-$B$9)/$B$7 -> 190.50443 | E45: =D45/Assumptions!$B$49-1 -> -0.42288873
...

Sheet Monte_Carlo
A1: MONTE CARLO SIMULATION — 500 LIVE TRIALS (press F9 / recalc to refresh draws)
A2: Compact DCF per trial calibrated to the DCF sheet at base inputs; equity = PV(TV) + PV(FCF) − net debt.
A4: Distribution parameters — Normal(mean, σ)
A5: Variable | B5: Mean (linked) | C5: σ (input)
A6: FY2027 revenue growth | B6: =Assumptions!E12 -> 0.13 | C6: 0.03
A7: Terminal Adj. EBITDA margin (FY35) | B7: =Assumptions!F17-Assumptions!F18 -> 0.5 | C7: 0.03
A8: WACC | B8: =WACC!B20 -> 0.09732295 | C8: 0.0075
A9: Exit EV/EBITDA multiple | B9: =Assumptions!B48 -> 20 | C9: 3
A11: Calibration statics (linked)
A12: Base FY2035 Adj. EBITDA | B12: =Model_3S!L22 -> 7576.1851
A13: Base PV of explicit FCF (DCF) | B13: =DCF!B15 -> 18038.088
A14: Net debt FY2026E | B14: =DCF!B31 -> 1707.9618
A15: Diluted shares (mm) | B15: =Assumptions!B37 -> 275.8
A16: Current share price | B16: =Assumptions!B49 -> 330.1
A17: FY2035 growth (selected) | B17: =Assumptions!E13 -> 0.08
A18: FY2026E revenue | B18: =Model_3S!C18 -> 6175
A20: Simulation results ($/share)
A21: Mean | B21: =AVERAGE($K$41:$K$540) -> 295.07707
A22: Median | B22: =MEDIAN($K$41:$K$540) -> 289.98405
A23: Standard deviation | B23: =STDEV($K$41:$K$540) -> 61.182128
A24: 5th percentile | B24: =PERCENTILE($K$41:$K$540,0.05) -> 209.85822
A25: 25th percentile | B25: =PERCENTILE($K$41:$K$540,0.25) -> 251.32034
A26: 75th percentile | B26: =PERCENTILE($K$41:$K$540,0.75) -> 328.63057
A27: 95th percentile | B27: =PERCENTILE($K$41:$K$540,0.95) -> 403.9716
A28: P(value > current price) | B28: =COUNTIF($K$41:$K$540,">"&B16)/500 -> 0.244
A30: Scenario probability-weighted value (compact DCF per scenario)
A31: Scenario | B31: Probability | C31: Value / share
A32: Base | B32: =Assumptions!B8 -> 0.5 | C32: =($B$13*($B$18*(1+(Assumptions!B12+Assumptions!B13)/2)^9*(Assumptions!C17-Assumptions!C18))/$B$12+Assumptions!$B$48*($B$18*(1+(Assumptions!B12+Assumptions!B13)/2)^9*(Assumptions!C17-Assumptions!C18))/(1+$B$8)^9-$B$14)/$B$15 -> 297.66559
A33: Bull | B33: =Assumptions!C8 -> 0.3 | C33: =($B$13*($B$18*(1+(Assumptions!C12+Assumptions!C13)/2)^9*(Assumptions!D17-Assumptions!D18))/$B$12+Assumptions!$B$48*($B$18*(1+(Assumptions!C12+Assumptions!C13)/2)^9*(Assumptions!D17-Assumptions!D18))/(1+$B$8)^9-$B$14)/$B$15 -> 432.31858
A34: Bear | B34: =Assumptions!D8 -> 0.2 | C34: =($B$13*($B$18*(1+(Assumptions!D12+Assumptions!D13)/2)^9*(Assumptions!E17-Assumptions!E18))/$B$12+Assumptions!$B$48*($B$18*(1+(Assumptions!D12+Assumptions!D13)/2)^9*(Assumptions!E17-Assumptions!E18))/(1+$B$8)^9-$B$14)/$B$15 -> 155.01786
A35: Probability-weighted value | C35: =SUMPRODUCT(B32:B34,C32:C34) -> 309.53194
A39: TRIALS
A40: # | B40: g FY27 | C40: Term margin | D40: WACC | E40: Exit x | F40: Rev FY35 | G40: EBITDA FY35 | H40: PV(TV) | I40: PV(FCF) | J40: Equity | K40: $ / share | N40: Bin ($/sh) | O40: low | P40: high | Q40: Count
A41: 1 | B41: =NORMINV(RAND(),$B$6,$C$6) -> 0.12423542 | C41: =MAX(0.25,NORMINV(RAND(),$B$7,$C$7)) -> 0.48994198 | D41: =MAX(0.07,NORMINV(RAND(),$B$8,$C$8)) -> 0.10432478 | E41: =MAX(8,NORMINV(RAND(),$B$9,$C$9)) -> 18.751467 | F41: =$B$18*(1+(B41+$B$17)/2)^9 -> 14814.561 | G41: =F41*C41 -> 7258.2755 | H41: =E41*G41/(1+D41)^9 -> 55718.237 | I41: =$B$13*G41/$B$12*((1+$B$8)/(1+D41))^4.5 -> 16793.56 | J41: =H41+I41-$B$14 -> 70803.835 | K41: =J41/$B$15 -> 256.72166 | N41: <125 | O41: 100 | P41: 125 | Q41: =COUNTIF($K$41:$K$540,"<"&P41) -> 0
A42: 2 | B42: =NORMINV(RAND(),$B$6,$C$6) -> 0.14333475 | C42: =MAX(0.25,NORMINV(RAND(),$B$7,$C$7)) -> 0.52287731 | D42: =MAX(0.07,NORMINV(RAND(),$B$8,$C$8)) -> 0.093204242 | E42: =MAX(8,NORMINV(RAND(),$B$9,$C$9)) -> 18.767401 | F42: =$B$18*(1+(B42+$B$17)/2)^9 -> 16010.714 | G42: =F42*C42 -> 8371.6391 | H42: =E42*G42/(1+D42)^9 -> 70453.546 | I42: =$B$13*G42/$B$12*((1+$B$8)/(1+D42))^4.5 -> 20272.141 | J42: =H42+I42-$B$14 -> 89017.724 | K42: =J42/$B$15 -> 322.76187 | N42: 125-150 | O42: 125 | P42: 150 | Q42: =COUNTIFS($K$41:$K$540,">="&O42,$K$41:$K$540,"<"&P42) -> 1
A43: 3 | B43: =NORMINV(RAND(),$B$6,$C$6) -> 0.11887506 | C43: =MAX(0.25,NORMINV(RAND(),$B$7,$C$7)) -> 0.51268571 | D43: =MAX(0.07,NORMINV(RAND(),$B$8,$C$8)) -> 0.096340537 | E43: =MAX(8,NORMINV(RAND(),$B$9,$C$9)) -> 17.883727 | F43: =$B$18*(1+(B43+$B$17)/2)^9 -> 14493.457 | G43: =F43*C43 -> 7430.5884 | H43: =E43*G43/(1+D43)^9 -> 58072.695 | I43: =$B$13*G43/$B$12*((1+$B$8)/(1+D43))^4.5 -> 17762.888 | J43: =H43+I43-$B$14 -> 74127.621 | K43: =J43/$B$15 -> 268.7731 | N43: 150-175 | O43: 150 | P43: 175 | Q43: =COUNTIFS($K$41:$K$540,">="&O43,$K$41:$K$540,"<"&P43) -> 2
A44: 4 | B44: =NORMINV(RAND(),$B$6,$C$6) -> 0.13143866 | C44: =MAX(0.25,NORMINV(RAND(),$B$7,$C$7)) -> 0.49417952 | D44: =MAX(0.07,NORMINV(RAND(),$B$8,$C$8)) -> 0.11272974 | E44: =MAX(8,NORMINV(RAND(),$B$9,$C$9)) -> 22.471805 | F44: =$B$18*(1+(B44+$B$17)/2)^9 -> 15256.014 | G44: =F44*C44 -> 7539.2095 | H44: =E44*G44/(1+D44)^9 -> 64782.32 | I44: =$B$13*G44/$B$12*((1+$B$8)/(1+D44))^4.5 -> 16858.432 | J44: =H44+I44-$B$14 -> 79932.79 | K44: =J44/$B$15 -> 289.82157 | N44: 175-200 | O44: 175 | P44: 200 | Q44: =COUNTIFS($K$41:$K$540,">="&O44,$K$41:$K$540,"<"&P44) -> 13
A45: 5 | B45: =NORMINV(RAND(),$B$6,$C$6) -> 0.1115909 | C45: =MAX(0.25,NORMINV(RAND(),$B$7,$C$7)) -> 0.51254878 | D45: =MAX(0.07,NORMINV(RAND(),$B$8,$C$8)) -> 0.09724733 | E45: =MAX(8,NORMINV(RAND(),$B$9,$C$9)) -> 15.227909 | F45: =$B$18*(1+(B45+$B$17)/2)^9 -> 14067.029 | G45: =F45*C45 -> 7210.0386 | H45: =E45*G45/(1+D45)^9 -> 47625.23 | I45: =$B$13*G45/$B$12*((1+$B$8)/(1+D45))^4.5 -> 17171.656 | J45: =H45+I45-$B$14 -> 63088.924 | K45: =J45/$B$15 -> 228.74882 | N45: 200-225 | O45: 200 | P45: 225 | Q45: =COUNTIFS($K$41:$K$540,">="&O45,$K$41:$K$540,"<"&P45) -> 38
A46: 6 | B46: =NORMINV(RAND(),$B$6,$C$6) -> 0.098106629 | C46: =MAX(0.25,NORMINV(RAND(),$B$7,$C$7)) -> 0.46808953 | D46: =MAX(0.07,NORMINV(RAND(),$B$8,$C$8)) -> 0.088661927 | E46: =MAX(8,NORMINV(RAND(),$B$9,$C$9)) -> 22.149681 | F46: =$B$18*(1+(B46+$B$17)/2)^9 -> 13306.972 | G46: =F46*C46 -> 6228.8541 | H46: =E46*G46/(1+D46)^9 -> 64230.059 | I46: =$B$13*G46/$B$12*((1+$B$8)/(1+D46))^4.5 -> 15368.607 | J46: =H46+I46-$B$14 -> 77890.704 | K46: =J46/$B$15 -> 282.41735 | N46: 225-250 | O46: 225 | P46: 250 | Q46: =COUNTIFS($K$41:$K$540,">="&O46,$K$41:$K$540,"<"&P46) -> 68
A47: 7 | B47: =NORMINV(RAND(),$B$6,$C$6) -> 0.12155337 | C47: =MAX(0.25,NORMINV(RAND(),$B$7,$C$7)) -> 0.53613145 | D47: =MAX(0.07,NORMINV(RAND(),$B$8,$C$8)) -> 0.10814294 | E47: =MAX(8,NORMINV(RAND(),$B$9,$C$9)) -> 14.9526 | F47: =$B$18*(1+(B47+$B$17)/2)^9 -> 14653.115 | G47: =F47*C47 -> 7855.9959 | H47: =E47*G47/(1+D47)^9 -> 46618.242 | I47: =$B$13*G47/$B$12*((1+$B$8)/(1+D47))^4.5 -> 17896.381 | J47: =H47+I47-$B$14 -> 62806.661 | K47: =J47/$B$15 -> 227.72538 | N47: 250-275 | O47: 250 | P47: 275 | Q47: =COUNTIFS($K$41:$K$540,">="&O47,$K$41:$K$540,"<"&P47) -> 76
...

Sheet Football_Field
A1: FOOTBALL FIELD — VALUATION SUMMARY ($ per share)
A2: =CONCATENATE("Current price: $",TEXT(Assumptions!B49,"0.00")," · Scenario: ",CHOOSE(Assumptions!B4,"BASE","BULL","BEAR")," · Probability-weighted value: $",TEXT(Monte_Carlo!C35,"0.00")) -> Current price: $330.10 · Scenario: BASE · Probability-weighted value: $309.53
A4: Methodology | B4: Low | C4: High | D4: (base) | E4: (span) | F4: Midpoint
A5: 52-week trading range | B5: 262.75 | C5: 416.69 | D5: =B5 -> 262.75 | E5: =C5-B5 -> 153.94 | F5: =(B5+C5)/2 -> 339.72
A6: Analyst targets (avg $387, n=32; low e) | B6: 340 | C6: 432 | D6: =B6 -> 340 | E6: =C6-B6 -> 92 | F6: =(B6+C6)/2 -> 386
A7: DCF — Gordon growth (WACC ±0.5%, g 3.0–4.0%) | B7: =(SUMPRODUCT(DCF!$B$10:$J$10,(1+(WACC!$B$20+0.005))^-DCF!$B$11:$J$11)+DCF!$J$10*(1+0.03)/((WACC!$B$20+0.005)-0.03)/(1+(WACC!$B$20+0.005))^9-DCF!$B$31)/DCF!$B$32 -> 158.81377 | C7: =(SUMPRODUCT(DCF!$B$10:$J$10,(1+(WACC!$B$20-0.005))^-DCF!$B$11:$J$11)+DCF!$J$10*(1+0.04)/((WACC!$B$20-0.005)-0.04)/(1+(WACC!$B$20-0.005))^9-DCF!$B$31)/DCF!$B$32 -> 213.58189 | D7: =B7 -> 158.81377 | E7: =C7-B7 -> 54.768126 | F7: =(B7+C7)/2 -> 186.19783
A8: DCF — exit multiple (17.5–22.5x, WACC ±0.5%) | B8: =(SUMPRODUCT(DCF!$B$10:$J$10,(1+(WACC!$B$20+0.005))^-DCF!$B$11:$J$11)+17.5*Model_3S!$L$22/(1+(WACC!$B$20+0.005))^9-DCF!$B$31)/DCF!$B$32 -> 257.88444 | C8: =(SUMPRODUCT(DCF!$B$10:$J$10,(1+(WACC!$B$20-0.005))^-DCF!$B$11:$J$11)+22.5*Model_3S!$L$22/(1+(WACC!$B$20-0.005))^9-DCF!$B$31)/DCF!$B$32 -> 339.79604 | D8: =B8 -> 257.88444 | E8: =C8-B8 -> 81.911595 | F8: =(B8+C8)/2 -> 298.84024
A9: Trading comps — EV/EBITDA (25–35x FY26E) | B9: =Comps!E14 -> 248.48681 | C9: =Comps!F14 -> 350.35864 | D9: =B9 -> 248.48681 | E9: =C9-B9 -> 101.87183 | F9: =(B9+C9)/2 -> 299.42273
A10: Trading comps — P/E (35–45x FY26E non-GAAP EPS) | B10: =Comps!E15 -> 276.5 | C10: =Comps!F15 -> 355.5 | D10: =B10 -> 276.5 | E10: =C10-B10 -> 79 | F10: =(B10+C10)/2 -> 316
A11: Precedent transactions (10–15x FY26E revenue) | B11: =Precedents!B18 -> 217.70137 | C11: =Precedents!C18 -> 329.64843 | D11: =B11 -> 217.70137 | E11: =C11-B11 -> 111.94706 | F11: =(B11+C11)/2 -> 273.6749
A12: LBO capacity (25% → 15% IRR) | B12: =LBO!D46 -> 166.17445 | C12: =LBO!D44 -> 221.75379 | D12: =B12 -> 166.17445 | E12: =C12-B12 -> 55.579333 | F12: =(B12+C12)/2 -> 193.96412
A13: Monte Carlo P25–P75 (live) | B13: =Monte_Carlo!B25 -> 251.32034 | C13: =Monte_Carlo!B26 -> 328.63057 | D13: =B13 -> 251.32034 | E13: =C13-B13 -> 77.310232 | F13: =(B13+C13)/2 -> 289.97546
A14: Current price (marker) | B14: =Assumptions!B49-3 -> 327.1 | C14: =Assumptions!B49+3 -> 333.1 | D14: =B14 -> 327.1 | E14: =C14-B14 -> 6 | F14: =(B14+C14)/2 -> 330.1
A16: 52-wk range: macrotrends. Analyst target: 32-analyst avg $387, high $432 (Stifel); low end of band estimated. All other rows are live model outputs.
