Workbook

Sheet Cover
A1: SYNOPSYS, INC. (NASDAQ: SNPS) — DCF VALUATION & 3-STATEMENT OPERATING MODEL
A2: Prepared July 20, 2026 · $ millions except per-share · Fiscal year ends late October
A4: CONTENTS
A5: Assumptions | C5: Scenario switch & levers (edit yellow cells)
A6: Historicals | C6: FY2022–FY2025 actuals, Q2 FY2026, FY2026E guidance build
A7: Model_3S | C7: Linked IS/BS/CF FY2026E–FY2035E: working capital, capex, debt schedule with deleveraging, buybacks
A8: WACC | C8: CAPM with current market data (beta 1.24, 10Y 4.55%)
A9: DCF | C9: Unlevered FCF, Gordon + exit-multiple terminal values, sensitivities
A10: Comps | C10: EDA / design-software peers (CDNS primary)
A11: Precedents | C11: EDA & engineering-software M&A — including Synopsys–Ansys itself
A12: LBO | C12: Leveraged buyout at 6.5x; max price at 15/20/25/30% IRR
A13: Monte_Carlo | C13: 500 live trials + scenario probability weights
A14: Football_Field | C14: Valuation summary chart vs. current price
A16: LEGEND
A17: Blue font / yellow fill | C17: Hardcoded input or scenario lever — edit these
A18: Black font | C18: Formula — do not overwrite
A19: Green font | C19: Link to another sheet
A20: 'e' | C20: Estimated figure — see notes
A22: KEY MODELING NOTES
A23: 1. | C23: Ansys closed July 2025 ($35B): FY2026 is the first full year — guidance $9.665B revenue / $14.76 non-GAAP EPS at midpoints (raised at Q2). Net debt ~$8.7B from deal financing.
A24: 2. | C24: Deleveraging modeled: $1.0B/yr debt repayment FY2027–29 (editable issuance row); buybacks held at a token $300mm/yr until releveraged.
A25: 3. | C25: GAAP-normalized model: EBITDA excludes SBC (~9% of revenue); heavy Ansys acquisition amortization (~60% of D&A) burdens GAAP EPS — consensus non-GAAP EPS runs ~2x higher.
A26: 4. | C26: Pending divestiture of the Processor IP Solutions business is NOT modeled (terms undisclosed) — treat as modest upside to margins, downside to revenue.
A28: KEY SOURCES
A29: Q2 FY2026 results & raised guidance (5/27/2026) | C29: news.synopsys.com / prnewswire: Q2 rev $2,276mm (vs $1,604mm), non-GAAP EPS $3.35; FY26 guide $9,665mm / $14.76
A30: Market data | C30: stockanalysis.com/stocks/snps/statistics & investing.com 7/20/26: price $384.28, 191.56mm shares (mkt cap ≈ $73.6B computed; a $100.5B quote in circulation is stale), beta 1.24, cash $2.20B, debt $10.87B, 52-wk $366.00–$651.73, 19-analyst avg target $564 ($404–650)
A31: FY2025 revenue | C31: ~$7.0B(e) — FY ended Oct-2025 incl. ~1 quarter of Ansys; FY2024 $6,127mm, FY2023 $5,843mm, FY2022 $5,082mm
A32: 10Y UST 4.55% (7/17/2026) | C32: tradingeconomics.com / FRED DGS10
A34: DISCLAIMER | C34: Educational model, not investment advice. Estimated cells flagged on-sheet; verify against Synopsys filings.

Sheet Assumptions
A1: ASSUMPTIONS & SCENARIO LEVERS — SYNOPSYS
A2: Edit yellow cells. Switch drives Model_3S, DCF, LBO, Monte Carlo.
A4: SCENARIO SWITCH (1 = Base, 2 = Bull, 3 = Bear) | B4: 1 | C4: =CHOOSE($B$4,"BASE — EDA growth + Ansys synergies on plan","BULL — AI design supercycle + full synergy capture","BEAR — China/IP weakness persists, synergies slip") -> BASE — EDA growth + Ansys synergies on plan
A6: Scenario probability weights
B7: Base | C7: Bull | D7: Bear | E7: Total
A8: Probability | B8: 0.5 | C8: 0.25 | D8: 0.25 | E8: =SUM(B8:D8) -> 1
A10: Revenue growth — decays linearly FY2027 → FY2035 (organic; Ansys already in FY26 base)
B11: Base | C11: Bull | D11: Bear | E11: Selected
A12: FY2027 revenue growth | B12: 0.1 | C12: 0.14 | D12: 0.05 | E12: =CHOOSE($B$4,B12,C12,D12) -> 0.1
A13: FY2035 revenue growth (terminal-year) | B13: 0.06 | C13: 0.09 | D13: 0.02 | E13: =CHOOSE($B$4,B13,C13,D13) -> 0.06
A14: FY2026E revenue $9,665mm = raised guidance midpoint (first full Ansys year; growth vs FY25 is largely inorganic).
A15: Operating drivers — FY2026 start ramps linearly to FY2035 target
A16: Driver | B16: FY26 start | C16: Base target | D16: Bull target | E16: Bear target | F16: Selected
A17: Gross margin (excl. D&A) | B17: 0.8 | C17: 0.82 | D17: 0.83 | E17: 0.79 | F17: =CHOOSE($B$4,C17,D17,E17) -> 0.82
A18: Cash opex — R&D + SG&A (% revenue) | B18: 0.405 | C18: 0.35 | D18: 0.32 | E18: 0.38 | F18: =CHOOSE($B$4,C18,D18,E18) -> 0.35
A19: Stock-based compensation (% revenue) | B19: 0.09 | C19: 0.075 | D19: 0.075 | E19: 0.085 | F19: =CHOOSE($B$4,C19,D19,E19) -> 0.075
A20: D&A incl. Ansys amortization (% revenue) | B20: 0.06 | C20: 0.045 | D20: 0.045 | E20: 0.055 | F20: =CHOOSE($B$4,C20,D20,E20) -> 0.045
A21: Capex (% revenue) | B21: 0.015 | C21: 0.015 | D21: 0.018 | E21: 0.012 | F21: =CHOOSE($B$4,C21,D21,E21) -> 0.015
A22: Cash tax rate | B22: 0.2 | C22: 0.22 | D22: 0.22 | E22: 0.2 | F22: =CHOOSE($B$4,C22,D22,E22) -> 0.22
A23: Other current assets (% revenue) | B23: 0.1 | C23: 0.1 | D23: 0.1 | E23: 0.1 | F23: =CHOOSE($B$4,C23,D23,E23) -> 0.1
A24: Deferred revenue (% revenue) | B24: 0.21 | C24: 0.21 | D24: 0.21 | E24: 0.2 | F24: =CHOOSE($B$4,C24,D24,E24) -> 0.21
A25: Implied Adj. EBITDA margin (pre-SBC): FY26 39.5% → Base 47% / Bull 51% / Bear 41% by FY2035 (Ansys cost synergies ~halfway captured by FY26 year-end, per management).
A26: Working capital (held constant)
A27: Days sales outstanding (DSO) | B27: 70
A28: Days inventory — emulation hardware (DIO, on COGS) | B28: 120
A29: Days payable (DPO, on COGS + cash opex) | B29: 40
A33: Capital & shareholder returns
A34: Interest earned on cash | B34: 0.04
A35: Revolver interest rate | B35: 0.06
A36: Minimum cash balance ($mm) | B36: 800
A37: Diluted shares outstanding (mm) | B37: 191.6
A38: Marginal tax rate (valuation) | B38: 0.22
A39: Average rate on debt | B39: 0.052
A40: Share buybacks per year ($mm) | B40: 300 | C40: Buybacks minimal while deleveraging; $1.0B/yr repayments prefilled FY27–29 in the Model_3S issuance row (editable)
A41: Acquisitions FY2026, net cash ($mm) | B41: 0
A42: New debt issued FY2026 ($mm) | B42: 0
A46: Terminal value & market inputs
A47: Terminal (perpetuity) growth rate g | B47: 0.035
A48: Exit EV / Adj. EBITDA multiple (FY2035) | B48: 18
A49: Current share price (7/20/2026) | B49: 384.28

Sheet Historicals
A1: HISTORICAL FINANCIALS ($mm; FY ends late October)
B4: FY2022A | C4: FY2023A | D4: FY2024A | E4: FY2025A e | G4: Q2-26A | H4: FY2026E
A5: Revenue | B5: 5082 | C5: 5843 | D5: 6127 | E5: 7000 | G5: 2276 | H5: 9665 | I5: FY2026E = raised guidance midpoint; FY2025 estimated (~1 quarter of Ansys included)
A6: % growth y/y | C6: =C5/B5-1 -> 0.1497442 | D6: =D5/C5-1 -> 0.048605169 | E6: =E5/D5-1 -> 0.14248409 | H6: =H5/E5-1 -> 0.38071429
A8: Q2 FY26: revenue / non-GAAP EPS | B8: $2,276mm (vs $1,604mm Q2 FY25) · $3.35 (beat $3.15 consensus)
A9: FY2026 guidance (raised at Q2) | B9: Revenue $9,665mm mid · non-GAAP EPS $14.76 mid
A10: Ansys acquisition | B10: Closed July 2025, ~$35B EV (~15.4x revenue); ~50% of cost synergies expected captured by FY26 year-end
A11: Debt / cash (7/2026) | B11: $10.87B debt · $2.20B cash → net debt $8.67B
A12: Pending divestiture | B12: Processor IP Solutions business sale in progress (not modeled)
A15: Opening balance sheet, 10/31/2025 (estimated):
A16: Cash + short-term investments e | B16: 2400
A17: Receivables e | B17: 1900
A18: Inventory e | B18: 400
A19: Other current assets e | B19: 950
A20: PP&E net e | B20: 600
A21: Goodwill + intangibles + other LT e | B21: 38000
A22: AP + accrued e | B22: 1300
A23: Deferred revenue e | B23: 2000
A24: Total debt e | B24: 11500
A25: Other LT liabilities e | B25: 3500
A27: Post-Ansys balance sheet largely estimated (goodwill/intangibles ~$38B from the $35B deal). Equity is the balancing plug (~$26B, consistent with ~$16B stock consideration). Sources on Cover.

Sheet Model_3S
A1: 3-STATEMENT OPERATING MODEL — FY2026E–FY2035E ($mm; FY ends October)
A2: =CONCATENATE("Active scenario: ",CHOOSE(Assumptions!$B$4,"BASE","BULL","BEAR")) -> Active scenario: BASE
B4: FY2025A | C4: FY2026E | D4: FY2027E | E4: FY2028E | F4: FY2029E | G4: FY2030E | H4: FY2031E | I4: FY2032E | J4: FY2033E | K4: FY2034E | L4: FY2035E
A6: DRIVERS (linked to Assumptions; linear ramps FY26 → FY35)
A7: Revenue growth % | C7: =C18/B18-1 -> 0.38071429 | D7: =Assumptions!$E$12+(Assumptions!$E$13-Assumptions!$E$12)*0/8 -> 0.1 | E7: =Assumptions!$E$12+(Assumptions!$E$13-Assumptions!$E$12)*1/8 -> 0.095 | F7: =Assumptions!$E$12+(Assumptions!$E$13-Assumptions!$E$12)*2/8 -> 0.09 | G7: =Assumptions!$E$12+(Assumptions!$E$13-Assumptions!$E$12)*3/8 -> 0.085 | H7: =Assumptions!$E$12+(Assumptions!$E$13-Assumptions!$E$12)*4/8 -> 0.08 | I7: =Assumptions!$E$12+(Assumptions!$E$13-Assumptions!$E$12)*5/8 -> 0.075 | J7: =Assumptions!$E$12+(Assumptions!$E$13-Assumptions!$E$12)*6/8 -> 0.07 | K7: =Assumptions!$E$12+(Assumptions!$E$13-Assumptions!$E$12)*7/8 -> 0.065 | L7: =Assumptions!$E$12+(Assumptions!$E$13-Assumptions!$E$12)*8/8 -> 0.06
A8: Gross margin % | C8: =Assumptions!$B$17 -> 0.8 | D8: =Assumptions!$B$17+(Assumptions!$F$17-Assumptions!$B$17)*1/9 -> 0.80222222 | E8: =Assumptions!$B$17+(Assumptions!$F$17-Assumptions!$B$17)*2/9 -> 0.80444444 | F8: =Assumptions!$B$17+(Assumptions!$F$17-Assumptions!$B$17)*3/9 -> 0.80666667 | G8: =Assumptions!$B$17+(Assumptions!$F$17-Assumptions!$B$17)*4/9 -> 0.80888889 | H8: =Assumptions!$B$17+(Assumptions!$F$17-Assumptions!$B$17)*5/9 -> 0.81111111 | I8: =Assumptions!$B$17+(Assumptions!$F$17-Assumptions!$B$17)*6/9 -> 0.81333333 | J8: =Assumptions!$B$17+(Assumptions!$F$17-Assumptions!$B$17)*7/9 -> 0.81555556 | K8: =Assumptions!$B$17+(Assumptions!$F$17-Assumptions!$B$17)*8/9 -> 0.81777778 | L8: =Assumptions!$B$17+(Assumptions!$F$17-Assumptions!$B$17)*9/9 -> 0.82
A9: Cash opex % rev | C9: =Assumptions!$B$18 -> 0.405 | D9: =Assumptions!$B$18+(Assumptions!$F$18-Assumptions!$B$18)*1/9 -> 0.39888889 | E9: =Assumptions!$B$18+(Assumptions!$F$18-Assumptions!$B$18)*2/9 -> 0.39277778 | F9: =Assumptions!$B$18+(Assumptions!$F$18-Assumptions!$B$18)*3/9 -> 0.38666667 | G9: =Assumptions!$B$18+(Assumptions!$F$18-Assumptions!$B$18)*4/9 -> 0.38055556 | H9: =Assumptions!$B$18+(Assumptions!$F$18-Assumptions!$B$18)*5/9 -> 0.37444444 | I9: =Assumptions!$B$18+(Assumptions!$F$18-Assumptions!$B$18)*6/9 -> 0.36833333 | J9: =Assumptions!$B$18+(Assumptions!$F$18-Assumptions!$B$18)*7/9 -> 0.36222222 | K9: =Assumptions!$B$18+(Assumptions!$F$18-Assumptions!$B$18)*8/9 -> 0.35611111 | L9: =Assumptions!$B$18+(Assumptions!$F$18-Assumptions!$B$18)*9/9 -> 0.35
A10: SBC % rev | C10: =Assumptions!$B$19 -> 0.09 | D10: =Assumptions!$B$19+(Assumptions!$F$19-Assumptions!$B$19)*1/9 -> 0.088333333 | E10: =Assumptions!$B$19+(Assumptions!$F$19-Assumptions!$B$19)*2/9 -> 0.086666667 | F10: =Assumptions!$B$19+(Assumptions!$F$19-Assumptions!$B$19)*3/9 -> 0.085 | G10: =Assumptions!$B$19+(Assumptions!$F$19-Assumptions!$B$19)*4/9 -> 0.083333333 | H10: =Assumptions!$B$19+(Assumptions!$F$19-Assumptions!$B$19)*5/9 -> 0.081666667 | I10: =Assumptions!$B$19+(Assumptions!$F$19-Assumptions!$B$19)*6/9 -> 0.08 | J10: =Assumptions!$B$19+(Assumptions!$F$19-Assumptions!$B$19)*7/9 -> 0.078333333 | K10: =Assumptions!$B$19+(Assumptions!$F$19-Assumptions!$B$19)*8/9 -> 0.076666667 | L10: =Assumptions!$B$19+(Assumptions!$F$19-Assumptions!$B$19)*9/9 -> 0.075
A11: D&A % rev | C11: =Assumptions!$B$20 -> 0.06 | D11: =Assumptions!$B$20+(Assumptions!$F$20-Assumptions!$B$20)*1/9 -> 0.058333333 | E11: =Assumptions!$B$20+(Assumptions!$F$20-Assumptions!$B$20)*2/9 -> 0.056666667 | F11: =Assumptions!$B$20+(Assumptions!$F$20-Assumptions!$B$20)*3/9 -> 0.055 | G11: =Assumptions!$B$20+(Assumptions!$F$20-Assumptions!$B$20)*4/9 -> 0.053333333 | H11: =Assumptions!$B$20+(Assumptions!$F$20-Assumptions!$B$20)*5/9 -> 0.051666667 | I11: =Assumptions!$B$20+(Assumptions!$F$20-Assumptions!$B$20)*6/9 -> 0.05 | J11: =Assumptions!$B$20+(Assumptions!$F$20-Assumptions!$B$20)*7/9 -> 0.048333333 | K11: =Assumptions!$B$20+(Assumptions!$F$20-Assumptions!$B$20)*8/9 -> 0.046666667 | L11: =Assumptions!$B$20+(Assumptions!$F$20-Assumptions!$B$20)*9/9 -> 0.045
A12: Capex % rev | C12: =Assumptions!$B$21 -> 0.015 | D12: =Assumptions!$B$21+(Assumptions!$F$21-Assumptions!$B$21)*1/9 -> 0.015 | E12: =Assumptions!$B$21+(Assumptions!$F$21-Assumptions!$B$21)*2/9 -> 0.015 | F12: =Assumptions!$B$21+(Assumptions!$F$21-Assumptions!$B$21)*3/9 -> 0.015 | G12: =Assumptions!$B$21+(Assumptions!$F$21-Assumptions!$B$21)*4/9 -> 0.015 | H12: =Assumptions!$B$21+(Assumptions!$F$21-Assumptions!$B$21)*5/9 -> 0.015 | I12: =Assumptions!$B$21+(Assumptions!$F$21-Assumptions!$B$21)*6/9 -> 0.015 | J12: =Assumptions!$B$21+(Assumptions!$F$21-Assumptions!$B$21)*7/9 -> 0.015 | K12: =Assumptions!$B$21+(Assumptions!$F$21-Assumptions!$B$21)*8/9 -> 0.015 | L12: =Assumptions!$B$21+(Assumptions!$F$21-Assumptions!$B$21)*9/9 -> 0.015
A13: Cash tax rate % | C13: =Assumptions!$B$22 -> 0.2 | D13: =Assumptions!$B$22+(Assumptions!$F$22-Assumptions!$B$22)*1/9 -> 0.20222222 | E13: =Assumptions!$B$22+(Assumptions!$F$22-Assumptions!$B$22)*2/9 -> 0.20444444 | F13: =Assumptions!$B$22+(Assumptions!$F$22-Assumptions!$B$22)*3/9 -> 0.20666667 | G13: =Assumptions!$B$22+(Assumptions!$F$22-Assumptions!$B$22)*4/9 -> 0.20888889 | H13: =Assumptions!$B$22+(Assumptions!$F$22-Assumptions!$B$22)*5/9 -> 0.21111111 | I13: =Assumptions!$B$22+(Assumptions!$F$22-Assumptions!$B$22)*6/9 -> 0.21333333 | J13: =Assumptions!$B$22+(Assumptions!$F$22-Assumptions!$B$22)*7/9 -> 0.21555556 | K13: =Assumptions!$B$22+(Assumptions!$F$22-Assumptions!$B$22)*8/9 -> 0.21777778 | L13: =Assumptions!$B$22+(Assumptions!$F$22-Assumptions!$B$22)*9/9 -> 0.22
A14: Other current assets % rev | C14: =Assumptions!$B$23 -> 0.1 | D14: =Assumptions!$B$23+(Assumptions!$F$23-Assumptions!$B$23)*1/9 -> 0.1 | E14: =Assumptions!$B$23+(Assumptions!$F$23-Assumptions!$B$23)*2/9 -> 0.1 | F14: =Assumptions!$B$23+(Assumptions!$F$23-Assumptions!$B$23)*3/9 -> 0.1 | G14: =Assumptions!$B$23+(Assumptions!$F$23-Assumptions!$B$23)*4/9 -> 0.1 | H14: =Assumptions!$B$23+(Assumptions!$F$23-Assumptions!$B$23)*5/9 -> 0.1 | I14: =Assumptions!$B$23+(Assumptions!$F$23-Assumptions!$B$23)*6/9 -> 0.1 | J14: =Assumptions!$B$23+(Assumptions!$F$23-Assumptions!$B$23)*7/9 -> 0.1 | K14: =Assumptions!$B$23+(Assumptions!$F$23-Assumptions!$B$23)*8/9 -> 0.1 | L14: =Assumptions!$B$23+(Assumptions!$F$23-Assumptions!$B$23)*9/9 -> 0.1
A15: Deferred revenue % rev | C15: =Assumptions!$B$24 -> 0.21 | D15: =Assumptions!$B$24+(Assumptions!$F$24-Assumptions!$B$24)*1/9 -> 0.21 | E15: =Assumptions!$B$24+(Assumptions!$F$24-Assumptions!$B$24)*2/9 -> 0.21 | F15: =Assumptions!$B$24+(Assumptions!$F$24-Assumptions!$B$24)*3/9 -> 0.21 | G15: =Assumptions!$B$24+(Assumptions!$F$24-Assumptions!$B$24)*4/9 -> 0.21 | H15: =Assumptions!$B$24+(Assumptions!$F$24-Assumptions!$B$24)*5/9 -> 0.21 | I15: =Assumptions!$B$24+(Assumptions!$F$24-Assumptions!$B$24)*6/9 -> 0.21 | J15: =Assumptions!$B$24+(Assumptions!$F$24-Assumptions!$B$24)*7/9 -> 0.21 | K15: =Assumptions!$B$24+(Assumptions!$F$24-Assumptions!$B$24)*8/9 -> 0.21 | L15: =Assumptions!$B$24+(Assumptions!$F$24-Assumptions!$B$24)*9/9 -> 0.21
A17: INCOME STATEMENT
A18: Revenue | B18: =Historicals!E5 -> 7000 | C18: =Historicals!H5 -> 9665 | D18: =C18*(1+D7) -> 10631.5 | E18: =D18*(1+E7) -> 11641.493 | F18: =E18*(1+F7) -> 12689.227 | G18: =F18*(1+G7) -> 13767.811 | H18: =G18*(1+H7) -> 14869.236 | I18: =H18*(1+I7) -> 15984.429 | J18: =I18*(1+J7) -> 17103.339 | K18: =J18*(1+K7) -> 18215.056 | L18: =K18*(1+L7) -> 19307.959
A19: Cost of revenue (excl. D&A) | C19: =-C18*(1-C8) -> -1933 | D19: =-D18*(1-D8) -> -2102.6744 | E19: =-E18*(1-E8) -> -2276.5585 | F19: =-F18*(1-F8) -> -2453.2505 | G19: =-G18*(1-G8) -> -2631.1817 | H19: =-H18*(1-H8) -> -2808.6335 | I19: =-I18*(1-I8) -> -2983.76 | J19: =-J18*(1-J8) -> -3154.6158 | ... L19: =-L18*(1-L8) -> -3475.4326
A20: Gross profit | C20: =C18+C19 -> 7732 | D20: =D18+D19 -> 8528.8256 | E20: =E18+E19 -> 9364.934 | F20: =F18+F19 -> 10235.976 | G20: =G18+G19 -> 11136.629 | H20: =H18+H19 -> 12060.603 | I20: =I18+I19 -> 13000.669 | J20: =J18+J19 -> 13948.723 | ... L20: =L18+L19 -> 15832.526
A21: Cash opex (R&D + SG&A) | C21: =-C18*C9 -> -3914.325 | D21: =-D18*D9 -> -4240.7872 | E21: =-E18*E9 -> -4572.5196 | F21: =-F18*F9 -> -4906.501 | G21: =-G18*G9 -> -5239.417 | H21: =-H18*H9 -> -5567.7028 | I21: =-I18*I9 -> -5887.5979 | J21: =-J18*J9 -> -6195.2094 | ... L21: =-L18*L9 -> -6757.7857
A22: Adjusted EBITDA (pre-SBC) | C22: =C20+C21 -> 3817.675 | D22: =D20+D21 -> 4288.0383 | E22: =E20+E21 -> 4792.4144 | F22: =F20+F21 -> 5329.4753 | G22: =G20+G21 -> 5897.2124 | H22: =H20+H21 -> 6492.8997 | I22: =I20+I21 -> 7113.0708 | J22: =J20+J21 -> 7753.5135 | ... L22: =L20+L21 -> 9074.7408
A23: Stock-based compensation | C23: =-C18*C10 -> -869.85 | D23: =-D18*D10 -> -939.11583 | E23: =-E18*E10 -> -1008.9293 | F23: =-F18*F10 -> -1078.5843 | G23: =-G18*G10 -> -1147.3176 | H23: =-H18*H10 -> -1214.3209 | I23: =-I18*I10 -> -1278.7543 | J23: =-J18*J10 -> -1339.7615 | ... L23: =-L18*L10 -> -1448.0969
A24: D&A incl. Ansys amortization | C24: =-C18*C11 -> -579.9 | D24: =-D18*D11 -> -620.17083 | E24: =-E18*E11 -> -659.68457 | F24: =-F18*F11 -> -697.90748 | G24: =-G18*G11 -> -734.28326 | H24: =-H18*H11 -> -768.24386 | I24: =-I18*I11 -> -799.22143 | J24: =-J18*J11 -> -826.66137 | ... L24: =-L18*L11 -> -868.85816
A25: EBIT | C25: =C22+C23+C24 -> 2367.925 | D25: =D22+D23+D24 -> 2728.7517 | E25: =E22+E23+E24 -> 3123.8005 | F25: =F22+F23+F24 -> 3552.9835 | G25: =G22+G23+G24 -> 4015.6116 | H25: =H22+H23+H24 -> 4510.3349 | I25: =I22+I23+I24 -> 5035.095 | J25: =J22+J23+J24 -> 5587.0906 | ... L25: =L22+L23+L24 -> 6757.7857
A26: Interest income (on beginning cash) | C26: =B70*Assumptions!$B$34 -> 96 | D26: =C70*Assumptions!$B$34 -> 162.49597 | E26: =D70*Assumptions!$B$34 -> 236.45048 | F26: =E70*Assumptions!$B$34 -> 330.39165 | G26: =F70*Assumptions!$B$34 -> 445.88152 | H26: =G70*Assumptions!$B$34 -> 624.4506 | I26: =H70*Assumptions!$B$34 -> 827.19541 | J26: =I70*Assumptions!$B$34 -> 1055.5011 | ... L26: =K70*Assumptions!$B$34 -> 1593.7817
A27: Interest expense (beginning debt) | C27: =-(B50*Assumptions!$B$39+B54*Assumptions!$B$35) -> -598 | D27: =-(C50*Assumptions!$B$39+C54*Assumptions!$B$35) -> -598 | E27: =-(D50*Assumptions!$B$39+D54*Assumptions!$B$35) -> -546 | F27: =-(E50*Assumptions!$B$39+E54*Assumptions!$B$35) -> -494 | G27: =-(F50*Assumptions!$B$39+F54*Assumptions!$B$35) -> -442 | H27: =-(G50*Assumptions!$B$39+G54*Assumptions!$B$35) -> -442 | I27: =-(H50*Assumptions!$B$39+H54*Assumptions!$B$35) -> -442 | J27: =-(I50*Assumptions!$B$39+I54*Assumptions!$B$35) -> -442 | ... L27: =-(K50*Assumptions!$B$39+K54*Assumptions!$B$35) -> -442
A28: Pre-tax income | C28: =C25+C26+C27 -> 1865.925 | D28: =D25+D26+D27 -> 2293.2476 | E28: =E25+E26+E27 -> 2814.251 | F28: =F25+F26+F27 -> 3389.3752 | G28: =G25+G26+G27 -> 4019.4931 | H28: =H25+H26+H27 -> 4692.7855 | I28: =I25+I26+I27 -> 5420.2904 | J28: =J25+J26+J27 -> 6200.5918 | ... L28: =L25+L26+L27 -> 7909.5674
A29: Taxes | C29: =-MAX(0,C28)*C13 -> -373.185 | D29: =-MAX(0,D28)*D13 -> -463.74563 | E29: =-MAX(0,E28)*E13 -> -575.35798 | F29: =-MAX(0,F28)*F13 -> -700.47087 | G29: =-MAX(0,G28)*G13 -> -839.62745 | H29: =-MAX(0,H28)*H13 -> -990.69917 | I29: =-MAX(0,I28)*I13 -> -1156.3286 | J29: =-MAX(0,J28)*J13 -> -1336.572 | ... L29: =-MAX(0,L28)*L13 -> -1740.1048
A30: Net income (GAAP-normalized) | C30: =C28+C29 -> 1492.74 | D30: =D28+D29 -> 1829.502 | E30: =E28+E29 -> 2238.893 | F30: =F28+F29 -> 2688.9043 | G30: =G28+G29 -> 3179.8656 | H30: =H28+H29 -> 3702.0864 | I30: =I28+I29 -> 4263.9618 | J30: =J28+J29 -> 4864.0198 | ... L30: =L28+L29 -> 6169.4626
A31: EPS (constant shares; non-GAAP consensus ~2x higher) | C31: =C30/Assumptions!$B$37 -> 7.7909186 | D31: =D30/Assumptions!$B$37 -> 9.5485491 | E31: =E30/Assumptions!$B$37 -> 11.685245 | F31: =F30/Assumptions!$B$37 -> 14.033947 | G31: =G30/Assumptions!$B$37 -> 16.596376 | H31: =H30/Assumptions!$B$37 -> 19.321954 | I31: =I30/Assumptions!$B$37 -> 22.254498 | J31: =J30/Assumptions!$B$37 -> 25.386324 | ... L31: =L30/Assumptions!$B$37 -> 32.1997
A32: Adj. EBITDA margin % | C32: =C22/C18 -> 0.395 | D32: =D22/D18 -> 0.40333333 | E32: =E22/E18 -> 0.41166667 | F32: =F22/F18 -> 0.42 | G32: =G22/G18 -> 0.42833333 | H32: =H22/H18 -> 0.43666667 | I32: =I22/I18 -> 0.445 | J32: =J22/J18 -> 0.45333333 | ... L32: =L22/L18 -> 0.47
A34: WORKING CAPITAL
A35: Accounts receivable | B35: 1900 | C35: =C18*Assumptions!$B$27/365 -> 1853.5616 | D35: =D18*Assumptions!$B$27/365 -> 2038.9178 | E35: =E18*Assumptions!$B$27/365 -> 2232.615 | F35: =F18*Assumptions!$B$27/365 -> 2433.5503 | G35: =G18*Assumptions!$B$27/365 -> 2640.4021 | H35: =H18*Assumptions!$B$27/365 -> 2851.6343 | I35: =I18*Assumptions!$B$27/365 -> 3065.5069 | J35: =J18*Assumptions!$B$27/365 -> 3280.0924 | ... L35: =L18*Assumptions!$B$27/365 -> 3702.8963
A36: Inventory (emulation hardware) | B36: 400 | C36: =-C19*Assumptions!$B$28/365 -> 635.50685 | D36: =-D19*Assumptions!$B$28/365 -> 691.29023 | E36: =-E19*Assumptions!$B$28/365 -> 748.4576 | F36: =-F19*Assumptions!$B$28/365 -> 806.54812 | G36: =-G19*Assumptions!$B$28/365 -> 865.04603 | H36: =-H19*Assumptions!$B$28/365 -> 923.38634 | I36: =-I19*Assumptions!$B$28/365 -> 980.9622 | J36: =-J19*Assumptions!$B$28/365 -> 1037.134 | ... L36: =-L19*Assumptions!$B$28/365 -> 1142.608
A37: Other current assets | B37: 950 | C37: =C18*C14 -> 966.5 | D37: =D18*D14 -> 1063.15 | E37: =E18*E14 -> 1164.1492 | F37: =F18*F14 -> 1268.9227 | G37: =G18*G14 -> 1376.7811 | H37: =H18*H14 -> 1486.9236 | I37: =I18*I14 -> 1598.4429 | J37: =J18*J14 -> 1710.3339 | ... L37: =L18*L14 -> 1930.7959
A38: AP + accrued | B38: -1300 | C38: =(C19+C21)*Assumptions!$B$29/365 -> -640.80274 | D38: =(D19+D21)*Assumptions!$B$29/365 -> -695.17388 | E38: =(E19+E21)*Assumptions!$B$29/365 -> -750.5839 | F38: =(F19+F21)*Assumptions!$B$29/365 -> -806.54812 | G38: =(G19+G21)*Assumptions!$B$29/365 -> -862.53136 | H38: =(H19+H21)*Assumptions!$B$29/365 -> -917.95466 | I38: =(I19+I21)*Assumptions!$B$29/365 -> -972.20361 | J38: =(J19+J21)*Assumptions!$B$29/365 -> -1024.6384 | ... L38: =(L19+L21)*Assumptions!$B$29/365 -> -1121.4486
A39: Deferred revenue | B39: -2000 | C39: =-C18*C15 -> -2029.65 | D39: =-D18*D15 -> -2232.615 | E39: =-E18*E15 -> -2444.7134 | F39: =-F18*F15 -> -2664.7376 | G39: =-G18*G15 -> -2891.2403 | H39: =-H18*H15 -> -3122.5396 | I39: =-I18*I15 -> -3356.73 | J39: =-J18*J15 -> -3591.7011 | ... L39: =-L18*L15 -> -4054.6714
A40: Net working capital | B40: =SUM(B35:B39) -> -50 | C40: =SUM(C35:C39) -> 785.11575 | D40: =SUM(D35:D39) -> 865.56916 | E40: =SUM(E35:E39) -> 949.92453 | F40: =SUM(F35:F39) -> 1037.7354 | G40: =SUM(G35:G39) -> 1128.4576 | H40: =SUM(H35:H39) -> 1221.45 | I40: =SUM(I35:I39) -> 1315.9783 | ... L40: =SUM(L35:L39) -> 1600.1802
A41: (Increase) / decrease in NWC — cash impact | C41: =-(C40-B40) -> -835.11575 | D41: =-(D40-C40) -> -80.453402 | E41: =-(E40-D40) -> -84.35537 | F41: =-(F40-E40) -> -87.810874 | G41: =-(G40-F40) -> -90.722178 | H41: =-(H40-G40) -> -92.992448 | I41: =-(I40-H40) -> -94.528282 | J41: =-(J40-I40) -> -95.242379 | ... L41: =-(L40-K40) -> -93.903187
A43: CAPEX & PP&E
A44: Capex | C44: =C18*C12 -> 144.975 | D44: =D18*D12 -> 159.4725 | E44: =E18*E12 -> 174.62239 | F44: =F18*F12 -> 190.3384 | G44: =G18*G12 -> 206.51717 | H44: =H18*H12 -> 223.03854 | I44: =I18*I12 -> 239.76643 | J44: =J18*J12 -> 256.55008 | ... L44: =L18*L12 -> 289.61939
A45: PP&E, net | B45: 600 | C45: =B45+C44+C24*0.4 -> 513.015 | D45: =C45+D44+D24*0.4 -> 424.41917 | E45: =D45+E44+E24*0.4 -> 335.16772 | F45: =E45+F44+F24*0.4 -> 246.34314 | G45: =F45+G44+G24*0.4 -> 159.147 | H45: =G45+H44+H24*0.4 -> 74.887995 | I45: =H45+I44+I24*0.4 -> -5.034148 | J45: =I45+J44+J24*0.4 -> -79.148616 | ... L45: =K45+L44+L24*0.4 -> -203.86103 | M45: 60% of D&A = Ansys/acquisition amortization (goodwill/intangibles line), 40% = depreciation of PP&E
...

Sheet WACC
A1: WEIGHTED AVERAGE COST OF CAPITAL — CURRENT MARKET DATA (JULY 2026)
A4: COST OF EQUITY (CAPM)
A5: Risk-free rate — 10Y UST, 7/17/2026 | B5: 0.0455 | C5: tradingeconomics.com / FRED DGS10
A6: Levered beta | B6: 1.24 | C6: stockanalysis.com, July 2026
A7: Equity risk premium | B7: 0.0475 | C7: Damodaran implied ERP, mid-2026
A8: Company-specific premium | B8: 0
A9: Cost of equity | B9: =B5+B6*B7+B8 -> 0.1044
A11: COST OF DEBT
A12: Pre-tax cost of debt | B12: 0.052 | C12: Blended Ansys financing (notes + term)
A13: Tax rate | B13: =Assumptions!B38 -> 0.22
A14: After-tax cost of debt | B14: =B12*(1-B13) -> 0.04056
A16: CAPITAL STRUCTURE (market weights)
A17: Debt / total capitalization | B17: 0.11 | C17: $10.9B debt vs ~$73.6B market cap
A18: Equity / total capitalization | B18: =1-B17 -> 0.89
A20: WACC | B20: =B18*B9+B17*B14 -> 0.0973776
A22: WACC ≈ 9.7%. Sensitivity range in DCF tables: 8.8% – 10.8%.

Sheet DCF
A1: DISCOUNTED CASH FLOW — UNLEVERED FCF ($mm; valuation as of FY2026 year-end, mid-year convention)
B4: FY2027E | C4: FY2028E | D4: FY2029E | E4: FY2030E | F4: FY2031E | G4: FY2032E | H4: FY2033E | I4: FY2034E | J4: FY2035E
A5: EBIT (post-SBC) | B5: =Model_3S!D25 -> 2728.7517 | C5: =Model_3S!E25 -> 3123.8005 | D5: =Model_3S!F25 -> 3552.9835 | E5: =Model_3S!G25 -> 4015.6116 | F5: =Model_3S!H25 -> 4510.3349 | G5: =Model_3S!I25 -> 5035.095 | H5: =Model_3S!J25 -> 5587.0906 | I5: =Model_3S!K25 -> 6162.7605 | J5: =Model_3S!L25 -> 6757.7857
A6: Cash taxes on EBIT | B6: =-MAX(0,B5)*Model_3S!D13 -> -551.81423 | C6: =-MAX(0,C5)*Model_3S!E13 -> -638.64366 | D6: =-MAX(0,D5)*Model_3S!F13 -> -734.28326 | E6: =-MAX(0,E5)*Model_3S!G13 -> -838.81664 | F6: =-MAX(0,F5)*Model_3S!H13 -> -952.18182 | G6: =-MAX(0,G5)*Model_3S!I13 -> -1074.1536 | H6: =-MAX(0,H5)*Model_3S!J13 -> -1204.3284 | I6: =-MAX(0,I5)*Model_3S!K13 -> -1342.1123 | J6: =-MAX(0,J5)*Model_3S!L13 -> -1486.7128
A7: + D&A | B7: =-Model_3S!D24 -> 620.17083 | C7: =-Model_3S!E24 -> 659.68457 | D7: =-Model_3S!F24 -> 697.90748 | E7: =-Model_3S!G24 -> 734.28326 | F7: =-Model_3S!H24 -> 768.24386 | G7: =-Model_3S!I24 -> 799.22143 | H7: =-Model_3S!J24 -> 826.66137 | I7: =-Model_3S!K24 -> 850.03593 | J7: =-Model_3S!L24 -> 868.85816
A8: − Capex | B8: =-Model_3S!D44 -> -159.4725 | C8: =-Model_3S!E44 -> -174.62239 | D8: =-Model_3S!F44 -> -190.3384 | E8: =-Model_3S!G44 -> -206.51717 | F8: =-Model_3S!H44 -> -223.03854 | G8: =-Model_3S!I44 -> -239.76643 | H8: =-Model_3S!J44 -> -256.55008 | I8: =-Model_3S!K44 -> -273.22584 | J8: =-Model_3S!L44 -> -289.61939
A9: +/− Change in NWC | B9: =Model_3S!D41 -> -80.453402 | C9: =Model_3S!E41 -> -84.35537 | D9: =Model_3S!F41 -> -87.810874 | E9: =Model_3S!G41 -> -90.722178 | F9: =Model_3S!H41 -> -92.992448 | G9: =Model_3S!I41 -> -94.528282 | H9: =Model_3S!J41 -> -95.242379 | I9: =Model_3S!K41 -> -95.056295 | J9: =Model_3S!L41 -> -93.903187
A10: Unlevered free cash flow | B10: =SUM(B5:B9) -> 2557.1824 | C10: =SUM(C5:C9) -> 2885.8637 | D10: =SUM(D5:D9) -> 3238.4585 | E10: =SUM(E5:E9) -> 3613.8388 | F10: =SUM(F5:F9) -> 4010.366 | G10: =SUM(G5:G9) -> 4425.8682 | H10: =SUM(H5:H9) -> 4857.6311 | I10: =SUM(I5:I9) -> 5302.402 | J10: =SUM(J5:J9) -> 5756.4084
A11: Discount period (mid-year) | B11: 0.5 | C11: 1.5 | D11: 2.5 | E11: 3.5 | F11: 4.5 | G11: 5.5 | H11: 6.5 | I11: 7.5 | J11: 8.5
A12: Discount factor @ WACC | B12: =(1+$B$16)^-B11 -> 0.95460115 | C12: =(1+$B$16)^-C11 -> 0.86989305 | D12: =(1+$B$16)^-D11 -> 0.79270167 | E12: =(1+$B$16)^-E11 -> 0.72235999 | F12: =(1+$B$16)^-F11 -> 0.65826019 | G12: =(1+$B$16)^-G11 -> 0.59984839 | H12: =(1+$B$16)^-H11 -> 0.54661986 | I12: =(1+$B$16)^-I11 -> 0.49811465 | J12: =(1+$B$16)^-J11 -> 0.45391363
A13: PV of FCF | B13: =B10*B12 -> 2441.0892 | C13: =C10*C12 -> 2510.3927 | D13: =D10*D12 -> 2567.1314 | E13: =E10*E12 -> 2610.4926 | F13: =F10*F12 -> 2639.8643 | G13: =G10*G12 -> 2654.8499 | H13: =H10*H12 -> 2655.2777 | I13: =I10*I12 -> 2641.2041 | J13: =J10*J12 -> 2612.9123
A15: Sum of PV of explicit FCF (FY27–35) | B15: =SUM(B13:J13) -> 23333.214
A16: WACC | B16: =WACC!B20 -> 0.0973776
A18: TERMINAL VALUE — METHOD 1: GORDON GROWTH
A19: Terminal growth g | B19: =Assumptions!B47 -> 0.035
A20: Terminal value | B20: =J10*(1+B19)/(B16-B19) -> 95513.176
A21: PV of terminal value (9.0 yrs) | B21: =B20/(1+B16)^9 -> 41386.478
A22: Implied exit EV/EBITDA | B22: =B20/Model_3S!L22 -> 10.525169
A24: TERMINAL VALUE — METHOD 2: EXIT MULTIPLE
A25: Exit EV/Adj. EBITDA multiple | B25: =Assumptions!B48 -> 18
A26: Terminal value | B26: =B25*Model_3S!L22 -> 163345.33
A27: PV of terminal value | B27: =B26/(1+B16)^9 -> 70778.591
A28: Implied perpetuity growth | B28: =(B16*B26-J10)/(B26+J10) -> 0.060021665
A30: ENTERPRISE → EQUITY VALUE BRIDGE
A31: Net debt, FY2026E year-end (debt − cash) | B31: =Model_3S!C55-Model_3S!C70 -> 7437.6008
A32: Diluted shares (mm) | B32: =Assumptions!B37 -> 191.6
B33: Gordon growth | C33: Exit multiple | D33: Average
A34: Enterprise value | B34: =B15+B21 -> 64719.692 | C34: =B15+B27 -> 94111.805 | D34: =AVERAGE(B34:C34) -> 79415.749
A35: − Net debt | B35: =-$B$31 -> -7437.6008 | C35: =-$B$31 -> -7437.6008 | D35: =-$B$31 -> -7437.6008
A36: Equity value | B36: =B34+B35 -> 57282.091 | C36: =C34+C35 -> 86674.205 | D36: =D34+D35 -> 71978.148
A37: Implied value per share | B37: =B36/$B$32 -> 298.96707 | C37: =C36/$B$32 -> 452.37059 | D37: =D36/$B$32 -> 375.66883
A38: Upside / (downside) vs current price | B38: =B37/Assumptions!$B$49-1 -> -0.2220072 | C38: =C37/Assumptions!$B$49-1 -> 0.17719004 | D38: =D37/Assumptions!$B$49-1 -> -0.022408581
A42: SENSITIVITY — VALUE PER SHARE: WACC × TERMINAL GROWTH (Gordon)
B43: WACC \ g | C43: 0.025 | D43: 0.03 | E43: 0.035 | F43: 0.04 | G43: 0.045
B44: 0.088 | C44: =(SUMPRODUCT($B$10:$J$10,(1+$B$44)^-($B$11:$J$11))+$J$10*(1+C$43)/($B$44-C$43)/(1+$B$44)^9-$B$31)/$B$32 -> 316.66113 | D44: =(SUMPRODUCT($B$10:$J$10,(1+$B$44)^-($B$11:$J$11))+$J$10*(1+D$43)/($B$44-D$43)/(1+$B$44)^9-$B$31)/$B$32 -> 337.59871 | E44: =(SUMPRODUCT($B$10:$J$10,(1+$B$44)^-($B$11:$J$11))+$J$10*(1+E$43)/($B$44-E$43)/(1+$B$44)^9-$B$31)/$B$32 -> 362.48677 | F44: =(SUMPRODUCT($B$10:$J$10,(1+$B$44)^-($B$11:$J$11))+$J$10*(1+F$43)/($B$44-F$43)/(1+$B$44)^9-$B$31)/$B$32 -> 392.55984 | G44: =(SUMPRODUCT($B$10:$J$10,(1+$B$44)^-($B$11:$J$11))+$J$10*(1+G$43)/($B$44-G$43)/(1+$B$44)^9-$B$31)/$B$32 -> 429.62666
B45: 0.093 | C45: =(SUMPRODUCT($B$10:$J$10,(1+$B$45)^-($B$11:$J$11))+$J$10*(1+C$43)/($B$45-C$43)/(1+$B$45)^9-$B$31)/$B$32 -> 288.62502 | D45: =(SUMPRODUCT($B$10:$J$10,(1+$B$45)^-($B$11:$J$11))+$J$10*(1+D$43)/($B$45-D$43)/(1+$B$45)^9-$B$31)/$B$32 -> 305.84035 | E45: =(SUMPRODUCT($B$10:$J$10,(1+$B$45)^-($B$11:$J$11))+$J$10*(1+E$43)/($B$45-E$43)/(1+$B$45)^9-$B$31)/$B$32 -> 326.02384 | F45: =(SUMPRODUCT($B$10:$J$10,(1+$B$45)^-($B$11:$J$11))+$J$10*(1+F$43)/($B$45-F$43)/(1+$B$45)^9-$B$31)/$B$32 -> 350.01554 | G45: =(SUMPRODUCT($B$10:$J$10,(1+$B$45)^-($B$11:$J$11))+$J$10*(1+G$43)/($B$45-G$43)/(1+$B$45)^9-$B$31)/$B$32 -> 379.0055
B46: 0.097 | C46: =(SUMPRODUCT($B$10:$J$10,(1+$B$46)^-($B$11:$J$11))+$J$10*(1+C$43)/($B$46-C$43)/(1+$B$46)^9-$B$31)/$B$32 -> 269.05723 | D46: =(SUMPRODUCT($B$10:$J$10,(1+$B$46)^-($B$11:$J$11))+$J$10*(1+D$43)/($B$46-D$43)/(1+$B$46)^9-$B$31)/$B$32 -> 283.90516 | E46: =(SUMPRODUCT($B$10:$J$10,(1+$B$46)^-($B$11:$J$11))+$J$10*(1+E$43)/($B$46-E$43)/(1+$B$46)^9-$B$31)/$B$32 -> 301.14791 | F46: =(SUMPRODUCT($B$10:$J$10,(1+$B$46)^-($B$11:$J$11))+$J$10*(1+F$43)/($B$46-F$43)/(1+$B$46)^9-$B$31)/$B$32 -> 321.41571 | G46: =(SUMPRODUCT($B$10:$J$10,(1+$B$46)^-($B$11:$J$11))+$J$10*(1+G$43)/($B$46-G$43)/(1+$B$46)^9-$B$31)/$B$32 -> 345.58116
B47: 0.103 | C47: =(SUMPRODUCT($B$10:$J$10,(1+$B$47)^-($B$11:$J$11))+$J$10*(1+C$43)/($B$47-C$43)/(1+$B$47)^9-$B$31)/$B$32 -> 243.55277 | D47: =(SUMPRODUCT($B$10:$J$10,(1+$B$47)^-($B$11:$J$11))+$J$10*(1+D$43)/($B$47-D$43)/(1+$B$47)^9-$B$31)/$B$32 -> 255.59494 | E47: =(SUMPRODUCT($B$10:$J$10,(1+$B$47)^-($B$11:$J$11))+$J$10*(1+E$43)/($B$47-E$43)/(1+$B$47)^9-$B$31)/$B$32 -> 269.40801 | F47: =(SUMPRODUCT($B$10:$J$10,(1+$B$47)^-($B$11:$J$11))+$J$10*(1+F$43)/($B$47-F$43)/(1+$B$47)^9-$B$31)/$B$32 -> 285.41363 | G47: =(SUMPRODUCT($B$10:$J$10,(1+$B$47)^-($B$11:$J$11))+$J$10*(1+G$43)/($B$47-G$43)/(1+$B$47)^9-$B$31)/$B$32 -> 304.17884
B48: 0.108 | C48: =(SUMPRODUCT($B$10:$J$10,(1+$B$48)^-($B$11:$J$11))+$J$10*(1+C$43)/($B$48-C$43)/(1+$B$48)^9-$B$31)/$B$32 -> 225.18487 | D48: =(SUMPRODUCT($B$10:$J$10,(1+$B$48)^-($B$11:$J$11))+$J$10*(1+D$43)/($B$48-D$43)/(1+$B$48)^9-$B$31)/$B$32 -> 235.3998 | E48: =(SUMPRODUCT($B$10:$J$10,(1+$B$48)^-($B$11:$J$11))+$J$10*(1+E$43)/($B$48-E$43)/(1+$B$48)^9-$B$31)/$B$32 -> 247.01404 | F48: =(SUMPRODUCT($B$10:$J$10,(1+$B$48)^-($B$11:$J$11))+$J$10*(1+F$43)/($B$48-F$43)/(1+$B$48)^9-$B$31)/$B$32 -> 260.33625 | G48: =(SUMPRODUCT($B$10:$J$10,(1+$B$48)^-($B$11:$J$11))+$J$10*(1+G$43)/($B$48-G$43)/(1+$B$48)^9-$B$31)/$B$32 -> 275.77309
A50: SENSITIVITY — VALUE PER SHARE: WACC × EXIT EV/EBITDA MULTIPLE
...

Sheet Comps
A1: TRADING COMPARABLES — EDA / DESIGN SOFTWARE (July 2026; peer multiples estimated)
A4: Company | B4: Ticker | C4: EV/Revenue | D4: EV/EBITDA | E4: Note
A5: Cadence Design Systems | B5: CDNS | C5: 15 | D5: 33 | E5: e — from CDNS model: ~$92.8B EV / $6.2B rev / $2.8B EBITDA FY26E
A6: Autodesk | B6: ADSK | C6: 7 | D6: 25 | E6: e
A7: Microsoft | B7: MSFT | C7: 11.5 | D7: 22 | E7: e
A8: Oracle | B8: ORCL | C8: 9 | D8: 18 | E8: e
A9: Synopsys (self, current) | B9: SNPS | C9: =(Assumptions!B49*Assumptions!B37+DCF!B31)/Model_3S!C18 -> 8.3875477 | D9: =(Assumptions!B49*Assumptions!B37+DCF!B31)/Model_3S!C22 -> 21.234298 | E9: computed below
A10: Peer median (ex-SNPS) | C10: =MEDIAN(C5:C8) -> 10.25 | D10: =MEDIAN(D5:D8) -> 23.5
A11: SNPS trades at a wide discount to CDNS post the FY25 guidance reset (IP/China) and with Ansys leverage — the central comps question is how much of that gap closes.
A12: IMPLIED VALUE PER SHARE
A13: Method | B13: Low x | C13: High x | D13: Metric | E13: $/sh low | F13: $/sh high
A14: EV/Adj. EBITDA × FY2026E ($mm) | B14: 20 | C14: 30 | D14: =Model_3S!C22 -> 3817.675 | E14: =(B14*D14-DCF!$B$31)/Assumptions!$B$37 -> 359.68632 | F14: =(C14*D14-DCF!$B$31)/Assumptions!$B$37 -> 558.93867
A15: P/E × FY2026E non-GAAP EPS guide ($14.76) | B15: 25 | C15: 35 | D15: 14.76 | E15: =B15*D15 -> 369 | F15: =C15*D15 -> 516.6

Sheet Precedents
A1: PRECEDENT TRANSACTIONS — EDA & ENGINEERING SOFTWARE M&A
A4: Date | B4: Acquirer | C4: Target | D4: EV ($mm) | E4: EV/Revenue | F4: Note
A5: Jan-2024 | B5: Synopsys | C5: Ansys | D5: 35000 | E5: 15.4 | F5: SNPS's own deal — closed July 2025
A6: Oct-2024 | B6: Siemens | C6: Altair Engineering | D6: 10600 | E6: 15 | F6: e
A7: Feb-2024 | B7: Renesas | C7: Altium | D7: 5900 | E7: 20 | F7: e
A8: Mar-2024 | B8: Cadence | C8: BETA CAE | D8: 1240 | E8: 14 | F8: e
A9: Nov-2016 | B9: Siemens | C9: Mentor Graphics | D9: 4500 | E9: 3.7 | F9: pre-AI-cycle benchmark
A10: Median EV/Revenue | E10: =MEDIAN(E5:E9) -> 15
A12: APPLIED RANGE
A13: A ~$85B+ SNPS control deal has no precedent and would face antitrust walls (duopoly) — the band is a size-discounted framework, not a realistic path.
B14: Low | C14: High
A15: EV/Revenue applied to FY2026E | B15: 8 | C15: 12
A16: Implied EV | B16: =B15*Model_3S!C18 -> 77320 | C16: =C15*Model_3S!C18 -> 115980
A17: Implied value per share | B17: =(B16-DCF!$B$31)/Assumptions!$B$37 -> 364.73069 | C17: =(C16-DCF!$B$31)/Assumptions!$B$37 -> 566.50522

Sheet LBO
A1: LBO ANALYSIS — 5-YEAR HOLD (ENTRY END-FY2026, EXIT END-FY2031) ($mm)
A4: ENTRY & FINANCING
A5: Entry premium to current price | B5: 0.2
A6: Entry price per share | B6: =Assumptions!B49*(1+B5) -> 461.136
A7: Diluted shares (mm) | B7: =Assumptions!B37 -> 191.6
A8: Equity purchase price | B8: =B6*B7 -> 88353.658
A9: Plus: net debt assumed/refinanced | B9: =DCF!B31 -> 7437.6008
A10: Entry enterprise value | B10: =B8+B9 -> 95791.258
A11: Transaction fees (% of EV) | B11: 0.02
A12: FY2026E Adj. EBITDA (debt sizing basis) | B12: =Model_3S!C22 -> 3817.675
A13: Entry EV / EBITDA | B13: =B10/B12 -> 25.091517
A14: Debt tranche | B14: Multiple | C14: Rate | D14: Amount
A15: Term Loan B | B15: 4.5 | C15: 0.075 | D15: =B15*$B$12 -> 17179.537
A16: Senior notes | B16: 2 | C16: 0.09 | D16: =B16*$B$12 -> 7635.35
A17: Total new debt | B17: =B15+B16 -> 6.5 | D17: =D15+D16 -> 24814.888
A18: Sponsor equity = EV×(1+fees) − debt | B18: =B10*(1+B11)-D17 -> 72892.196
A20: DEBT PAYDOWN — 100% FCF SWEEP
B21: FY2027E | C21: FY2028E | D21: FY2029E | E21: FY2030E | F21: FY2031E
A22: Unlevered FCF (DCF sheet) | B22: =DCF!B10 -> 2557.1824 | C22: =DCF!C10 -> 2885.8637 | D22: =DCF!D10 -> 3238.4585 | E22: =DCF!E10 -> 3613.8388 | F22: =DCF!F10 -> 4010.366
A23: Cash interest — TLB (beginning) | B23: =-$D$15*$C$15 -> -1288.4653 | C23: =-B29*$C$15 -> -1212.252 | D23: =-C29*$C$15 -> -1106.9291 | E23: =-D29*$C$15 -> -969.00014 | F23: =-E29*$C$15 -> -794.84885
A24: Cash interest — notes | B24: =-$D$16*$C$16 -> -687.1815 | C24: =-$D$16*$C$16 -> -687.1815 | D24: =-$D$16*$C$16 -> -687.1815 | E24: =-$D$16*$C$16 -> -687.1815 | F24: =-$D$16*$C$16 -> -687.1815
A25: Interest tax shield | B25: =-(B23+B24)*Assumptions!$B$38 -> 434.6423 | C25: =-(C23+C24)*Assumptions!$B$38 -> 417.87536 | D25: =-(D23+D24)*Assumptions!$B$38 -> 394.70432 | E25: =-(E23+E24)*Assumptions!$B$38 -> 364.35996 | F25: =-(F23+F24)*Assumptions!$B$38 -> 326.04668
A26: Levered FCF for paydown | B26: =MAX(0,B22+B23+B24+B25) -> 1016.1779 | C26: =MAX(0,C22+C23+C24+C25) -> 1404.3055 | D26: =MAX(0,D22+D23+D24+D25) -> 1839.0522 | E26: =MAX(0,E22+E23+E24+E25) -> 2322.0172 | F26: =MAX(0,F22+F23+F24+F25) -> 2854.3823
A27: TLB — beginning | B27: =$D$15 -> 17179.537 | C27: =B29 -> 16163.36 | D27: =C29 -> 14759.054 | E27: =D29 -> 12920.002 | F27: =E29 -> 10597.985
A28: TLB — (paydown) | B28: =-MIN(B27,B26) -> -1016.1779 | C28: =-MIN(C27,C26) -> -1404.3055 | D28: =-MIN(D27,D26) -> -1839.0522 | E28: =-MIN(E27,E26) -> -2322.0172 | F28: =-MIN(F27,F26) -> -2854.3823
A29: TLB — ending | B29: =B27+B28 -> 16163.36 | C29: =C27+C28 -> 14759.054 | D29: =D27+D28 -> 12920.002 | E29: =E27+E28 -> 10597.985 | F29: =F27+F28 -> 7743.6024
A30: Notes — ending (bullet) | B30: =$D$16 -> 7635.35 | C30: =$D$16 -> 7635.35 | D30: =$D$16 -> 7635.35 | E30: =$D$16 -> 7635.35 | F30: =$D$16 -> 7635.35
A31: Total debt — ending | B31: =B29+B30 -> 23798.71 | C31: =C29+C30 -> 22394.404 | D31: =D29+D30 -> 20555.352 | E31: =E29+E30 -> 18233.335 | F31: =F29+F30 -> 15378.952
A33: EXIT & RETURNS
A34: FY2031E Adj. EBITDA | B34: =Model_3S!H22 -> 6492.8997
A35: Exit EV/EBITDA multiple | B35: 18
A36: Exit enterprise value | B36: =B34*B35 -> 116872.19
A37: Less: exit net debt | B37: =-F31 -> -15378.952
A38: Exit equity value | B38: =B36+B37 -> 101493.24
A39: MOIC | B39: =B38/B18 -> 1.3923746
A40: IRR (5-yr) | B40: =(B38/B18)^(1/5)-1 -> 0.068442657
A42: MAXIMUM ENTRY PRICE AT TARGET IRR THRESHOLDS (exit equity constant — debt sized on EBITDA, not price)
A43: Target IRR | B43: Max sponsor equity | C43: Implied entry EV | D43: Implied price/share | E43: Prem/(disc) to market
A44: 0.15 | B44: =$B$38/(1+A44)^5 -> 50460.079 | C44: =(B44+$D$17)/(1+$B$11) -> 73798.987 | D44: =(C44-$B$9)/$B$7 -> 346.35379 | E44: =D44/Assumptions!$B$49-1 -> -0.09869421
A45: 0.2 | B45: =$B$38/(1+A45)^5 -> 40787.858 | C45: =(B45+$D$17)/(1+$B$11) -> 64316.417 | D45: =(C45-$B$9)/$B$7 -> 296.8623 | E45: =D45/Assumptions!$B$49-1 -> -0.22748439
...

Sheet Monte_Carlo
A1: MONTE CARLO SIMULATION — 500 LIVE TRIALS (press F9 / recalc to refresh draws)
A2: Compact DCF per trial calibrated to the DCF sheet at base inputs; equity = PV(TV) + PV(FCF) − net debt.
A4: Distribution parameters — Normal(mean, σ)
A5: Variable | B5: Mean (linked) | C5: σ (input)
A6: FY2027 revenue growth | B6: =Assumptions!E12 -> 0.1 | C6: 0.03
A7: Terminal Adj. EBITDA margin (FY35) | B7: =Assumptions!F17-Assumptions!F18 -> 0.47 | C7: 0.03
A8: WACC | B8: =WACC!B20 -> 0.0973776 | C8: 0.0075
A9: Exit EV/EBITDA multiple | B9: =Assumptions!B48 -> 18 | C9: 3
A11: Calibration statics (linked)
A12: Base FY2035 Adj. EBITDA | B12: =Model_3S!L22 -> 9074.7408
A13: Base PV of explicit FCF (DCF) | B13: =DCF!B15 -> 23333.214
A14: Net debt FY2026E | B14: =DCF!B31 -> 7437.6008
A15: Diluted shares (mm) | B15: =Assumptions!B37 -> 191.6
A16: Current share price | B16: =Assumptions!B49 -> 384.28
A17: FY2035 growth (selected) | B17: =Assumptions!E13 -> 0.06
A18: FY2026E revenue | B18: =Model_3S!C18 -> 9665
A20: Simulation results ($/share)
A21: Mean | B21: =AVERAGE($K$41:$K$540) -> 456.38162
A22: Median | B22: =MEDIAN($K$41:$K$540) -> 447.41778
A23: Standard deviation | B23: =STDEV($K$41:$K$540) -> 96.15805
A24: 5th percentile | B24: =PERCENTILE($K$41:$K$540,0.05) -> 310.04622
A25: 25th percentile | B25: =PERCENTILE($K$41:$K$540,0.25) -> 390.39033
A26: 75th percentile | B26: =PERCENTILE($K$41:$K$540,0.75) -> 516.34826
A27: 95th percentile | B27: =PERCENTILE($K$41:$K$540,0.95) -> 617.04752
A28: P(value > current price) | B28: =COUNTIF($K$41:$K$540,">"&B16)/500 -> 0.764
A30: Scenario probability-weighted value (compact DCF per scenario)
A31: Scenario | B31: Probability | C31: Value / share
A32: Base | B32: =Assumptions!B8 -> 0.5 | C32: =($B$13*($B$18*(1+(Assumptions!B12+Assumptions!B13)/2)^9*(Assumptions!C17-Assumptions!C18))/$B$12+Assumptions!$B$48*($B$18*(1+(Assumptions!B12+Assumptions!B13)/2)^9*(Assumptions!C17-Assumptions!C18))/(1+$B$8)^9-$B$14)/$B$15 -> 452.68657
A33: Bull | B33: =Assumptions!C8 -> 0.25 | C33: =($B$13*($B$18*(1+(Assumptions!C12+Assumptions!C13)/2)^9*(Assumptions!D17-Assumptions!D18))/$B$12+Assumptions!$B$48*($B$18*(1+(Assumptions!C12+Assumptions!C13)/2)^9*(Assumptions!D17-Assumptions!D18))/(1+$B$8)^9-$B$14)/$B$15 -> 671.83891
A34: Bear | B34: =Assumptions!D8 -> 0.25 | C34: =($B$13*($B$18*(1+(Assumptions!D12+Assumptions!D13)/2)^9*(Assumptions!E17-Assumptions!E18))/$B$12+Assumptions!$B$48*($B$18*(1+(Assumptions!D12+Assumptions!D13)/2)^9*(Assumptions!E17-Assumptions!E18))/(1+$B$8)^9-$B$14)/$B$15 -> 253.50479
A35: Probability-weighted value | C35: =SUMPRODUCT(B32:B34,C32:C34) -> 457.67921
A39: TRIALS
A40: # | B40: g FY27 | C40: Term margin | D40: WACC | E40: Exit x | F40: Rev FY35 | G40: EBITDA FY35 | H40: PV(TV) | I40: PV(FCF) | J40: Equity | K40: $ / share | N40: Bin ($/sh) | O40: low | P40: high | Q40: Count
A41: 1 | B41: =NORMINV(RAND(),$B$6,$C$6) -> 0.060468505 | C41: =MAX(0.25,NORMINV(RAND(),$B$7,$C$7)) -> 0.44950452 | D41: =MAX(0.07,NORMINV(RAND(),$B$8,$C$8)) -> 0.11184191 | E41: =MAX(8,NORMINV(RAND(),$B$9,$C$9)) -> 24.616987 | F41: =$B$18*(1+(B41+$B$17)/2)^9 -> 16361.32 | G41: =F41*C41 -> 7354.4872 | H41: =E41*G41/(1+D41)^9 -> 69726.828 | I41: =$B$13*G41/$B$12*((1+$B$8)/(1+D41))^4.5 -> 17827.952 | J41: =H41+I41-$B$14 -> 80117.179 | K41: =J41/$B$15 -> 418.14812 | N41: <125 | O41: 100 | P41: 125 | Q41: =COUNTIF($K$41:$K$540,"<"&P41) -> 0
A42: 2 | B42: =NORMINV(RAND(),$B$6,$C$6) -> 0.11331274 | C42: =MAX(0.25,NORMINV(RAND(),$B$7,$C$7)) -> 0.48284025 | D42: =MAX(0.07,NORMINV(RAND(),$B$8,$C$8)) -> 0.10666952 | E42: =MAX(8,NORMINV(RAND(),$B$9,$C$9)) -> 8.6135552 | F42: =$B$18*(1+(B42+$B$17)/2)^9 -> 20418.88 | G42: =F42*C42 -> 9859.0572 | H42: =E42*G42/(1+D42)^9 -> 34108.003 | I42: =$B$13*G42/$B$12*((1+$B$8)/(1+D42))^4.5 -> 24406.043 | J42: =H42+I42-$B$14 -> 51076.444 | K42: =J42/$B$15 -> 266.57852 | N42: 125-150 | O42: 125 | P42: 150 | Q42: =COUNTIFS($K$41:$K$540,">="&O42,$K$41:$K$540,"<"&P42) -> 0
A43: 3 | B43: =NORMINV(RAND(),$B$6,$C$6) -> 0.079636035 | C43: =MAX(0.25,NORMINV(RAND(),$B$7,$C$7)) -> 0.49076138 | D43: =MAX(0.07,NORMINV(RAND(),$B$8,$C$8)) -> 0.10175967 | E43: =MAX(8,NORMINV(RAND(),$B$9,$C$9)) -> 17.24645 | F43: =$B$18*(1+(B43+$B$17)/2)^9 -> 17741.528 | G43: =F43*C43 -> 8706.8568 | H43: =E43*G43/(1+D43)^9 -> 62773.927 | I43: =$B$13*G43/$B$12*((1+$B$8)/(1+D43))^4.5 -> 21989.393 | J43: =H43+I43-$B$14 -> 77325.719 | K43: =J43/$B$15 -> 403.57891 | N43: 150-175 | O43: 150 | P43: 175 | Q43: =COUNTIFS($K$41:$K$540,">="&O43,$K$41:$K$540,"<"&P43) -> 0
A44: 4 | B44: =NORMINV(RAND(),$B$6,$C$6) -> 0.10953995 | C44: =MAX(0.25,NORMINV(RAND(),$B$7,$C$7)) -> 0.55431958 | D44: =MAX(0.07,NORMINV(RAND(),$B$8,$C$8)) -> 0.10344668 | E44: =MAX(8,NORMINV(RAND(),$B$9,$C$9)) -> 17.101002 | F44: =$B$18*(1+(B44+$B$17)/2)^9 -> 20102.069 | G44: =F44*C44 -> 11142.97 | H44: =E44*G44/(1+D44)^9 -> 78570.653 | I44: =$B$13*G44/$B$12*((1+$B$8)/(1+D44))^4.5 -> 27948.766 | J44: =H44+I44-$B$14 -> 99081.818 | K44: =J44/$B$15 -> 517.12849 | N44: 175-200 | O44: 175 | P44: 200 | Q44: =COUNTIFS($K$41:$K$540,">="&O44,$K$41:$K$540,"<"&P44) -> 0
A45: 5 | B45: =NORMINV(RAND(),$B$6,$C$6) -> 0.081637421 | C45: =MAX(0.25,NORMINV(RAND(),$B$7,$C$7)) -> 0.45533548 | D45: =MAX(0.07,NORMINV(RAND(),$B$8,$C$8)) -> 0.10894737 | E45: =MAX(8,NORMINV(RAND(),$B$9,$C$9)) -> 13.65525 | F45: =$B$18*(1+(B45+$B$17)/2)^9 -> 17891.445 | G45: =F45*C45 -> 8146.6097 | H45: =E45*G45/(1+D45)^9 -> 43860.963 | I45: =$B$13*G45/$B$12*((1+$B$8)/(1+D45))^4.5 -> 19981.149 | J45: =H45+I45-$B$14 -> 56404.511 | K45: =J45/$B$15 -> 294.3868 | N45: 200-225 | O45: 200 | P45: 225 | Q45: =COUNTIFS($K$41:$K$540,">="&O45,$K$41:$K$540,"<"&P45) -> 1
A46: 6 | B46: =NORMINV(RAND(),$B$6,$C$6) -> 0.070948195 | C46: =MAX(0.25,NORMINV(RAND(),$B$7,$C$7)) -> 0.45383386 | D46: =MAX(0.07,NORMINV(RAND(),$B$8,$C$8)) -> 0.086503601 | E46: =MAX(8,NORMINV(RAND(),$B$9,$C$9)) -> 19.387889 | F46: =$B$18*(1+(B46+$B$17)/2)^9 -> 17103.615 | G46: =F46*C46 -> 7762.1998 | H46: =E46*G46/(1+D46)^9 -> 71323.855 | I46: =$B$13*G46/$B$12*((1+$B$8)/(1+D46))^4.5 -> 20873.117 | J46: =H46+I46-$B$14 -> 84759.371 | K46: =J46/$B$15 -> 442.37668 | N46: 225-250 | O46: 225 | P46: 250 | Q46: =COUNTIFS($K$41:$K$540,">="&O46,$K$41:$K$540,"<"&P46) -> 0
A47: 7 | B47: =NORMINV(RAND(),$B$6,$C$6) -> 0.099888919 | C47: =MAX(0.25,NORMINV(RAND(),$B$7,$C$7)) -> 0.53164924 | D47: =MAX(0.07,NORMINV(RAND(),$B$8,$C$8)) -> 0.09313978 | E47: =MAX(8,NORMINV(RAND(),$B$9,$C$9)) -> 17.615915 | F47: =$B$18*(1+(B47+$B$17)/2)^9 -> 19311.439 | G47: =F47*C47 -> 10266.912 | H47: =E47*G47/(1+D47)^9 -> 81145.372 | I47: =$B$13*G47/$B$12*((1+$B$8)/(1+D47))^4.5 -> 26862.223 | J47: =H47+I47-$B$14 -> 100569.99 | K47: =J47/$B$15 -> 524.89559 | N47: 250-275 | O47: 250 | P47: 275 | Q47: =COUNTIFS($K$41:$K$540,">="&O47,$K$41:$K$540,"<"&P47) -> 8
...

Sheet Football_Field
A1: FOOTBALL FIELD — VALUATION SUMMARY ($ per share)
A2: =CONCATENATE("Current price: $",TEXT(Assumptions!B49,"0.00")," · Scenario: ",CHOOSE(Assumptions!B4,"BASE","BULL","BEAR")," · Probability-weighted value: $",TEXT(Monte_Carlo!C35,"0.00")) -> Current price: $384.28 · Scenario: BASE · Probability-weighted value: $457.68
A4: Methodology | B4: Low | C4: High | D4: (base) | E4: (span) | F4: Midpoint
A5: 52-week trading range | B5: 366 | C5: 651.73 | D5: =B5 -> 366 | E5: =C5-B5 -> 285.73 | F5: =(B5+C5)/2 -> 508.865
A6: Analyst targets (avg $564, n=19) | B6: 403.85 | C6: 650 | D6: =B6 -> 403.85 | E6: =C6-B6 -> 246.15 | F6: =(B6+C6)/2 -> 526.925
A7: DCF — Gordon growth (WACC ±0.5%, g 3.0–4.0%) | B7: =(SUMPRODUCT(DCF!$B$10:$J$10,(1+(WACC!$B$20+0.005))^-DCF!$B$11:$J$11)+DCF!$J$10*(1+0.03)/((WACC!$B$20+0.005)-0.03)/(1+(WACC!$B$20+0.005))^9-DCF!$B$31)/DCF!$B$32 -> 258.3088 | C7: =(SUMPRODUCT(DCF!$B$10:$J$10,(1+(WACC!$B$20-0.005))^-DCF!$B$11:$J$11)+DCF!$J$10*(1+0.04)/((WACC!$B$20-0.005)-0.04)/(1+(WACC!$B$20-0.005))^9-DCF!$B$31)/DCF!$B$32 -> 354.86368 | D7: =B7 -> 258.3088 | E7: =C7-B7 -> 96.554876 | F7: =(B7+C7)/2 -> 306.58624
A8: DCF — exit multiple (16–20x, WACC ±0.5%) | B8: =(SUMPRODUCT(DCF!$B$10:$J$10,(1+(WACC!$B$20+0.005))^-DCF!$B$11:$J$11)+16*Model_3S!$L$22/(1+(WACC!$B$20+0.005))^9-DCF!$B$31)/DCF!$B$32 -> 395.67375 | C8: =(SUMPRODUCT(DCF!$B$10:$J$10,(1+(WACC!$B$20-0.005))^-DCF!$B$11:$J$11)+20*Model_3S!$L$22/(1+(WACC!$B$20-0.005))^9-DCF!$B$31)/DCF!$B$32 -> 513.20596 | D8: =B8 -> 395.67375 | E8: =C8-B8 -> 117.53221 | F8: =(B8+C8)/2 -> 454.43985
A9: Trading comps — EV/EBITDA (20–30x FY26E) | B9: =Comps!E14 -> 359.68632 | C9: =Comps!F14 -> 558.93867 | D9: =B9 -> 359.68632 | E9: =C9-B9 -> 199.25235 | F9: =(B9+C9)/2 -> 459.3125
A10: Trading comps — P/E (25–35x FY26E non-GAAP EPS) | B10: =Comps!E15 -> 369 | C10: =Comps!F15 -> 516.6 | D10: =B10 -> 369 | E10: =C10-B10 -> 147.6 | F10: =(B10+C10)/2 -> 442.8
A11: Precedent transactions (8–12x FY26E revenue) | B11: =Precedents!B17 -> 364.73069 | C11: =Precedents!C17 -> 566.50522 | D11: =B11 -> 364.73069 | E11: =C11-B11 -> 201.77453 | F11: =(B11+C11)/2 -> 465.61795
A12: LBO capacity (25% → 15% IRR) | B12: =LBO!D46 -> 258.32945 | C12: =LBO!D44 -> 346.35379 | D12: =B12 -> 258.32945 | E12: =C12-B12 -> 88.024342 | F12: =(B12+C12)/2 -> 302.34162
A13: Monte Carlo P25–P75 (live) | B13: =Monte_Carlo!B25 -> 390.39033 | C13: =Monte_Carlo!B26 -> 516.34826 | D13: =B13 -> 390.39033 | E13: =C13-B13 -> 125.95794 | F13: =(B13+C13)/2 -> 453.3693
A14: Current price (marker) | B14: =Assumptions!B49-3.5 -> 380.78 | C14: =Assumptions!B49+3.5 -> 387.78 | D14: =B14 -> 380.78 | E14: =C14-B14 -> 7 | F14: =(B14+C14)/2 -> 384.28
A16: 52-wk range & analyst targets: investing.com / stockanalysis.com, July 2026. All other rows are live model outputs.
