Workbook

Sheet Cover
A1: SYMBOTIC INC. (NASDAQ: SYM) — DCF VALUATION & 3-STATEMENT OPERATING MODEL
A2: Prepared July 20, 2026 · All figures in $ millions except per-share data · Fiscal year ends late September
A4: CONTENTS
A5: Assumptions | C5: All scenario levers, WACC & valuation inputs (edit yellow cells only)
A6: Historicals | C6: FY2022–FY2025 actuals and FY2026 quarterly build with sources
A7: Model_3S | C7: Linked 3-statement model FY2026E–FY2035E: IS, BS, CF, working capital, capex, debt schedule
A8: WACC | C8: Cost of capital build-up from current market data
A9: DCF | C9: Unlevered FCF, terminal value (Gordon growth & exit multiple), sensitivity tables
A10: Comps | C10: Trading comparables — warehouse automation & industrial automation peers
A11: Precedents | C11: Precedent M&A transactions in warehouse automation / robotics
A12: LBO | C12: Leveraged buyout analysis; implied max entry price at 15/20/25/30% IRR thresholds
A13: Monte_Carlo | C13: Live 500-trial simulation + scenario probability-weighted value
A14: Football_Field | C14: Valuation summary chart across all methodologies
A16: LEGEND
A17: Blue font / yellow fill | C17: Hardcoded input or scenario lever — edit these
A18: Black font | C18: Formula — do not overwrite
A19: Green font | C19: Link to another sheet
A20: 'e' suffix in a label or note | C20: Estimated figure (not directly disclosed); see cell notes/sources
A22: HOW TO USE
A23: 1. | C23: Set the scenario switch on Assumptions!B4 (1=Base, 2=Bull, 3=Bear). The entire model, DCF and LBO re-derive.
A24: 2. | C24: Edit growth/margin targets, WACC inputs, terminal assumptions — all yellow cells.
A25: 3. | C25: Monte Carlo trials use RAND() and refresh on every recalculation (F9).
A27: KEY SOURCES
A28: Q2 FY2026 results (8-K ex.99.1, May 6, 2026) | C28: https://www.sec.gov/Archives/edgar/data/0001837240/000183724026000023/q2268-k_ex991.htm
A29: Q1 FY2026 results (8-K ex.99.1, Feb 4, 2026) | C29: https://www.sec.gov/Archives/edgar/data/1837240/000183724026000008/q1268-k_ex991.htm
A30: FY2025 10-K (filed Nov 2025) | C30: https://www.sec.gov/Archives/edgar/data/1837240/000183724025000278/sym-20250927.htm
A31: FY2025 Q4/FY results press release | C31: https://ir.symbotic.com/news-releases/news-release-details/symbotic-reports-fourth-quarter-and-fiscal-year-2025-results
A32: User-provided source document | C32: https://ir.symbotic.com/node/11021/html (Q2 FY2026 filing; site blocks automated access — figures cross-sourced from SEC mirrors above)
A33: Market data (price, beta, 10Y UST, peer multiples) | C33: stockanalysis.com, tradingeconomics.com/FRED, multiples.vc, marketbeat/tipranks consensus — as of July 17-20, 2026
A35: DISCLAIMER | C35: Educational model, not investment advice. Estimated cells are best-effort reconstructions where line-item detail was not retrievable; verify against filings before relying on any output.

Sheet Assumptions
A1: ASSUMPTIONS & SCENARIO LEVERS
A2: Edit yellow cells. Scenario switch drives Model_3S, DCF, LBO and Monte Carlo.
A4: SCENARIO SWITCH (1 = Base, 2 = Bull, 3 = Bear) | B4: 1 | C4: =CHOOSE($B$4,"BASE — current trajectory","BULL — accelerated backlog conversion","BEAR — deployment slowdown") -> BASE — current trajectory
A6: Scenario probability weights (used for weighted value & Monte Carlo)
B7: Base | C7: Bull | D7: Bear | E7: Total
A8: Probability | B8: 0.5 | C8: 0.3 | D8: 0.2 | E8: =SUM(B8:D8) -> 1 | F8: Must total 100%
A10: Revenue growth — decays linearly from FY2027 rate to FY2035 rate
B11: Base | C11: Bull | D11: Bear | E11: Selected
A12: FY2027 revenue growth | B12: 0.2 | C12: 0.25 | D12: 0.13 | E12: =CHOOSE($B$4,B12,C12,D12) -> 0.2
A13: FY2035 revenue growth (terminal-year) | B13: 0.05 | C13: 0.08 | D13: 0.01 | E13: =CHOOSE($B$4,B13,C13,D13) -> 0.05
A14: Bull = Base +5pp initial growth; Bear = Base −7pp. Backlog of $22.7B (~8x FY26E revenue) supports multi-year visibility.
A15: Operating drivers — FY2026 start value ramps linearly to FY2035 target
A16: Driver | B16: FY26 start | C16: Base target | D16: Bull target | E16: Bear target | F16: Selected
A17: Gross margin (excl. D&A) | B17: 0.205 | C17: 0.3 | D17: 0.33 | E17: 0.25 | F17: =CHOOSE($B$4,C17,D17,E17) -> 0.3
A18: R&D expense (cash, % revenue) | B18: 0.045 | C18: 0.045 | D18: 0.04 | E18: 0.05 | F18: =CHOOSE($B$4,C18,D18,E18) -> 0.045
A19: SG&A expense (cash, % revenue) | B19: 0.046 | C19: 0.045 | D19: 0.04 | E19: 0.06 | F19: =CHOOSE($B$4,C19,D19,E19) -> 0.045
A20: Stock-based compensation (% revenue) | B20: 0.067 | C20: 0.035 | D20: 0.035 | E20: 0.045 | F20: =CHOOSE($B$4,C20,D20,E20) -> 0.035
A21: D&A (% revenue) | B21: 0.025 | C21: 0.025 | D21: 0.025 | E21: 0.025 | F21: =CHOOSE($B$4,C21,D21,E21) -> 0.025
A22: Capex incl. capitalized software (% revenue) | B22: 0.03 | C22: 0.025 | D22: 0.03 | E22: 0.02 | F22: =CHOOSE($B$4,C22,D22,E22) -> 0.025
A23: Cash tax rate (NOL runoff by FY2035) | B23: 0.15 | C23: 0.25 | D23: 0.25 | E23: 0.25 | F23: =CHOOSE($B$4,C23,D23,E23) -> 0.25
A24: Deferred revenue / customer deposits (% revenue) | B24: 0.4 | C24: 0.25 | D24: 0.28 | E24: 0.2 | F24: =CHOOSE($B$4,C24,D24,E24) -> 0.25
A25: FY26 starts calibrated to H1 FY26 actuals + Q3 guidance (see Historicals). Implied terminal Adj. EBITDA margin: Base 21%, Bull 25%, Bear 14%.
A26: Working capital drivers (held constant)
A27: Days sales outstanding (DSO) | B27: 45
A28: Days inventory outstanding (DIO, on COGS) | B28: 55
A29: Days payable outstanding (DPO, on COGS) | B29: 75
A30: Accrued liabilities (% revenue) | B30: 0.1
A31: Other current assets (% revenue) | B31: 0.03
A33: Capital & other
A34: Interest earned on cash balances | B34: 0.04
A35: Revolver interest rate | B35: 0.07
A36: Minimum cash balance ($mm) | B36: 200
A37: Diluted shares outstanding (mm, all classes A/V-1/V-3 + dilutives) | B37: 630 | C37: ~125.5mm Class A + ~478mm Class V-1/V-3 (Up-C units) + dilutives; cross-checks to $26.8B mkt cap at $42.51
A38: Marginal tax rate (valuation) | B38: 0.25
A40: Terminal value & market inputs
A41: Terminal (perpetuity) growth rate g | B41: 0.03
A42: Exit EV / Adj. EBITDA multiple (terminal FY2035) | B42: 12
A43: Current share price (7/17-18/2026) | B43: 42.51
A44: FY2026 equity issuance (Q1 FY26 follow-on, net, $mm) | B44: 424
A46: Valuation date convention: values as of FY2026 fiscal year end (late Sept 2026); FY2027-35 FCF discounted mid-year. Exit multiple of 12x terminal EBITDA is a discount to current peer median (~18x) reflecting matured growth by FY2035.

Sheet Historicals
A1: HISTORICAL FINANCIALS & FY2026 BUILD ($mm)
B4: FY2022A | C4: FY2023A | D4: FY2024A* | E4: FY2025A | G4: Q1 FY26A | H4: Q2 FY26A | I4: Q3 FY26E | J4: Q4 FY26E | K4: FY2026E
A5: Revenue | B5: 593.3 | C5: 1176.6 | D5: 1783.3 | E5: 2246.9 | G5: 630 | H5: 676 | I5: 710 | J5: 755 | K5: =SUM(G5:J5) -> 2771
A6: % growth y/y | C6: =C5/B5-1 -> 0.98314512 | D6: =D5/C5-1 -> 0.51563828 | E6: =E5/D5-1 -> 0.25996748 | K6: =K5/E5-1 -> 0.23325471
A7: Gross profit | B7: 96.9 | C7: 192.5 | D7: 245.7 | E7: 422.6
A8: Gross margin % | B8: =B7/B5 -> 0.16332378 | C8: =C7/C5 -> 0.163607 | D8: =D7/D5 -> 0.13777828 | E8: =E7/E5 -> 0.18808136
A9: Operating income (loss) | D9: -116.7 | E9: -115
A10: Net income (loss) | B10: -139.1 | C10: -207.8 | D10: -84.7 | E10: -91 | G10: 13 | H10: 9
A11: Adjusted EBITDA | E11: 147 | G11: 67 | H11: 78 | I11: 82.5 | J11: 95 | K11: =SUM(G11:J11) -> 322.5
A12: Adj. EBITDA margin % | E12: =E11/E5 -> 0.065423472 | K12: =K11/K5 -> 0.11638398
A13: Cash & equivalents (period end) | E13: 1245 | G13: 1800 | H13: 2000
A14: Contracted backlog ($B) | E14: 22.5 | H14: 22.7
A16: * FY2024 restated (Nov-2024 revenue recognition restatement); FY2024 revenue derived from FY2025 reported +26% y/y growth. FY2023 shown as originally reported.
A17: Estimated cells ('e'): FY22/FY23 gross profit (~16.3-16.4% margin, per 10-K trend); FY24 gross profit = FY25 $422.6mm less disclosed +$176.9mm increase; FY24 net loss approximate.
A18: Q3 FY26E = management guidance midpoint (rev $700-720mm, Adj. EBITDA $80-85mm). Q4 FY26E = extrapolation (+6% q/q revenue), analyst-consensus-consistent.
A19: Q1 FY26: rev $630mm, NI $13mm, Adj. EBITDA $67mm, cash $1.8B (incl. $424mm follow-on proceeds). Q2 FY26: rev $676mm, NI $9mm, Adj. EBITDA $78mm, cash $2.0B, backlog $22.7B.
A20: Sources: SEC 8-K exhibits 99.1 (Q1 & Q2 FY26), FY2025 10-K & Q4 FY25 press release — full URLs on Cover sheet.

Sheet Model_3S
A1: 3-STATEMENT OPERATING MODEL — FY2026E–FY2035E ($mm)
A2: =CONCATENATE("Active scenario: ",CHOOSE(Assumptions!$B$4,"BASE","BULL","BEAR")) -> Active scenario: BASE
B4: FY2025A | C4: FY2026E | D4: FY2027E | E4: FY2028E | F4: FY2029E | G4: FY2030E | H4: FY2031E | I4: FY2032E | J4: FY2033E | K4: FY2034E | L4: FY2035E
A6: DRIVERS (green = linked to Assumptions; ramps are linear FY26 → FY35)
A7: Revenue growth % | C7: =C18/B18-1 -> 0.23325471 | D7: =Assumptions!$E$12+(Assumptions!$E$13-Assumptions!$E$12)*0/8 -> 0.2 | E7: =Assumptions!$E$12+(Assumptions!$E$13-Assumptions!$E$12)*1/8 -> 0.18125 | F7: =Assumptions!$E$12+(Assumptions!$E$13-Assumptions!$E$12)*2/8 -> 0.1625 | G7: =Assumptions!$E$12+(Assumptions!$E$13-Assumptions!$E$12)*3/8 -> 0.14375 | H7: =Assumptions!$E$12+(Assumptions!$E$13-Assumptions!$E$12)*4/8 -> 0.125 | I7: =Assumptions!$E$12+(Assumptions!$E$13-Assumptions!$E$12)*5/8 -> 0.10625 | J7: =Assumptions!$E$12+(Assumptions!$E$13-Assumptions!$E$12)*6/8 -> 0.0875 | K7: =Assumptions!$E$12+(Assumptions!$E$13-Assumptions!$E$12)*7/8 -> 0.06875 | L7: =Assumptions!$E$12+(Assumptions!$E$13-Assumptions!$E$12)*8/8 -> 0.05
A8: Gross margin % | C8: =Assumptions!$B$17 -> 0.205 | D8: =Assumptions!$B$17+(Assumptions!$F$17-Assumptions!$B$17)*1/9 -> 0.21555556 | E8: =Assumptions!$B$17+(Assumptions!$F$17-Assumptions!$B$17)*2/9 -> 0.22611111 | F8: =Assumptions!$B$17+(Assumptions!$F$17-Assumptions!$B$17)*3/9 -> 0.23666667 | G8: =Assumptions!$B$17+(Assumptions!$F$17-Assumptions!$B$17)*4/9 -> 0.24722222 | H8: =Assumptions!$B$17+(Assumptions!$F$17-Assumptions!$B$17)*5/9 -> 0.25777778 | I8: =Assumptions!$B$17+(Assumptions!$F$17-Assumptions!$B$17)*6/9 -> 0.26833333 | J8: =Assumptions!$B$17+(Assumptions!$F$17-Assumptions!$B$17)*7/9 -> 0.27888889 | K8: =Assumptions!$B$17+(Assumptions!$F$17-Assumptions!$B$17)*8/9 -> 0.28944444 | L8: =Assumptions!$B$17+(Assumptions!$F$17-Assumptions!$B$17)*9/9 -> 0.3
A9: R&D % rev | C9: =Assumptions!$B$18 -> 0.045 | D9: =Assumptions!$B$18+(Assumptions!$F$18-Assumptions!$B$18)*1/9 -> 0.045 | E9: =Assumptions!$B$18+(Assumptions!$F$18-Assumptions!$B$18)*2/9 -> 0.045 | F9: =Assumptions!$B$18+(Assumptions!$F$18-Assumptions!$B$18)*3/9 -> 0.045 | G9: =Assumptions!$B$18+(Assumptions!$F$18-Assumptions!$B$18)*4/9 -> 0.045 | H9: =Assumptions!$B$18+(Assumptions!$F$18-Assumptions!$B$18)*5/9 -> 0.045 | I9: =Assumptions!$B$18+(Assumptions!$F$18-Assumptions!$B$18)*6/9 -> 0.045 | J9: =Assumptions!$B$18+(Assumptions!$F$18-Assumptions!$B$18)*7/9 -> 0.045 | K9: =Assumptions!$B$18+(Assumptions!$F$18-Assumptions!$B$18)*8/9 -> 0.045 | L9: =Assumptions!$B$18+(Assumptions!$F$18-Assumptions!$B$18)*9/9 -> 0.045
A10: SG&A % rev | C10: =Assumptions!$B$19 -> 0.046 | D10: =Assumptions!$B$19+(Assumptions!$F$19-Assumptions!$B$19)*1/9 -> 0.045888889 | E10: =Assumptions!$B$19+(Assumptions!$F$19-Assumptions!$B$19)*2/9 -> 0.045777778 | F10: =Assumptions!$B$19+(Assumptions!$F$19-Assumptions!$B$19)*3/9 -> 0.045666667 | G10: =Assumptions!$B$19+(Assumptions!$F$19-Assumptions!$B$19)*4/9 -> 0.045555556 | H10: =Assumptions!$B$19+(Assumptions!$F$19-Assumptions!$B$19)*5/9 -> 0.045444444 | I10: =Assumptions!$B$19+(Assumptions!$F$19-Assumptions!$B$19)*6/9 -> 0.045333333 | J10: =Assumptions!$B$19+(Assumptions!$F$19-Assumptions!$B$19)*7/9 -> 0.045222222 | K10: =Assumptions!$B$19+(Assumptions!$F$19-Assumptions!$B$19)*8/9 -> 0.045111111 | L10: =Assumptions!$B$19+(Assumptions!$F$19-Assumptions!$B$19)*9/9 -> 0.045
A11: SBC % rev | C11: =Assumptions!$B$20 -> 0.067 | D11: =Assumptions!$B$20+(Assumptions!$F$20-Assumptions!$B$20)*1/9 -> 0.063444444 | E11: =Assumptions!$B$20+(Assumptions!$F$20-Assumptions!$B$20)*2/9 -> 0.059888889 | F11: =Assumptions!$B$20+(Assumptions!$F$20-Assumptions!$B$20)*3/9 -> 0.056333333 | G11: =Assumptions!$B$20+(Assumptions!$F$20-Assumptions!$B$20)*4/9 -> 0.052777778 | H11: =Assumptions!$B$20+(Assumptions!$F$20-Assumptions!$B$20)*5/9 -> 0.049222222 | I11: =Assumptions!$B$20+(Assumptions!$F$20-Assumptions!$B$20)*6/9 -> 0.045666667 | J11: =Assumptions!$B$20+(Assumptions!$F$20-Assumptions!$B$20)*7/9 -> 0.042111111 | K11: =Assumptions!$B$20+(Assumptions!$F$20-Assumptions!$B$20)*8/9 -> 0.038555556 | L11: =Assumptions!$B$20+(Assumptions!$F$20-Assumptions!$B$20)*9/9 -> 0.035
A12: D&A % rev | C12: =Assumptions!$B$21 -> 0.025 | D12: =Assumptions!$B$21+(Assumptions!$F$21-Assumptions!$B$21)*1/9 -> 0.025 | E12: =Assumptions!$B$21+(Assumptions!$F$21-Assumptions!$B$21)*2/9 -> 0.025 | F12: =Assumptions!$B$21+(Assumptions!$F$21-Assumptions!$B$21)*3/9 -> 0.025 | G12: =Assumptions!$B$21+(Assumptions!$F$21-Assumptions!$B$21)*4/9 -> 0.025 | H12: =Assumptions!$B$21+(Assumptions!$F$21-Assumptions!$B$21)*5/9 -> 0.025 | I12: =Assumptions!$B$21+(Assumptions!$F$21-Assumptions!$B$21)*6/9 -> 0.025 | J12: =Assumptions!$B$21+(Assumptions!$F$21-Assumptions!$B$21)*7/9 -> 0.025 | K12: =Assumptions!$B$21+(Assumptions!$F$21-Assumptions!$B$21)*8/9 -> 0.025 | L12: =Assumptions!$B$21+(Assumptions!$F$21-Assumptions!$B$21)*9/9 -> 0.025
A13: Capex % rev | C13: =Assumptions!$B$22 -> 0.03 | D13: =Assumptions!$B$22+(Assumptions!$F$22-Assumptions!$B$22)*1/9 -> 0.029444444 | E13: =Assumptions!$B$22+(Assumptions!$F$22-Assumptions!$B$22)*2/9 -> 0.028888889 | F13: =Assumptions!$B$22+(Assumptions!$F$22-Assumptions!$B$22)*3/9 -> 0.028333333 | G13: =Assumptions!$B$22+(Assumptions!$F$22-Assumptions!$B$22)*4/9 -> 0.027777778 | H13: =Assumptions!$B$22+(Assumptions!$F$22-Assumptions!$B$22)*5/9 -> 0.027222222 | I13: =Assumptions!$B$22+(Assumptions!$F$22-Assumptions!$B$22)*6/9 -> 0.026666667 | J13: =Assumptions!$B$22+(Assumptions!$F$22-Assumptions!$B$22)*7/9 -> 0.026111111 | K13: =Assumptions!$B$22+(Assumptions!$F$22-Assumptions!$B$22)*8/9 -> 0.025555556 | L13: =Assumptions!$B$22+(Assumptions!$F$22-Assumptions!$B$22)*9/9 -> 0.025
A14: Cash tax rate % | C14: =Assumptions!$B$23 -> 0.15 | D14: =Assumptions!$B$23+(Assumptions!$F$23-Assumptions!$B$23)*1/9 -> 0.16111111 | E14: =Assumptions!$B$23+(Assumptions!$F$23-Assumptions!$B$23)*2/9 -> 0.17222222 | F14: =Assumptions!$B$23+(Assumptions!$F$23-Assumptions!$B$23)*3/9 -> 0.18333333 | G14: =Assumptions!$B$23+(Assumptions!$F$23-Assumptions!$B$23)*4/9 -> 0.19444444 | H14: =Assumptions!$B$23+(Assumptions!$F$23-Assumptions!$B$23)*5/9 -> 0.20555556 | I14: =Assumptions!$B$23+(Assumptions!$F$23-Assumptions!$B$23)*6/9 -> 0.21666667 | J14: =Assumptions!$B$23+(Assumptions!$F$23-Assumptions!$B$23)*7/9 -> 0.22777778 | K14: =Assumptions!$B$23+(Assumptions!$F$23-Assumptions!$B$23)*8/9 -> 0.23888889 | L14: =Assumptions!$B$23+(Assumptions!$F$23-Assumptions!$B$23)*9/9 -> 0.25
A15: Deferred rev % rev | C15: =Assumptions!$B$24 -> 0.4 | D15: =Assumptions!$B$24+(Assumptions!$F$24-Assumptions!$B$24)*1/9 -> 0.38333333 | E15: =Assumptions!$B$24+(Assumptions!$F$24-Assumptions!$B$24)*2/9 -> 0.36666667 | F15: =Assumptions!$B$24+(Assumptions!$F$24-Assumptions!$B$24)*3/9 -> 0.35 | G15: =Assumptions!$B$24+(Assumptions!$F$24-Assumptions!$B$24)*4/9 -> 0.33333333 | H15: =Assumptions!$B$24+(Assumptions!$F$24-Assumptions!$B$24)*5/9 -> 0.31666667 | I15: =Assumptions!$B$24+(Assumptions!$F$24-Assumptions!$B$24)*6/9 -> 0.3 | J15: =Assumptions!$B$24+(Assumptions!$F$24-Assumptions!$B$24)*7/9 -> 0.28333333 | K15: =Assumptions!$B$24+(Assumptions!$F$24-Assumptions!$B$24)*8/9 -> 0.26666667 | L15: =Assumptions!$B$24+(Assumptions!$F$24-Assumptions!$B$24)*9/9 -> 0.25
A17: INCOME STATEMENT
A18: Revenue | B18: =Historicals!E5 -> 2246.9 | C18: =Historicals!K5 -> 2771 | D18: =C18*(1+D7) -> 3325.2 | E18: =D18*(1+E7) -> 3927.8925 | F18: =E18*(1+F7) -> 4566.175 | G18: =F18*(1+G7) -> 5222.5627 | H18: =G18*(1+H7) -> 5875.383 | I18: =H18*(1+I7) -> 6499.6425 | J18: =I18*(1+J7) -> 7068.3612 | K18: =J18*(1+K7) -> 7554.311 | L18: =K18*(1+L7) -> 7932.0266
A19: Cost of revenue (excl. D&A) | C19: =-C18*(1-C8) -> -2202.945 | D19: =-D18*(1-D8) -> -2608.4347 | E19: =-E18*(1-E8) -> -3039.7524 | F19: =-F18*(1-F8) -> -3485.5136 | G19: =-G18*(1-G8) -> -3931.4291 | H19: =-H18*(1-H8) -> -4360.8398 | I19: =-I18*(1-I8) -> -4755.5717 | J19: =-J18*(1-J8) -> -5097.0738 | ... L19: =-L18*(1-L8) -> -5552.4186
A20: Gross profit | C20: =C18+C19 -> 568.055 | D20: =D18+D19 -> 716.76533 | E20: =E18+E19 -> 888.14014 | F20: =F18+F19 -> 1080.6614 | G20: =G18+G19 -> 1291.1336 | H20: =H18+H19 -> 1514.5432 | I20: =I18+I19 -> 1744.0707 | J20: =J18+J19 -> 1971.2874 | ... L20: =L18+L19 -> 2379.608
A21: R&D (cash) | C21: =-C18*C9 -> -124.695 | D21: =-D18*D9 -> -149.634 | E21: =-E18*E9 -> -176.75516 | F21: =-F18*F9 -> -205.47788 | G21: =-G18*G9 -> -235.01532 | H21: =-H18*H9 -> -264.39224 | I21: =-I18*I9 -> -292.48391 | J21: =-J18*J9 -> -318.07625 | ... L21: =-L18*L9 -> -356.9412
A22: SG&A (cash) | C22: =-C18*C10 -> -127.466 | D22: =-D18*D10 -> -152.58973 | E22: =-E18*E10 -> -179.81019 | F22: =-F18*F10 -> -208.52199 | G22: =-G18*G10 -> -237.91674 | H22: =-H18*H10 -> -267.00352 | I22: =-I18*I10 -> -294.65046 | J22: =-J18*J10 -> -319.647 | ... L22: =-L18*L10 -> -356.9412
A23: Adjusted EBITDA | C23: =C20+C21+C22 -> 315.894 | D23: =D20+D21+D22 -> 414.5416 | E23: =E20+E21+E22 -> 531.57479 | F23: =F20+F21+F22 -> 666.66155 | G23: =G20+G21+G22 -> 818.20149 | H23: =H20+H21+H22 -> 983.14743 | I23: =I20+I21+I22 -> 1156.9364 | J23: =J20+J21+J22 -> 1333.5641 | ... L23: =L20+L21+L22 -> 1665.7256
A24: Stock-based compensation | C24: =-C18*C11 -> -185.657 | D24: =-D18*D11 -> -210.96547 | E24: =-E18*E11 -> -235.23712 | F24: =-F18*F11 -> -257.22786 | G24: =-G18*G11 -> -275.63525 | H24: =-H18*H11 -> -289.19941 | I24: =-I18*I11 -> -296.81701 | J24: =-J18*J11 -> -297.65654 | ... L24: =-L18*L11 -> -277.62093
A25: Depreciation & amortization | C25: =-C18*C12 -> -69.275 | D25: =-D18*D12 -> -83.13 | E25: =-E18*E12 -> -98.197312 | F25: =-F18*F12 -> -114.15438 | G25: =-G18*G12 -> -130.56407 | H25: =-H18*H12 -> -146.88458 | I25: =-I18*I12 -> -162.49106 | J25: =-J18*J12 -> -176.70903 | ... L25: =-L18*L12 -> -198.30066
A26: EBIT (operating income) | C26: =C23+C24+C25 -> 60.962 | D26: =D23+D24+D25 -> 120.44613 | E26: =E23+E24+E25 -> 198.14035 | F26: =F23+F24+F25 -> 295.27932 | G26: =G23+G24+G25 -> 412.00217 | H26: =H23+H24+H25 -> 547.06344 | I26: =I23+I24+I25 -> 697.62829 | J26: =J23+J24+J25 -> 859.19857 | ... L26: =L23+L24+L25 -> 1189.804
A27: Interest income (on beginning cash) | C27: =B70*Assumptions!$B$34 -> 49.8 | D27: =C70*Assumptions!$B$34 -> 83.455955 | E27: =D70*Assumptions!$B$34 -> 104.50334 | F27: =E70*Assumptions!$B$34 -> 129.60609 | G27: =F70*Assumptions!$B$34 -> 159.09984 | H27: =G70*Assumptions!$B$34 -> 193.23311 | I27: =H70*Assumptions!$B$34 -> 232.14084 | J27: =I70*Assumptions!$B$34 -> 275.82172 | ... L27: =K70*Assumptions!$B$34 -> 376.72807
A28: Interest expense (on beginning debt) | C28: =-B56*Assumptions!$B$35 -> 0 | D28: =-C56*Assumptions!$B$35 -> 0 | E28: =-D56*Assumptions!$B$35 -> 0 | F28: =-E56*Assumptions!$B$35 -> 0 | G28: =-F56*Assumptions!$B$35 -> 0 | H28: =-G56*Assumptions!$B$35 -> 0 | I28: =-H56*Assumptions!$B$35 -> 0 | J28: =-I56*Assumptions!$B$35 -> 0 | ... L28: =-K56*Assumptions!$B$35 -> 0
A29: Pre-tax income | C29: =C26+C27+C28 -> 110.762 | D29: =D26+D27+D28 -> 203.90209 | E29: =E26+E27+E28 -> 302.64369 | F29: =F26+F27+F28 -> 424.88541 | G29: =G26+G27+G28 -> 571.102 | H29: =H26+H27+H28 -> 740.29655 | I29: =I26+I27+I28 -> 929.76913 | J29: =J26+J27+J28 -> 1135.0203 | ... L29: =L26+L27+L28 -> 1566.5321
A30: Taxes (cash rate; NOL ramp) | C30: =-MAX(0,C29)*C14 -> -16.6143 | D30: =-MAX(0,D29)*D14 -> -32.850892 | E30: =-MAX(0,E29)*E14 -> -52.121969 | F30: =-MAX(0,F29)*F14 -> -77.895658 | G30: =-MAX(0,G29)*G14 -> -111.04761 | H30: =-MAX(0,H29)*H14 -> -152.17207 | I30: =-MAX(0,I29)*I14 -> -201.44998 | J30: =-MAX(0,J29)*J14 -> -258.5324 | ... L30: =-MAX(0,L29)*L14 -> -391.63301
A31: Net income | C31: =C29+C30 -> 94.1477 | D31: =D29+D30 -> 171.0512 | E31: =E29+E30 -> 250.52172 | F31: =F29+F30 -> 346.98975 | G31: =G29+G30 -> 460.05439 | H31: =H29+H30 -> 588.12448 | I31: =I29+I30 -> 728.31916 | J31: =J29+J30 -> 876.48789 | ... L31: =L29+L30 -> 1174.899
A32: Adj. EBITDA margin % | C32: =C23/C18 -> 0.114 | D32: =D23/D18 -> 0.12466667 | E32: =E23/E18 -> 0.13533333 | F32: =F23/F18 -> 0.146 | G32: =G23/G18 -> 0.15666667 | H32: =H23/H18 -> 0.16733333 | I32: =I23/I18 -> 0.178 | J32: =J23/J18 -> 0.18866667 | ... L32: =L23/L18 -> 0.21
A35: WORKING CAPITAL
A36: Accounts receivable | B36: 380 | C36: =C18*Assumptions!$B$27/365 -> 341.63014 | D36: =D18*Assumptions!$B$27/365 -> 409.95616 | E36: =E18*Assumptions!$B$27/365 -> 484.26072 | F36: =F18*Assumptions!$B$27/365 -> 562.95309 | G36: =G18*Assumptions!$B$27/365 -> 643.87759 | H36: =H18*Assumptions!$B$27/365 -> 724.36229 | I36: =I18*Assumptions!$B$27/365 -> 801.32578 | J36: =J18*Assumptions!$B$27/365 -> 871.44179 | ... L36: =L18*Assumptions!$B$27/365 -> 977.92108 | M36: FY2025A column: estimated opening balances (10-K line detail not retrievable); liabilities shown negative
A37: Inventory | B37: 360 | C37: =-C19*Assumptions!$B$28/365 -> 331.95062 | D37: =-D19*Assumptions!$B$28/365 -> 393.0518 | E37: =-E19*Assumptions!$B$28/365 -> 458.04488 | F37: =-F19*Assumptions!$B$28/365 -> 525.21438 | G37: =-G19*Assumptions!$B$28/365 -> 592.40713 | H37: =-H19*Assumptions!$B$28/365 -> 657.11285 | I37: =-I19*Assumptions!$B$28/365 -> 716.593 | J37: =-J19*Assumptions!$B$28/365 -> 768.05222 | ... L37: =-L19*Assumptions!$B$28/365 -> 836.66582
A38: Other current assets | B38: 80 | C38: =C18*Assumptions!$B$31 -> 83.13 | D38: =D18*Assumptions!$B$31 -> 99.756 | E38: =E18*Assumptions!$B$31 -> 117.83678 | F38: =F18*Assumptions!$B$31 -> 136.98525 | G38: =G18*Assumptions!$B$31 -> 156.67688 | H38: =H18*Assumptions!$B$31 -> 176.26149 | I38: =I18*Assumptions!$B$31 -> 194.98927 | J38: =J18*Assumptions!$B$31 -> 212.05084 | ... L38: =L18*Assumptions!$B$31 -> 237.9608
A39: Accounts payable | B39: -450 | C39: =C19*Assumptions!$B$29/365 -> -452.65993 | D39: =D19*Assumptions!$B$29/365 -> -535.97973 | E39: =E19*Assumptions!$B$29/365 -> -624.60665 | F39: =F19*Assumptions!$B$29/365 -> -716.20143 | G39: =G19*Assumptions!$B$29/365 -> -807.8279 | H39: =H19*Assumptions!$B$29/365 -> -896.06298 | I39: =I19*Assumptions!$B$29/365 -> -977.17228 | J39: =J19*Assumptions!$B$29/365 -> -1047.3439 | ... L39: =L19*Assumptions!$B$29/365 -> -1140.9079
A40: Accrued liabilities | B40: -250 | C40: =-C18*Assumptions!$B$30 -> -277.1 | D40: =-D18*Assumptions!$B$30 -> -332.52 | E40: =-E18*Assumptions!$B$30 -> -392.78925 | F40: =-F18*Assumptions!$B$30 -> -456.6175 | G40: =-G18*Assumptions!$B$30 -> -522.25627 | H40: =-H18*Assumptions!$B$30 -> -587.5383 | I40: =-I18*Assumptions!$B$30 -> -649.96425 | J40: =-J18*Assumptions!$B$30 -> -706.83612 | ... L40: =-L18*Assumptions!$B$30 -> -793.20266
A41: Deferred revenue & customer deposits | B41: -1050 | C41: =-C18*C15 -> -1108.4 | D41: =-D18*D15 -> -1274.66 | E41: =-E18*E15 -> -1440.2272 | F41: =-F18*F15 -> -1598.1613 | G41: =-G18*G15 -> -1740.8542 | H41: =-H18*H15 -> -1860.538 | I41: =-I18*I15 -> -1949.8927 | J41: =-J18*J15 -> -2002.7023 | ... L41: =-L18*L15 -> -1983.0066
A42: Net working capital | B42: =SUM(B36:B41) -> -930 | C42: =SUM(C36:C41) -> -1081.4492 | D42: =SUM(D36:D41) -> -1240.3958 | E42: =SUM(E36:E41) -> -1397.4808 | F42: =SUM(F36:F41) -> -1545.8275 | G42: =SUM(G36:G41) -> -1677.9768 | H42: =SUM(H36:H41) -> -1786.4026 | I42: =SUM(I36:I41) -> -1864.1212 | ... L42: =SUM(L36:L41) -> -1864.5695
A43: (Increase) / decrease in NWC — cash impact | C43: =-(C42-B42) -> 151.44918 | D43: =-(D42-C42) -> 158.94658 | E43: =-(E42-D42) -> 157.08502 | F43: =-(F42-E42) -> 148.34669 | G43: =-(G42-F42) -> 132.14933 | H43: =-(H42-G42) -> 108.42581 | I43: =-(I42-H42) -> 77.718596 | J43: =-(J42-I42) -> 41.21634 | ... L43: =-(L42-K42) -> -41.485471
A45: CAPEX & PP&E (incl. capitalized software & intangibles)
A46: Capex | C46: =C18*C13 -> 83.13 | D46: =D18*D13 -> 97.908667 | E46: =E18*E13 -> 113.47245 | F46: =F18*F13 -> 129.37496 | G46: =G18*G13 -> 145.07119 | H46: =H18*H13 -> 159.94098 | I46: =I18*I13 -> 173.3238 | J46: =J18*J13 -> 184.56276 | ... L46: =L18*L13 -> 198.30066
...

Sheet WACC
A1: WEIGHTED AVERAGE COST OF CAPITAL — CURRENT MARKET DATA (JULY 2026)
A4: COST OF EQUITY (CAPM)
A5: Risk-free rate — 10Y UST, 7/17/2026 | B5: 0.0455 | C5: tradingeconomics.com / FRED DGS10
A6: Levered beta (5-year; sources range 1.6–2.1) | B6: 1.9 | C6: investing.com 5-yr beta 2.14; yahoo ~1.9; stockanalysis 1.58 — 1.90 selected
A7: Equity risk premium | B7: 0.0475 | C7: Damodaran implied ERP, mid-2026 (~4.5–5.0%)
A8: Company-specific / execution premium | B8: 0 | C8: Optional adder for customer concentration (Walmart ~85% of revenue)
A9: Cost of equity | B9: =B5+B6*B7+B8 -> 0.13575
A11: COST OF DEBT
A12: Pre-tax cost of debt (hypothetical IG-crossover issue) | B12: 0.065 | C12: ~10Y UST + 195bp; SYM currently has no debt
A13: Tax rate | B13: =Assumptions!B38 -> 0.25
A14: After-tax cost of debt | B14: =B12*(1-B13) -> 0.04875
A16: CAPITAL STRUCTURE (target)
A17: Debt / total capital | B17: 0.02 | C17: Effectively all-equity; nominal 2% weight
A18: Equity / total capital | B18: =1-B17 -> 0.98
A20: WACC | B20: =B18*B9+B17*B14 -> 0.13401
A22: Sensitivity range used in DCF tables: 11.5% – 15.5%. High beta reflects post-SPAC volatility, customer concentration and restatement history.

Sheet DCF
A1: DISCOUNTED CASH FLOW — UNLEVERED FCF ($mm; valuation as of FY2026 year-end, mid-year convention)
B4: FY2027E | C4: FY2028E | D4: FY2029E | E4: FY2030E | F4: FY2031E | G4: FY2032E | H4: FY2033E | I4: FY2034E | J4: FY2035E
A5: EBIT (post-SBC) | B5: =Model_3S!D26 -> 120.44613 | C5: =Model_3S!E26 -> 198.14035 | D5: =Model_3S!F26 -> 295.27932 | E5: =Model_3S!G26 -> 412.00217 | F5: =Model_3S!H26 -> 547.06344 | G5: =Model_3S!I26 -> 697.62829 | H5: =Model_3S!J26 -> 859.19857 | I5: =Model_3S!K26 -> 1025.7076 | J5: =Model_3S!L26 -> 1189.804
A6: Cash taxes on EBIT | B6: =-MAX(0,B5)*Model_3S!D14 -> -19.40521 | C6: =-MAX(0,C5)*Model_3S!E14 -> -34.124172 | D6: =-MAX(0,D5)*Model_3S!F14 -> -54.134542 | E6: =-MAX(0,E5)*Model_3S!G14 -> -80.111533 | F6: =-MAX(0,F5)*Model_3S!H14 -> -112.45193 | G6: =-MAX(0,G5)*Model_3S!I14 -> -151.1528 | H6: =-MAX(0,H5)*Model_3S!J14 -> -195.70634 | I6: =-MAX(0,I5)*Model_3S!K14 -> -245.03014 | J6: =-MAX(0,J5)*Model_3S!L14 -> -297.451
A7: + D&A | B7: =-Model_3S!D25 -> 83.13 | C7: =-Model_3S!E25 -> 98.197312 | D7: =-Model_3S!F25 -> 114.15438 | E7: =-Model_3S!G25 -> 130.56407 | F7: =-Model_3S!H25 -> 146.88458 | G7: =-Model_3S!I25 -> 162.49106 | H7: =-Model_3S!J25 -> 176.70903 | I7: =-Model_3S!K25 -> 188.85778 | J7: =-Model_3S!L25 -> 198.30066
A8: − Capex | B8: =-Model_3S!D46 -> -97.908667 | C8: =-Model_3S!E46 -> -113.47245 | D8: =-Model_3S!F46 -> -129.37496 | E8: =-Model_3S!G46 -> -145.07119 | F8: =-Model_3S!H46 -> -159.94098 | G8: =-Model_3S!I46 -> -173.3238 | H8: =-Model_3S!J46 -> -184.56276 | I8: =-Model_3S!K46 -> -193.05462 | J8: =-Model_3S!L46 -> -198.30066
A9: +/− Change in NWC | B9: =Model_3S!D43 -> 158.94658 | C9: =Model_3S!E43 -> 157.08502 | D9: =Model_3S!F43 -> 148.34669 | E9: =Model_3S!G43 -> 132.14933 | F9: =Model_3S!H43 -> 108.42581 | G9: =Model_3S!I43 -> 77.718596 | H9: =Model_3S!J43 -> 41.21634 | I9: =Model_3S!K43 -> 0.71746018 | J9: =Model_3S!L43 -> -41.485471
A10: Unlevered free cash flow | B10: =SUM(B5:B9) -> 245.20884 | C10: =SUM(C5:C9) -> 305.82606 | D10: =SUM(D5:D9) -> 374.27089 | E10: =SUM(E5:E9) -> 449.53284 | F10: =SUM(F5:F9) -> 529.98091 | G10: =SUM(G5:G9) -> 613.36135 | H10: =SUM(H5:H9) -> 696.85484 | I10: =SUM(I5:I9) -> 777.19804 | J10: =SUM(J5:J9) -> 850.86752
A11: Discount period (mid-year) | B11: 0.5 | C11: 1.5 | D11: 2.5 | E11: 3.5 | F11: 4.5 | G11: 5.5 | H11: 6.5 | I11: 7.5 | J11: 8.5
A12: Discount factor @ WACC | B12: =(1+$B$16)^-B11 -> 0.93905614 | C12: =(1+$B$16)^-C11 -> 0.82808453 | D12: =(1+$B$16)^-D11 -> 0.73022684 | E12: =(1+$B$16)^-E11 -> 0.64393333 | F12: =(1+$B$16)^-F11 -> 0.56783744 | G12: =(1+$B$16)^-G11 -> 0.50073406 | H12: =(1+$B$16)^-H11 -> 0.44156054 | I12: =(1+$B$16)^-I11 -> 0.38937976 | J12: =(1+$B$16)^-J11 -> 0.34336536
A13: PV of FCF | B13: =B10*B12 -> 230.26487 | C13: =C10*C12 -> 253.24983 | D13: =D10*D12 -> 273.30265 | E13: =E10*E12 -> 289.46918 | F13: =F10*F12 -> 300.943 | G13: =G10*G12 -> 307.13092 | H13: =H10*H12 -> 307.70359 | I13: =I10*I12 -> 302.62518 | J13: =J10*J12 -> 292.15843
A14: SBC treated as a cash-like expense (deducted in EBIT, not added back) — conservative; avoids double-count with fixed share count.
A15: Sum of PV of explicit FCF (FY27–35) | B15: =SUM(B13:J13) -> 2556.8477
A16: WACC | B16: =WACC!B20 -> 0.13401
A18: TERMINAL VALUE — METHOD 1: GORDON GROWTH
A19: Terminal growth g | B19: =Assumptions!B41 -> 0.03
A20: Terminal value = FCF35 × (1+g) / (WACC − g) | B20: =J10*(1+B19)/(B16-B19) -> 8426.0508
A21: PV of terminal value (discounted 9.0 yrs) | B21: =B20/(1+B16)^9 -> 2716.8904
A22: Implied exit EV/EBITDA on FY35 Adj. EBITDA | B22: =B20/Model_3S!L23 -> 5.0584868
A24: TERMINAL VALUE — METHOD 2: EXIT MULTIPLE
A25: Exit EV/Adj. EBITDA multiple | B25: =Assumptions!B42 -> 12
A26: Terminal value = multiple × FY35 Adj. EBITDA | B26: =B25*Model_3S!L23 -> 19988.707
A27: PV of terminal value | B27: =B26/(1+B16)^9 -> 6445.1457
A28: Implied perpetuity growth from exit TV | B28: =(B16*B26-J10)/(B26+J10) -> 0.087709041
A30: ENTERPRISE → EQUITY VALUE BRIDGE
A31: Net cash, FY2026E year-end (incl. customer prepayments) | B31: =Model_3S!C70-Model_3S!C56 -> 2086.3989
A32: Diluted shares (mm) | B32: =Assumptions!B37 -> 630
B33: Gordon growth | C33: Exit multiple | D33: Average
A34: Enterprise value | B34: =B15+B21 -> 5273.738 | C34: =B15+B27 -> 9001.9934 | D34: =AVERAGE(B34:C34) -> 7137.8657
A35: + Net cash | B35: =$B$31 -> 2086.3989 | C35: =$B$31 -> 2086.3989 | D35: =$B$31 -> 2086.3989
A36: Equity value | B36: =B34+B35 -> 7360.1369 | C36: =C34+C35 -> 11088.392 | D36: =D34+D35 -> 9224.2646
A37: Implied value per share | B37: =B36/$B$32 -> 11.682757 | C37: =C36/$B$32 -> 17.600623 | D37: =D36/$B$32 -> 14.64169
A38: Upside / (downside) vs current price | B38: =B37/Assumptions!$B$43-1 -> -0.72517626 | C38: =C37/Assumptions!$B$43-1 -> -0.58596512 | D38: =D37/Assumptions!$B$43-1 -> -0.65557069
A40: Interpretation: at ~13.4% WACC the DCF values SYM well below its market price — the market is pricing faster backlog conversion, GreenBox/new-vertical upside and margin expansion beyond the Base case. Toggle Bull (Assumptions!B4=2) and/or lower WACC to see implied expectations.
A42: SENSITIVITY — VALUE PER SHARE: WACC × TERMINAL GROWTH (Gordon)
B43: WACC \ g | C43: 0.02 | D43: 0.025 | E43: 0.03 | F43: 0.035 | G43: 0.04
B44: 0.115 | C44: =(SUMPRODUCT($B$10:$J$10,(1+$B$44)^-($B$11:$J$11))+$J$10*(1+C$43)/($B$44-C$43)/(1+$B$44)^9+$B$31)/$B$32 -> 13.153062 | D44: =(SUMPRODUCT($B$10:$J$10,(1+$B$44)^-($B$11:$J$11))+$J$10*(1+D$43)/($B$44-D$43)/(1+$B$44)^9+$B$31)/$B$32 -> 13.48368 | E44: =(SUMPRODUCT($B$10:$J$10,(1+$B$44)^-($B$11:$J$11))+$J$10*(1+E$43)/($B$44-E$43)/(1+$B$44)^9+$B$31)/$B$32 -> 13.853194 | F44: =(SUMPRODUCT($B$10:$J$10,(1+$B$44)^-($B$11:$J$11))+$J$10*(1+F$43)/($B$44-F$43)/(1+$B$44)^9+$B$31)/$B$32 -> 14.268897 | G44: =(SUMPRODUCT($B$10:$J$10,(1+$B$44)^-($B$11:$J$11))+$J$10*(1+G$43)/($B$44-G$43)/(1+$B$44)^9+$B$31)/$B$32 -> 14.740028
B45: 0.125 | C45: =(SUMPRODUCT($B$10:$J$10,(1+$B$45)^-($B$11:$J$11))+$J$10*(1+C$43)/($B$45-C$43)/(1+$B$45)^9+$B$31)/$B$32 -> 12.071014 | D45: =(SUMPRODUCT($B$10:$J$10,(1+$B$45)^-($B$11:$J$11))+$J$10*(1+D$43)/($B$45-D$43)/(1+$B$45)^9+$B$31)/$B$32 -> 12.321673 | E45: =(SUMPRODUCT($B$10:$J$10,(1+$B$45)^-($B$11:$J$11))+$J$10*(1+E$43)/($B$45-E$43)/(1+$B$45)^9+$B$31)/$B$32 -> 12.598716 | F45: =(SUMPRODUCT($B$10:$J$10,(1+$B$45)^-($B$11:$J$11))+$J$10*(1+F$43)/($B$45-F$43)/(1+$B$45)^9+$B$31)/$B$32 -> 12.906542 | G45: =(SUMPRODUCT($B$10:$J$10,(1+$B$45)^-($B$11:$J$11))+$J$10*(1+G$43)/($B$45-G$43)/(1+$B$45)^9+$B$31)/$B$32 -> 13.250582
B46: 0.134 | C46: =(SUMPRODUCT($B$10:$J$10,(1+$B$46)^-($B$11:$J$11))+$J$10*(1+C$43)/($B$46-C$43)/(1+$B$46)^9+$B$31)/$B$32 -> 11.267121 | D46: =(SUMPRODUCT($B$10:$J$10,(1+$B$46)^-($B$11:$J$11))+$J$10*(1+D$43)/($B$46-D$43)/(1+$B$46)^9+$B$31)/$B$32 -> 11.465847 | E46: =(SUMPRODUCT($B$10:$J$10,(1+$B$46)^-($B$11:$J$11))+$J$10*(1+E$43)/($B$46-E$43)/(1+$B$46)^9+$B$31)/$B$32 -> 11.683682 | F46: =(SUMPRODUCT($B$10:$J$10,(1+$B$46)^-($B$11:$J$11))+$J$10*(1+F$43)/($B$46-F$43)/(1+$B$46)^9+$B$31)/$B$32 -> 11.92352 | G46: =(SUMPRODUCT($B$10:$J$10,(1+$B$46)^-($B$11:$J$11))+$J$10*(1+G$43)/($B$46-G$43)/(1+$B$46)^9+$B$31)/$B$32 -> 12.188873
B47: 0.145 | C47: =(SUMPRODUCT($B$10:$J$10,(1+$B$47)^-($B$11:$J$11))+$J$10*(1+C$43)/($B$47-C$43)/(1+$B$47)^9+$B$31)/$B$32 -> 10.450024 | D47: =(SUMPRODUCT($B$10:$J$10,(1+$B$47)^-($B$11:$J$11))+$J$10*(1+D$43)/($B$47-D$43)/(1+$B$47)^9+$B$31)/$B$32 -> 10.602414 | E47: =(SUMPRODUCT($B$10:$J$10,(1+$B$47)^-($B$11:$J$11))+$J$10*(1+E$43)/($B$47-E$43)/(1+$B$47)^9+$B$31)/$B$32 -> 10.768055 | F47: =(SUMPRODUCT($B$10:$J$10,(1+$B$47)^-($B$11:$J$11))+$J$10*(1+F$43)/($B$47-F$43)/(1+$B$47)^9+$B$31)/$B$32 -> 10.948755 | G47: =(SUMPRODUCT($B$10:$J$10,(1+$B$47)^-($B$11:$J$11))+$J$10*(1+G$43)/($B$47-G$43)/(1+$B$47)^9+$B$31)/$B$32 -> 11.146664
...

Sheet Comps
A1: TRADING COMPARABLES — WAREHOUSE / INDUSTRIAL AUTOMATION (July 2026)
A4: Company | B4: Ticker | C4: EV/Revenue | D4: EV/EBITDA | E4: Note
A5: Daifuku Co. | B5: 6383.T | C5: 3.2 | D5: 18.8 | E5: Market cap ~$15B; multiples per multiples.vc, Jul-2026
A6: Rockwell Automation | B6: ROK | C6: 6.3 | D6: 28.2 | E6: LTM per multiples.vc Jun-2026 (24.3x NTM)
A7: KION Group (incl. Dematic) | B7: KGX.DE | C7: 0.9 | D7: 7.6 | E7: LTM EV/EBITDA per finbox/gurufocus; EV/Rev estimated
A8: Zebra Technologies | B8: ZBRA | C8: 3.4 | D8: 14 | E8: e — estimated from historical trading range
A9: Cognex | B9: CGNX | C9: 7 | D9: 30 | E9: e — estimated from historical trading range
A10: AutoStore Holdings | B10: AUTO.OL | C10: 5.5 | D10: 17 | E10: e — estimated from historical trading range
A11: Median | C11: =MEDIAN(C5:C10) -> 4.45 | D11: =MEDIAN(D5:D10) -> 17.9
A12: Mean | C12: =AVERAGE(C5:C10) -> 4.3833333 | D12: =AVERAGE(D5:D10) -> 19.266667
A14: SYM CURRENT MULTIPLES (for reference)
A15: Current EV = price × shares − net cash | B15: =Assumptions!B43*Assumptions!B37-DCF!B31 -> 24694.901
A16: EV / FY2026E revenue | B16: =B15/Model_3S!C18 -> 8.9119095 | C16: SYM trades far above peer medians — the market caps its $22.7B backlog and software mix, not current-year financials
A17: EV / FY2026E Adj. EBITDA | B17: =B15/Model_3S!C23 -> 78.174644
A19: IMPLIED VALUE PER SHARE FROM PEER MULTIPLES
A20: Method | B20: Low x | C20: High x | D20: Metric ($mm) | E20: Implied EV low | F20: Implied EV high | G20: $/sh low | H20: $/sh high
A21: EV/Revenue × FY2026E revenue | B21: 3.2 | C21: 6.5 | D21: =Model_3S!C18 -> 2771 | E21: =B21*D21 -> 8867.2 | F21: =C21*D21 -> 18011.5 | G21: =(E21+DCF!$B$31)/Assumptions!$B$37 -> 17.386665 | H21: =(F21+DCF!$B$31)/Assumptions!$B$37 -> 31.901427
A22: EV/EBITDA × FY2027E Adj. EBITDA | B22: 15 | C22: 28 | D22: =Model_3S!D23 -> 414.5416 | E22: =B22*D22 -> 6218.124 | F22: =C22*D22 -> 11607.165 | G22: =(E22+DCF!$B$31)/Assumptions!$B$37 -> 13.181782 | H22: =(F22+DCF!$B$31)/Assumptions!$B$37 -> 21.735815
A24: Low/high bands span peer 25th–90th percentile. FY27E EBITDA used for the EBITDA method because FY26 margins are still ramping.

Sheet Precedents
A1: PRECEDENT TRANSACTIONS — WAREHOUSE AUTOMATION / ROBOTICS
A4: Date | B4: Acquirer | C4: Target | D4: EV ($mm) | E4: EV/Revenue | F4: Note
A5: Jun-2016 | B5: KION Group | C5: Dematic | D5: 3250 | E5: 1.8 | F5: ~$1.8B revenue systems integrator; ~10-13x EBITDA (e)
A6: Jul-2016 | B6: Honeywell | C6: Intelligrated | D6: 1500 | E6: 1.7 | F6: ~$900mm revenue (e)
A7: Jul-2021 | B7: Zebra Technologies | C7: Fetch Robotics | D7: 305 | E7: 10 | F7: AMR startup; revenue multiple estimated (e)
A8: Jul-2021 | B8: ABB | C8: ASTI Mobile Robotics | D8: 190 | E8: 4 | F8: terms not disclosed; estimated (e)
A9: Sep-2023 | B9: Rockwell Automation | C9: Clearpath / OTTO Motors | D9: 600 | E9: 10 | F9: AMR; both figures estimated (e)
A10: Mar-2023 | B10: SoftBank | C10: Berkshire Grey (take-private) | D10: 375 | E10: 4.6 | F10: ~$81mm LTM revenue; distressed
A11: Median EV/Revenue | E11: =MEDIAN(E5:E10) -> 4.3
A13: APPLIED RANGE
A14: Mature integrators transact at ~1.5–2.0x revenue; scarce high-growth robotics platforms at 4–10x. A control premium on SYM would price off backlog, not trailing revenue — band reflects that spread.
B15: Low | C15: High
A16: EV/Revenue applied to FY2026E revenue | B16: 2 | C16: 6
A17: Implied EV | B17: =B16*Model_3S!C18 -> 5542 | C17: =C16*Model_3S!C18 -> 16626
A18: Implied value per share | B18: =(B17+DCF!$B$31)/Assumptions!$B$37 -> 12.10857 | C18: =(C17+DCF!$B$31)/Assumptions!$B$37 -> 29.70222

Sheet LBO
A1: LBO ANALYSIS — 5-YEAR HOLD (ENTRY END-FY2026, EXIT END-FY2031) ($mm)
A4: ENTRY & FINANCING ASSUMPTIONS
A5: Entry premium to current price | B5: 0.2
A6: Entry price per share | B6: =Assumptions!B43*(1+B5) -> 51.012
A7: Diluted shares (mm) | B7: =Assumptions!B37 -> 630
A8: Equity purchase price | B8: =B6*B7 -> 32137.56
A9: Less: net cash at close (swept to fund deal) | B9: =DCF!B31 -> 2086.3989
A10: Entry enterprise value | B10: =B8-B9 -> 30051.161
A11: Transaction fees (% of EV) | B11: 0.02
A12: FY2026E Adj. EBITDA (debt sizing basis) | B12: =Model_3S!C23 -> 315.894
A13: Debt tranche | B13: Multiple | C13: Rate | D13: Amount
A14: Term Loan B | B14: 4 | C14: 0.08 | D14: =B14*$B$12 -> 1263.576
A15: Subordinated notes | B15: 0.5 | C15: 0.105 | D15: =B15*$B$12 -> 157.947
A16: Total debt | B16: =B14+B15 -> 4.5 | D16: =D14+D15 -> 1421.523
A18: SOURCES & USES
A19: Sources | B19: $ | C19: Uses | D19: $
A20: Term Loan B | B20: =D14 -> 1263.576 | C20: Equity purchase | D20: =B8 -> 32137.56
A21: Subordinated notes | B21: =D15 -> 157.947 | C21: Transaction fees | D21: =B11*B10 -> 601.02322
A22: Company net cash | B22: =B9 -> 2086.3989
A23: Sponsor equity (plug) | B23: =D24-B20-B21-B22 -> 29230.661
A24: Total sources | B24: =SUM(B20:B23) -> 32738.583 | C24: Total uses | D24: =D20+D21 -> 32738.583
A26: DEBT PAYDOWN — 100% FCF SWEEP (FCF from operating model, scenario-driven)
B27: FY2027E | C27: FY2028E | D27: FY2029E | E27: FY2030E | F27: FY2031E
A28: Unlevered FCF (DCF sheet) | B28: =DCF!B10 -> 245.20884 | C28: =DCF!C10 -> 305.82606 | D28: =DCF!D10 -> 374.27089 | E28: =DCF!E10 -> 449.53284 | F28: =DCF!F10 -> 529.98091
A29: Cash interest — TLB (beginning balance) | B29: =-$D$14*$C$14 -> -101.08608 | C29: =-B35*$C$14 -> -88.529604 | D29: =-C35*$C$14 -> -70.370361 | E29: =-D35*$C$14 -> -45.645978 | F29: =-E35*$C$14 -> -13.417175
A30: Cash interest — Sub notes | B30: =-$D$15*$C$15 -> -16.584435 | C30: =-$D$15*$C$15 -> -16.584435 | D30: =-$D$15*$C$15 -> -16.584435 | E30: =-$D$15*$C$15 -> -16.584435 | F30: =-$D$15*$C$15 -> -16.584435
A31: Interest tax shield | B31: =-(B29+B30)*Assumptions!$B$38 -> 29.417629 | C31: =-(C29+C30)*Assumptions!$B$38 -> 26.27851 | D31: =-(D29+D30)*Assumptions!$B$38 -> 21.738699 | E31: =-(E29+E30)*Assumptions!$B$38 -> 15.557603 | F31: =-(F29+F30)*Assumptions!$B$38 -> 7.5004025
A32: Levered FCF available for paydown | B32: =MAX(0,B28+B29+B30+B31) -> 156.95595 | C32: =MAX(0,C28+C29+C30+C31) -> 226.99053 | D32: =MAX(0,D28+D29+D30+D31) -> 309.05479 | E32: =MAX(0,E28+E29+E30+E31) -> 402.86003 | F32: =MAX(0,F28+F29+F30+F31) -> 507.4797
A33: TLB — beginning | B33: =$D$14 -> 1263.576 | C33: =B35 -> 1106.62 | D33: =C35 -> 879.62951 | E33: =D35 -> 570.57472 | F33: =E35 -> 167.71469
A34: TLB — (paydown) | B34: =-MIN(B33,B32) -> -156.95595 | C34: =-MIN(C33,C32) -> -226.99053 | D34: =-MIN(D33,D32) -> -309.05479 | E34: =-MIN(E33,E32) -> -402.86003 | F34: =-MIN(F33,F32) -> -167.71469
A35: TLB — ending | B35: =B33+B34 -> 1106.62 | C35: =C33+C34 -> 879.62951 | D35: =D33+D34 -> 570.57472 | E35: =E33+E34 -> 167.71469 | F35: =F33+F34 -> 0
A36: Sub notes — ending (bullet) | B36: =$D$15 -> 157.947 | C36: =$D$15 -> 157.947 | D36: =$D$15 -> 157.947 | E36: =$D$15 -> 157.947 | F36: =$D$15 -> 157.947
A37: Total debt — ending | B37: =B35+B36 -> 1264.567 | C37: =C35+C36 -> 1037.5765 | D37: =D35+D36 -> 728.52172 | E37: =E35+E36 -> 325.66169 | F37: =F35+F36 -> 157.947
A39: EXIT & RETURNS
A40: FY2031E Adj. EBITDA | B40: =Model_3S!H23 -> 983.14743
A41: Exit EV/EBITDA multiple | B41: 12
A42: Exit enterprise value | B42: =B40*B41 -> 11797.769
A43: Less: exit net debt | B43: =-F37 -> -157.947
A44: Exit equity value | B44: =B42+B43 -> 11639.822
A45: MOIC | B45: =B44/B23 -> 0.39820591
...

Sheet Monte_Carlo
A1: MONTE CARLO SIMULATION — 500 LIVE TRIALS (press F9 / recalc to refresh draws)
A2: Compact DCF per trial: Rev FY35 = FY26E rev × (1+avg growth)^9; TV = exit multiple × terminal EBITDA; PV of interim FCF scaled from the full DCF. Calibrated to match the DCF sheet at base-case inputs.
A4: Distribution parameters — Normal(mean, σ)
A5: Variable | B5: Mean (linked) | C5: σ (input)
A6: FY2027 revenue growth | B6: =Assumptions!E12 -> 0.2 | C6: 0.04
A7: Terminal Adj. EBITDA margin (FY35) | B7: =Assumptions!F17-Assumptions!F18-Assumptions!F19 -> 0.21 | C7: 0.03
A8: WACC | B8: =WACC!B20 -> 0.13401 | C8: 0.01
A9: Exit EV/EBITDA multiple | B9: =Assumptions!B42 -> 12 | C9: 2
A11: Calibration statics (linked)
A12: Base FY2035 Adj. EBITDA | B12: =Model_3S!L23 -> 1665.7256
A13: Base PV of explicit FCF (DCF) | B13: =DCF!B15 -> 2556.8477
A14: Net cash FY2026E | B14: =DCF!B31 -> 2086.3989
A15: Diluted shares (mm) | B15: =Assumptions!B37 -> 630
A16: Current share price | B16: =Assumptions!B43 -> 42.51
A17: FY2035 growth (selected) | B17: =Assumptions!E13 -> 0.05
A18: FY2026E revenue | B18: =Model_3S!C18 -> 2771
A20: Simulation results ($/share)
A21: Mean | B21: =AVERAGE($K$41:$K$540) -> 17.691873
A22: Median | B22: =MEDIAN($K$41:$K$540) -> 17.080109
A23: Standard deviation | B23: =STDEV($K$41:$K$540) -> 3.7870852
A24: 5th percentile | B24: =PERCENTILE($K$41:$K$540,0.05) -> 12.248174
A25: 25th percentile | B25: =PERCENTILE($K$41:$K$540,0.25) -> 15.038863
A26: 75th percentile | B26: =PERCENTILE($K$41:$K$540,0.75) -> 20.001149
A27: 95th percentile | B27: =PERCENTILE($K$41:$K$540,0.95) -> 24.353668
A28: P(value > current price) | B28: =COUNTIF($K$41:$K$540,">"&B16)/500 -> 0
A30: Scenario probability-weighted value (compact DCF per scenario)
A31: Scenario | B31: Probability | C31: Value / share
A32: Base | B32: =Assumptions!B8 -> 0.5 | C32: =($B$13*($B$18*(1+(Assumptions!B12+Assumptions!B13)/2)^9*(Assumptions!C17-Assumptions!C18-Assumptions!C19))/$B$12+Assumptions!$B$42*($B$18*(1+(Assumptions!B12+Assumptions!B13)/2)^9*(Assumptions!C17-Assumptions!C18-Assumptions!C19))/(1+$B$8)^9+$B$14)/$B$15 -> 17.720391
A33: Bull | B33: =Assumptions!C8 -> 0.3 | C33: =($B$13*($B$18*(1+(Assumptions!C12+Assumptions!C13)/2)^9*(Assumptions!D17-Assumptions!D18-Assumptions!D19))/$B$12+Assumptions!$B$42*($B$18*(1+(Assumptions!C12+Assumptions!C13)/2)^9*(Assumptions!D17-Assumptions!D18-Assumptions!D19))/(1+$B$8)^9+$B$14)/$B$15 -> 26.802909
A34: Bear | B34: =Assumptions!D8 -> 0.2 | C34: =($B$13*($B$18*(1+(Assumptions!D12+Assumptions!D13)/2)^9*(Assumptions!E17-Assumptions!E18-Assumptions!E19))/$B$12+Assumptions!$B$42*($B$18*(1+(Assumptions!D12+Assumptions!D13)/2)^9*(Assumptions!E17-Assumptions!E18-Assumptions!E19))/(1+$B$8)^9+$B$14)/$B$15 -> 9.4297974
A35: Probability-weighted value | C35: =SUMPRODUCT(B32:B34,C32:C34) -> 18.787028
A36: Compact-DCF approximation; PV-of-FCF scaling is calibrated on the active scenario (most accurate with switch = 1/Base).
A39: TRIALS
A40: # | B40: g FY27 | C40: Term margin | D40: WACC | E40: Exit x | F40: Rev FY35 | G40: EBITDA FY35 | H40: PV(TV) | I40: PV(FCF) | J40: Equity | K40: $ / share | N40: Bin ($/sh) | O40: low | P40: high | Q40: Count
A41: 1 | B41: =NORMINV(RAND(),$B$6,$C$6) -> 0.10729796 | C41: =MAX(0.03,NORMINV(RAND(),$B$7,$C$7)) -> 0.19735136 | D41: =MAX(0.08,NORMINV(RAND(),$B$8,$C$8)) -> 0.12294685 | E41: =MAX(4,NORMINV(RAND(),$B$9,$C$9)) -> 10.341656 | F41: =$B$18*(1+(B41+$B$17)/2)^9 -> 5477.1893 | G41: =F41*C41 -> 1080.9308 | H41: =E41*G41/(1+D41)^9 -> 3936.9071 | I41: =$B$13*G41/$B$12*((1+$B$8)/(1+D41))^4.5 -> 1734.0389 | J41: =H41+I41+$B$14 -> 7757.3449 | K41: =J41/$B$15 -> 12.313246 | N41: 0-5 | O41: 0 | P41: 5 | Q41: =COUNTIFS($K$41:$K$540,">="&O41,$K$41:$K$540,"<"&P41) -> 0
A42: 2 | B42: =NORMINV(RAND(),$B$6,$C$6) -> 0.15109298 | C42: =MAX(0.03,NORMINV(RAND(),$B$7,$C$7)) -> 0.22780604 | D42: =MAX(0.08,NORMINV(RAND(),$B$8,$C$8)) -> 0.1250699 | E42: =MAX(4,NORMINV(RAND(),$B$9,$C$9)) -> 11.853935 | F42: =$B$18*(1+(B42+$B$17)/2)^9 -> 6563.1459 | G42: =F42*C42 -> 1495.1243 | H42: =E42*G42/(1+D42)^9 -> 6136.5501 | I42: =$B$13*G42/$B$12*((1+$B$8)/(1+D42))^4.5 -> 2378.1919 | J42: =H42+I42+$B$14 -> 10601.141 | K42: =J42/$B$15 -> 16.827208 | N42: 5-10 | O42: 5 | P42: 10 | Q42: =COUNTIFS($K$41:$K$540,">="&O42,$K$41:$K$540,"<"&P42) -> 2
A43: 3 | B43: =NORMINV(RAND(),$B$6,$C$6) -> 0.26223244 | C43: =MAX(0.03,NORMINV(RAND(),$B$7,$C$7)) -> 0.16595236 | D43: =MAX(0.08,NORMINV(RAND(),$B$8,$C$8)) -> 0.13251716 | E43: =MAX(4,NORMINV(RAND(),$B$9,$C$9)) -> 9.3081706 | F43: =$B$18*(1+(B43+$B$17)/2)^9 -> 10224.686 | G43: =F43*C43 -> 1696.8108 | H43: =E43*G43/(1+D43)^9 -> 5153.4093 | I43: =$B$13*G43/$B$12*((1+$B$8)/(1+D43))^4.5 -> 2620.0479 | J43: =H43+I43+$B$14 -> 9859.8561 | K43: =J43/$B$15 -> 15.650565 | N43: 10-15 | O43: 10 | P43: 15 | Q43: =COUNTIFS($K$41:$K$540,">="&O43,$K$41:$K$540,"<"&P43) -> 121
A44: 4 | B44: =NORMINV(RAND(),$B$6,$C$6) -> 0.20390211 | C44: =MAX(0.03,NORMINV(RAND(),$B$7,$C$7)) -> 0.23653167 | D44: =MAX(0.08,NORMINV(RAND(),$B$8,$C$8)) -> 0.14005084 | E44: =MAX(4,NORMINV(RAND(),$B$9,$C$9)) -> 15.309664 | F44: =$B$18*(1+(B44+$B$17)/2)^9 -> 8124.2263 | G44: =F44*C44 -> 1921.6368 | H44: =E44*G44/(1+D44)^9 -> 9043.135 | I44: =$B$13*G44/$B$12*((1+$B$8)/(1+D44))^4.5 -> 2879.9816 | J44: =H44+I44+$B$14 -> 14009.515 | K44: =J44/$B$15 -> 22.237326 | N44: 15-20 | O44: 15 | P44: 20 | Q44: =COUNTIFS($K$41:$K$540,">="&O44,$K$41:$K$540,"<"&P44) -> 252
A45: 5 | B45: =NORMINV(RAND(),$B$6,$C$6) -> 0.22516288 | C45: =MAX(0.03,NORMINV(RAND(),$B$7,$C$7)) -> 0.2054325 | D45: =MAX(0.08,NORMINV(RAND(),$B$8,$C$8)) -> 0.14696476 | E45: =MAX(4,NORMINV(RAND(),$B$9,$C$9)) -> 10.546037 | F45: =$B$18*(1+(B45+$B$17)/2)^9 -> 8840.5444 | G45: =F45*C45 -> 1816.1352 | H45: =E45*G45/(1+D45)^9 -> 5575.538 | I45: =$B$13*G45/$B$12*((1+$B$8)/(1+D45))^4.5 -> 2648.8064 | J45: =H45+I45+$B$14 -> 10310.743 | K45: =J45/$B$15 -> 16.366259 | N45: 20-25 | O45: 20 | P45: 25 | Q45: =COUNTIFS($K$41:$K$540,">="&O45,$K$41:$K$540,"<"&P45) -> 105
A46: 6 | B46: =NORMINV(RAND(),$B$6,$C$6) -> 0.12239551 | C46: =MAX(0.03,NORMINV(RAND(),$B$7,$C$7)) -> 0.23902025 | D46: =MAX(0.08,NORMINV(RAND(),$B$8,$C$8)) -> 0.14232064 | E46: =MAX(4,NORMINV(RAND(),$B$9,$C$9)) -> 14.007749 | F46: =$B$18*(1+(B46+$B$17)/2)^9 -> 5831.9883 | G46: =F46*C46 -> 1393.9633 | H46: =E46*G46/(1+D46)^9 -> 5895.593 | I46: =$B$13*G46/$B$12*((1+$B$8)/(1+D46))^4.5 -> 2070.5352 | J46: =H46+I46+$B$14 -> 10052.527 | K46: =J46/$B$15 -> 15.956392 | N46: 25-30 | O46: 25 | P46: 30 | Q46: =COUNTIFS($K$41:$K$540,">="&O46,$K$41:$K$540,"<"&P46) -> 18
...

Sheet Football_Field
A1: FOOTBALL FIELD — VALUATION SUMMARY ($ per share)
A2: =CONCATENATE("Current price: $",TEXT(Assumptions!B43,"0.00")," · Scenario: ",CHOOSE(Assumptions!B4,"BASE","BULL","BEAR")," · Probability-weighted value: $",TEXT(Monte_Carlo!C35,"0.00")) -> Current price: $42.51 · Scenario: BASE · Probability-weighted value: $18.79
A4: Methodology | B4: Low | C4: High | D4: (base) | E4: (span) | F4: Midpoint
A5: 52-week trading range | B5: 38.19 | C5: 87.88 | D5: =B5 -> 38.19 | E5: =C5-B5 -> 49.69 | F5: =(B5+C5)/2 -> 63.035
A6: Analyst price targets (n≈19) | B6: 44 | C6: 84 | D6: =B6 -> 44 | E6: =C6-B6 -> 40 | F6: =(B6+C6)/2 -> 64
A7: DCF — Gordon growth (WACC ±1%, g 2.5–3.5%) | B7: =(SUMPRODUCT(DCF!$B$10:$J$10,(1+(WACC!$B$20+0.01))^-DCF!$B$11:$J$11)+DCF!$J$10*(1+0.025)/((WACC!$B$20+0.01)-0.025)/(1+(WACC!$B$20+0.01))^9+DCF!$B$31)/DCF!$B$32 -> 10.673232 | C7: =(SUMPRODUCT(DCF!$B$10:$J$10,(1+(WACC!$B$20-0.01))^-DCF!$B$11:$J$11)+DCF!$J$10*(1+0.035)/((WACC!$B$20-0.01)-0.035)/(1+(WACC!$B$20-0.01))^9+DCF!$B$31)/DCF!$B$32 -> 13.027298 | D7: =B7 -> 10.673232 | E7: =C7-B7 -> 2.3540656 | F7: =(B7+C7)/2 -> 11.850265
A8: DCF — exit multiple (10–14x, WACC ±1%) | B8: =(SUMPRODUCT(DCF!$B$10:$J$10,(1+(WACC!$B$20+0.01))^-DCF!$B$11:$J$11)+10*Model_3S!$L$23/(1+(WACC!$B$20+0.01))^9+DCF!$B$31)/DCF!$B$32 -> 15.085123 | C8: =(SUMPRODUCT(DCF!$B$10:$J$10,(1+(WACC!$B$20-0.01))^-DCF!$B$11:$J$11)+14*Model_3S!$L$23/(1+(WACC!$B$20-0.01))^9+DCF!$B$31)/DCF!$B$32 -> 20.469232 | D8: =B8 -> 15.085123 | E8: =C8-B8 -> 5.3841087 | F8: =(B8+C8)/2 -> 17.777178
A9: Trading comps — EV/Revenue (3.2–6.5x FY26E) | B9: =Comps!G21 -> 17.386665 | C9: =Comps!H21 -> 31.901427 | D9: =B9 -> 17.386665 | E9: =C9-B9 -> 14.514762 | F9: =(B9+C9)/2 -> 24.644046
A10: Trading comps — EV/EBITDA (15–28x FY27E) | B10: =Comps!G22 -> 13.181782 | C10: =Comps!H22 -> 21.735815 | D10: =B10 -> 13.181782 | E10: =C10-B10 -> 8.554033 | F10: =(B10+C10)/2 -> 17.458799
A11: Precedent transactions (2–6x FY26E revenue) | B11: =Precedents!B18 -> 12.10857 | C11: =Precedents!C18 -> 29.70222 | D11: =B11 -> 12.10857 | E11: =C11-B11 -> 17.593651 | F11: =(B11+C11)/2 -> 20.905395
A12: LBO capacity (25% → 15% IRR) | B12: =LBO!D52 -> 11.459363 | C12: =LBO!D50 -> 14.529565 | D12: =B12 -> 11.459363 | E12: =C12-B12 -> 3.0702021 | F12: =(B12+C12)/2 -> 12.994464
A13: Monte Carlo P25–P75 (live) | B13: =Monte_Carlo!B25 -> 15.038863 | C13: =Monte_Carlo!B26 -> 20.001149 | D13: =B13 -> 15.038863 | E13: =C13-B13 -> 4.9622866 | F13: =(B13+C13)/2 -> 17.520006
A14: Current price (marker) | B14: =Assumptions!B43-0.4 -> 42.11 | C14: =Assumptions!B43+0.4 -> 42.91 | D14: =B14 -> 42.11 | E14: =C14-B14 -> 0.8 | F14: =(B14+C14)/2 -> 42.51
A16: 52-wk range: stockanalysis.com. Analyst targets: S&P Global / TipRanks consensus (avg ≈ $66). All other rows are live model outputs.
