Workbook

Sheet Cover
A1: T1 ENERGY INC. (NYSE: TE) — DCF VALUATION & 3-STATEMENT OPERATING MODEL
A2: Prepared August 2026 · $ millions except per-share · Calendar fiscal year · Formerly FREYR Battery; pivoted to US solar manufacturing
A4: READ THIS FIRST — THE CRUX
C5: T1's profit engine is the Section 45X Advanced Manufacturing Production Credit (~$0.07/W modules, ~$0.04/W cells), NOT its operating margin. Module assembly against Chinese competition earns a thin-to-negative gross margin on its own; the credits are what make the P&L work. 45X is scheduled to STEP DOWN (100% through 2029, then 75%/50%/25%/0% in 2030-33). So the entire investment question is: can T1 reach standalone profitability BEFORE the credits disappear? This model makes that explicit — see the '45X phase-out factor' row on Model_3S and the Bear scenario.
A7: CONTENTS
A8: Assumptions | C8: Scenario switch & levers (edit yellow cells)
A9: Historicals | C9: FY2024–FY2025 actuals, Q2-2026 preliminary, FY2026E build
A10: Model_3S | C10: Linked IS/BS/CF FY2026E–FY2035E with explicit 45X credit line and phase-out schedule
A11: WACC | C11: CAPM — high beta small-cap with policy risk
A12: DCF | C12: Unlevered FCF, Gordon + exit-multiple TV, sensitivities
A13: Comps | C13: US/global solar manufacturing peers (FSLR primary)
A14: Precedents | C14: Solar manufacturing M&A — incl. T1's own Trina-US and KORE deals
A15: LBO | C15: Illustrative — negative EBITDA means conventional debt capacity is ~zero
A16: Monte_Carlo | C16: 500 live trials + scenario probability weights
A17: Football_Field | C17: Valuation summary chart vs. current price
A19: LEGEND
A20: Blue font / yellow fill | C20: Hardcoded input or scenario lever — edit these
A21: Black font | C21: Formula — do not overwrite
A22: Green font | C22: Link to another sheet
A23: 'e' | C23: Estimated figure — see notes
A25: KEY MODELING NOTES
A26: 1. | C26: Q2-2026 preliminary: revenue $245-255mm on 835 MW shipped, net loss from continuing ops $34-37mm, NEGATIVE adjusted EBITDA, cash + restricted cash $156.4mm at 6/30/26.
A27: 2. | C27: G2_Austin (solar CELL plant) Phase 1 capex RAISED to $510mm from $425mm; first cell production DELAYED to Q1-2027. Cells are what stack the 45X credit and lift domestic content — the delay pushes the profitability inflection right.
A28: 3. | C28: 2026 actions: bought Evervolt solar patents ($135mm), monetized 2025 45X credits for $39.1mm, closed KORE Power acquisition (energy storage / AI data-center infrastructure, 'T1 NRI' brand), raised $120mm convertible notes (late July).
A29: 4. | C29: Liquidity is the live risk: ~$150mm cash against a $510mm Phase 1 program and ~$670mm debt. The model's revolver-draw row is a FUNDING-GAP INDICATOR — draws mean an equity raise in practice (dilution not modeled).
A30: 5. | C30: Share-count/market-cap sources conflict (279.27mm shares × $6.81 ≈ $1.90B vs. a $1.37B market cap quoted 7/28/26) — likely convertible/timing differences. Both are editable inputs; verify before relying on per-share output.
A32: KEY SOURCES
A33: Q2-2026 preliminary results (July 2026) | C33: stocktitan/Globe & Mail/Benzinga: rev $245-255mm, 835 MW, net loss $34-37mm, cash $156.4mm; G2 capex $510mm, first cells Q1-2027; Evervolt patents $135mm; 45X monetization $39.1mm
A34: Market data (Aug 2026) | C34: stockanalysis/etoro/CNN: price ~$6.81, 279.27mm shares, cash $46.37mm & debt $549.78mm (as reported; pre-convert), analyst avg target ~$10.07 'Strong Buy'; Alliance Global cut to $7
A35: 45X credit mechanics | C35: IRA Section 45X: ~$0.07/W modules, ~$0.04/W cells; statutory step-down 2030-2032. Treat the phase-out row as an ASSUMPTION — subsequent legislation may alter it.
A36: 10Y UST 4.55% | C36: tradingeconomics / FRED DGS10
A38: DISCLAIMER | C38: Educational model, not investment advice. TE is a small-cap, levered, policy-dependent manufacturer — outcomes are wide and the equity is speculative. Verify all figures against T1 filings.

Sheet Assumptions
A1: ASSUMPTIONS & SCENARIO LEVERS — T1 ENERGY
A2: Edit yellow cells. Switch drives Model_3S, DCF, LBO, Monte Carlo.
A4: SCENARIO SWITCH (1 = Base, 2 = Bull, 3 = Bear) | B4: 1 | C4: =CHOOSE($B$4,"BASE — G2 cells ramp, margins improve before 45X fades","BULL — full domestic stack + storage/AI datacenter scale","BEAR — thin margins persist, 45X fades, funding squeeze") -> BASE — G2 cells ramp, margins improve before 45X fades
A6: Scenario probability weights
B7: Base | C7: Bull | D7: Bear | E7: Total
A8: Probability | B8: 0.4 | C8: 0.2 | D8: 0.4 | E8: =SUM(B8:D8) -> 1 | F8: Heavy 40% bear weight: policy dependence + funding gap + commodity competition are all live
A10: Revenue growth — decays linearly FY2027 → FY2035
B11: Base | C11: Bull | D11: Bear | E11: Selected
A12: FY2027 revenue growth | B12: 0.35 | C12: 0.55 | D12: 0.1 | E12: =CHOOSE($B$4,B12,C12,D12) -> 0.35
A13: FY2035 revenue growth (terminal-year) | B13: 0.04 | C13: 0.07 | D13: 0 | E13: =CHOOSE($B$4,B13,C13,D13) -> 0.04
A14: FY27 growth = G2_Austin cells coming online (Q1-27) + KORE storage. Bear assumes the ramp slips and pricing stays brutal.
A15: Operating drivers — FY2026 start ramps linearly to FY2035 target
A16: Driver | B16: FY26 start | C16: Base target | D16: Bull target | E16: Bear target | F16: Selected
A17: Gross margin EXCLUDING 45X credits | B17: 0.03 | C17: 0.14 | D17: 0.2 | E17: 0.03 | F17: =CHOOSE($B$4,C17,D17,E17) -> 0.14
A18: 45X credits as % of revenue (pre-phase-out) | B18: 0.23 | C18: 0.28 | D18: 0.3 | E18: 0.2 | F18: =CHOOSE($B$4,C18,D18,E18) -> 0.28
A19: Cash opex — SG&A + R&D (% revenue) | B19: 0.11 | C19: 0.065 | D19: 0.055 | E19: 0.09 | F19: =CHOOSE($B$4,C19,D19,E19) -> 0.065
A20: Stock-based compensation (% revenue) | B20: 0.02 | C20: 0.012 | D20: 0.012 | E20: 0.018 | F20: =CHOOSE($B$4,C20,D20,E20) -> 0.012
A21: D&A (% revenue) | B21: 0.055 | C21: 0.05 | D21: 0.045 | E21: 0.06 | F21: =CHOOSE($B$4,C21,D21,E21) -> 0.05
A22: Cash tax rate (large NOLs early) | B22: 0 | C22: 0.18 | D22: 0.18 | E22: 0 | F22: =CHOOSE($B$4,C22,D22,E22) -> 0.18
A23: Other current assets (% revenue) | B23: 0.08 | C23: 0.08 | D23: 0.08 | E23: 0.08 | F23: =CHOOSE($B$4,C23,D23,E23) -> 0.08
A24: Customer deposits / deferred revenue (% rev) | B24: 0.05 | C24: 0.05 | D24: 0.06 | E24: 0.04 | F24: =CHOOSE($B$4,C24,D24,E24) -> 0.05
A25: THE WHOLE THESIS IS ROW 17: ex-credit gross margin. Base says domestic cells lift it 3% → 14% by FY35. Bear says it never improves — and when 45X fades, EBITDA goes structurally negative.
A26: Working capital (held constant)
A27: Days sales outstanding (DSO) | B27: 45
A28: Days inventory (DIO, on COGS) | B28: 75
A29: Days payable (DPO, on COGS + cash opex) | B29: 60
A33: Capital, capex program & financing
A34: Interest earned on cash | B34: 0.035
A35: Revolver / gap-funding rate | B35: 0.1
A36: Minimum cash balance ($mm) | B36: 100
A37: Diluted shares outstanding (mm) | B37: 279.3
A38: Marginal tax rate (valuation) | B38: 0.21
A39: Average rate on existing debt | B39: 0.085
A40: G2_Austin Phase 1 capex — FY2026 ($mm) | B40: 300 | C40: Phase 1 total $510mm split across FY26/27; first cells Q1-2027
A41: G2_Austin Phase 1 capex — FY2027 ($mm) | B41: 210
A42: Maintenance capex thereafter (% revenue) | B42: 0.03
A43: Acquisitions FY2026 (Evervolt patents etc., $mm) | B43: 135
A44: Equity issuance FY2026 ($mm) | B44: 0
A46: Terminal value & market inputs
A47: Terminal (perpetuity) growth rate g | B47: 0.02
...

Sheet Historicals
A1: HISTORICAL FINANCIALS ($mm)
B4: FY2024A | C4: FY2025A e | E4: Q1-26A e | F4: Q2-26A prelim | H4: FY2026E
A5: Revenue | B5: 0 | C5: 340 | E5: 190 | F5: 250 | H5: 1050 | I5: FY26E ~$1.05B: ~3.5 GW at ~$0.30/W ASP (G1_Dallas target 3.1-4.2 GW, guided to upper end)
A6: Module shipments (MW) | F6: 835 | H6: 3500
A7: Net income (loss) from continuing ops | C7: -180 | F7: -35
A8: Adjusted EBITDA | F8: -15 | G8: NEGATIVE in Q2-26 — the company is not yet EBITDA-profitable
A9: Cash + restricted cash (period end) | F9: 156.4
A11: Business | B11: US solar manufacturing. G1_Dallas (5 GW module plant, ex-Trina) operating; G2_Austin (cells) Phase 1 $510mm, first output Q1-2027.
A12: Profit engine | B12: Section 45X credits (~$0.07/W modules, ~$0.04/W cells). Monetized $39.1mm of 2025 credits in 2026.
A13: 2026 corporate actions | B13: Evervolt solar patents $135mm · KORE Power acquired (storage + AI data-center infra, 'T1 NRI') · $120mm convertible notes raised late July
A14: Capital structure | B14: ~$550mm debt reported + ~$120mm new converts ≈ $670mm; cash ~$150mm → net debt ~$520mm vs ~$1.9B market cap
A15: Analyst view | B15: Avg target ~$10.07, 'Strong Buy' consensus; but Alliance Global cut to $7 — wide dispersion is itself a signal
A16: Risk file | B16: 45X phase-out (2030-33) · Chinese module pricing · G2 execution/delay · funding gap vs $510mm program · tariff/policy swings
A19: Opening balance sheet, 12/31/2025 (estimated):
A20: Cash + restricted e | B20: 200
A21: Receivables e | B21: 120
A22: Inventory e | B22: 180
A23: Other current assets e | B23: 90
A24: PP&E net e | B24: 900
A25: Goodwill + intangibles + other LT e | B25: 300
A26: AP + accrued e | B26: 160
A27: Customer deposits / deferred e | B27: 50
A28: Total debt e | B28: 550
A29: Other LT liabilities e | B29: 120
A31: Balance sheet substantially ESTIMATED (post-pivot reporting is discontinuous — FREYR→T1 with asset acquisitions and a discontinued battery segment). Equity is the plug. Verify against the 10-Q before relying on it.

Sheet Model_3S
A1: 3-STATEMENT OPERATING MODEL — FY2026E–FY2035E ($mm; 45X credits shown explicitly)
A2: =CONCATENATE("Active scenario: ",CHOOSE(Assumptions!$B$4,"BASE","BULL","BEAR")) -> Active scenario: BASE
B4: FY2025A | C4: FY2026E | D4: FY2027E | E4: FY2028E | F4: FY2029E | G4: FY2030E | H4: FY2031E | I4: FY2032E | J4: FY2033E | K4: FY2034E | L4: FY2035E
A6: DRIVERS
A7: Revenue growth % | C7: =C19/B19-1 -> 2.0882353 | D7: =Assumptions!$E$12+(Assumptions!$E$13-Assumptions!$E$12)*0/8 -> 0.35 | E7: =Assumptions!$E$12+(Assumptions!$E$13-Assumptions!$E$12)*1/8 -> 0.31125 | F7: =Assumptions!$E$12+(Assumptions!$E$13-Assumptions!$E$12)*2/8 -> 0.2725 | G7: =Assumptions!$E$12+(Assumptions!$E$13-Assumptions!$E$12)*3/8 -> 0.23375 | H7: =Assumptions!$E$12+(Assumptions!$E$13-Assumptions!$E$12)*4/8 -> 0.195 | I7: =Assumptions!$E$12+(Assumptions!$E$13-Assumptions!$E$12)*5/8 -> 0.15625 | J7: =Assumptions!$E$12+(Assumptions!$E$13-Assumptions!$E$12)*6/8 -> 0.1175 | K7: =Assumptions!$E$12+(Assumptions!$E$13-Assumptions!$E$12)*7/8 -> 0.07875 | L7: =Assumptions!$E$12+(Assumptions!$E$13-Assumptions!$E$12)*8/8 -> 0.04
A8: Gross margin ex-45X % | C8: =Assumptions!$B$17 -> 0.03 | D8: =Assumptions!$B$17+(Assumptions!$F$17-Assumptions!$B$17)*1/9 -> 0.042222222 | E8: =Assumptions!$B$17+(Assumptions!$F$17-Assumptions!$B$17)*2/9 -> 0.054444444 | F8: =Assumptions!$B$17+(Assumptions!$F$17-Assumptions!$B$17)*3/9 -> 0.066666667 | G8: =Assumptions!$B$17+(Assumptions!$F$17-Assumptions!$B$17)*4/9 -> 0.078888889 | H8: =Assumptions!$B$17+(Assumptions!$F$17-Assumptions!$B$17)*5/9 -> 0.091111111 | I8: =Assumptions!$B$17+(Assumptions!$F$17-Assumptions!$B$17)*6/9 -> 0.10333333 | J8: =Assumptions!$B$17+(Assumptions!$F$17-Assumptions!$B$17)*7/9 -> 0.11555556 | K8: =Assumptions!$B$17+(Assumptions!$F$17-Assumptions!$B$17)*8/9 -> 0.12777778 | L8: =Assumptions!$B$17+(Assumptions!$F$17-Assumptions!$B$17)*9/9 -> 0.14
A9: 45X credit % of revenue (pre-phase-out) | C9: =Assumptions!$B$18 -> 0.23 | D9: =Assumptions!$B$18+(Assumptions!$F$18-Assumptions!$B$18)*1/9 -> 0.23555556 | E9: =Assumptions!$B$18+(Assumptions!$F$18-Assumptions!$B$18)*2/9 -> 0.24111111 | F9: =Assumptions!$B$18+(Assumptions!$F$18-Assumptions!$B$18)*3/9 -> 0.24666667 | G9: =Assumptions!$B$18+(Assumptions!$F$18-Assumptions!$B$18)*4/9 -> 0.25222222 | H9: =Assumptions!$B$18+(Assumptions!$F$18-Assumptions!$B$18)*5/9 -> 0.25777778 | I9: =Assumptions!$B$18+(Assumptions!$F$18-Assumptions!$B$18)*6/9 -> 0.26333333 | J9: =Assumptions!$B$18+(Assumptions!$F$18-Assumptions!$B$18)*7/9 -> 0.26888889 | K9: =Assumptions!$B$18+(Assumptions!$F$18-Assumptions!$B$18)*8/9 -> 0.27444444 | L9: =Assumptions!$B$18+(Assumptions!$F$18-Assumptions!$B$18)*9/9 -> 0.28
A10: Cash opex % rev | C10: =Assumptions!$B$19 -> 0.11 | D10: =Assumptions!$B$19+(Assumptions!$F$19-Assumptions!$B$19)*1/9 -> 0.105 | E10: =Assumptions!$B$19+(Assumptions!$F$19-Assumptions!$B$19)*2/9 -> 0.1 | F10: =Assumptions!$B$19+(Assumptions!$F$19-Assumptions!$B$19)*3/9 -> 0.095 | G10: =Assumptions!$B$19+(Assumptions!$F$19-Assumptions!$B$19)*4/9 -> 0.09 | H10: =Assumptions!$B$19+(Assumptions!$F$19-Assumptions!$B$19)*5/9 -> 0.085 | I10: =Assumptions!$B$19+(Assumptions!$F$19-Assumptions!$B$19)*6/9 -> 0.08 | J10: =Assumptions!$B$19+(Assumptions!$F$19-Assumptions!$B$19)*7/9 -> 0.075 | K10: =Assumptions!$B$19+(Assumptions!$F$19-Assumptions!$B$19)*8/9 -> 0.07 | L10: =Assumptions!$B$19+(Assumptions!$F$19-Assumptions!$B$19)*9/9 -> 0.065
A11: SBC % rev | C11: =Assumptions!$B$20 -> 0.02 | D11: =Assumptions!$B$20+(Assumptions!$F$20-Assumptions!$B$20)*1/9 -> 0.019111111 | E11: =Assumptions!$B$20+(Assumptions!$F$20-Assumptions!$B$20)*2/9 -> 0.018222222 | F11: =Assumptions!$B$20+(Assumptions!$F$20-Assumptions!$B$20)*3/9 -> 0.017333333 | G11: =Assumptions!$B$20+(Assumptions!$F$20-Assumptions!$B$20)*4/9 -> 0.016444444 | H11: =Assumptions!$B$20+(Assumptions!$F$20-Assumptions!$B$20)*5/9 -> 0.015555556 | I11: =Assumptions!$B$20+(Assumptions!$F$20-Assumptions!$B$20)*6/9 -> 0.014666667 | J11: =Assumptions!$B$20+(Assumptions!$F$20-Assumptions!$B$20)*7/9 -> 0.013777778 | K11: =Assumptions!$B$20+(Assumptions!$F$20-Assumptions!$B$20)*8/9 -> 0.012888889 | L11: =Assumptions!$B$20+(Assumptions!$F$20-Assumptions!$B$20)*9/9 -> 0.012
A12: D&A % rev | C12: =Assumptions!$B$21 -> 0.055 | D12: =Assumptions!$B$21+(Assumptions!$F$21-Assumptions!$B$21)*1/9 -> 0.054444444 | E12: =Assumptions!$B$21+(Assumptions!$F$21-Assumptions!$B$21)*2/9 -> 0.053888889 | F12: =Assumptions!$B$21+(Assumptions!$F$21-Assumptions!$B$21)*3/9 -> 0.053333333 | G12: =Assumptions!$B$21+(Assumptions!$F$21-Assumptions!$B$21)*4/9 -> 0.052777778 | H12: =Assumptions!$B$21+(Assumptions!$F$21-Assumptions!$B$21)*5/9 -> 0.052222222 | I12: =Assumptions!$B$21+(Assumptions!$F$21-Assumptions!$B$21)*6/9 -> 0.051666667 | J12: =Assumptions!$B$21+(Assumptions!$F$21-Assumptions!$B$21)*7/9 -> 0.051111111 | K12: =Assumptions!$B$21+(Assumptions!$F$21-Assumptions!$B$21)*8/9 -> 0.050555556 | L12: =Assumptions!$B$21+(Assumptions!$F$21-Assumptions!$B$21)*9/9 -> 0.05
A13: Cash tax rate % | C13: =Assumptions!$B$22 -> 0 | D13: =Assumptions!$B$22+(Assumptions!$F$22-Assumptions!$B$22)*1/9 -> 0.02 | E13: =Assumptions!$B$22+(Assumptions!$F$22-Assumptions!$B$22)*2/9 -> 0.04 | F13: =Assumptions!$B$22+(Assumptions!$F$22-Assumptions!$B$22)*3/9 -> 0.06 | G13: =Assumptions!$B$22+(Assumptions!$F$22-Assumptions!$B$22)*4/9 -> 0.08 | H13: =Assumptions!$B$22+(Assumptions!$F$22-Assumptions!$B$22)*5/9 -> 0.1 | I13: =Assumptions!$B$22+(Assumptions!$F$22-Assumptions!$B$22)*6/9 -> 0.12 | J13: =Assumptions!$B$22+(Assumptions!$F$22-Assumptions!$B$22)*7/9 -> 0.14 | K13: =Assumptions!$B$22+(Assumptions!$F$22-Assumptions!$B$22)*8/9 -> 0.16 | L13: =Assumptions!$B$22+(Assumptions!$F$22-Assumptions!$B$22)*9/9 -> 0.18
A14: Other current assets % rev | C14: =Assumptions!$B$23 -> 0.08 | D14: =Assumptions!$B$23+(Assumptions!$F$23-Assumptions!$B$23)*1/9 -> 0.08 | E14: =Assumptions!$B$23+(Assumptions!$F$23-Assumptions!$B$23)*2/9 -> 0.08 | F14: =Assumptions!$B$23+(Assumptions!$F$23-Assumptions!$B$23)*3/9 -> 0.08 | G14: =Assumptions!$B$23+(Assumptions!$F$23-Assumptions!$B$23)*4/9 -> 0.08 | H14: =Assumptions!$B$23+(Assumptions!$F$23-Assumptions!$B$23)*5/9 -> 0.08 | I14: =Assumptions!$B$23+(Assumptions!$F$23-Assumptions!$B$23)*6/9 -> 0.08 | J14: =Assumptions!$B$23+(Assumptions!$F$23-Assumptions!$B$23)*7/9 -> 0.08 | K14: =Assumptions!$B$23+(Assumptions!$F$23-Assumptions!$B$23)*8/9 -> 0.08 | L14: =Assumptions!$B$23+(Assumptions!$F$23-Assumptions!$B$23)*9/9 -> 0.08
A15: Deferred revenue % rev | C15: =Assumptions!$B$24 -> 0.05 | D15: =Assumptions!$B$24+(Assumptions!$F$24-Assumptions!$B$24)*1/9 -> 0.05 | E15: =Assumptions!$B$24+(Assumptions!$F$24-Assumptions!$B$24)*2/9 -> 0.05 | F15: =Assumptions!$B$24+(Assumptions!$F$24-Assumptions!$B$24)*3/9 -> 0.05 | G15: =Assumptions!$B$24+(Assumptions!$F$24-Assumptions!$B$24)*4/9 -> 0.05 | H15: =Assumptions!$B$24+(Assumptions!$F$24-Assumptions!$B$24)*5/9 -> 0.05 | I15: =Assumptions!$B$24+(Assumptions!$F$24-Assumptions!$B$24)*6/9 -> 0.05 | J15: =Assumptions!$B$24+(Assumptions!$F$24-Assumptions!$B$24)*7/9 -> 0.05 | K15: =Assumptions!$B$24+(Assumptions!$F$24-Assumptions!$B$24)*8/9 -> 0.05 | L15: =Assumptions!$B$24+(Assumptions!$F$24-Assumptions!$B$24)*9/9 -> 0.05
A16: 45X PHASE-OUT FACTOR (statutory step-down — editable) | C16: 1 | D16: 1 | E16: 1 | F16: 1 | G16: 0.75 | H16: 0.5 | I16: 0.25 | J16: 0 | K16: 0 | L16: 0 | M16: IRA 45X: 100% through 2029, then 75%/50%/25%/0% for 2030-2032, zero thereafter. THE key policy assumption.
A18: INCOME STATEMENT
A19: Revenue | B19: =Historicals!C5 -> 340 | C19: =Historicals!H5 -> 1050 | D19: =C19*(1+D7) -> 1417.5 | E19: =D19*(1+E7) -> 1858.6969 | F19: =E19*(1+F7) -> 2365.1918 | G19: =F19*(1+G7) -> 2918.0554 | H19: =G19*(1+H7) -> 3487.0761 | I19: =H19*(1+I7) -> 4031.9318 | J19: =I19*(1+J7) -> 4505.6838 | K19: =J19*(1+K7) -> 4860.5064 | L19: =K19*(1+L7) -> 5054.9266
A20: Cost of revenue (excl. D&A) | C20: =-C19*(1-C8) -> -1018.5 | D20: =-D19*(1-D8) -> -1357.65 | E20: =-E19*(1-E8) -> -1757.5012 | F20: =-F19*(1-F8) -> -2207.5123 | G20: =-G19*(1-G8) -> -2687.8532 | H20: =-H19*(1-H8) -> -3169.3648 | I20: =-I19*(1-I8) -> -3615.2988 | J20: =-J19*(1-J8) -> -3985.027 | ... L20: =-L19*(1-L8) -> -4347.2369
A21: Gross profit EXCLUDING 45X credits | C21: =C19+C20 -> 31.5 | D21: =D19+D20 -> 59.85 | E21: =E19+E20 -> 101.19572 | F21: =F19+F20 -> 157.67945 | G21: =G19+G20 -> 230.20214 | H21: =H19+H20 -> 317.71138 | I21: =I19+I20 -> 416.63295 | J21: =J19+J20 -> 520.65679 | ... L21: =L19+L20 -> 707.68973 | M21: If this row is negative, the business loses money on every panel BEFORE credits
A22: 45X production tax credits | C22: =C19*C9*C16 -> 241.5 | D22: =D19*D9*D16 -> 333.9 | E22: =E19*E9*E16 -> 448.15247 | F22: =F19*F9*F16 -> 583.41397 | G22: =G19*G9*G16 -> 551.9988 | H22: =H19*H9*H16 -> 449.44537 | I22: =I19*I9*I16 -> 265.43551 | J22: =J19*J9*J16 -> 0 | ... L22: =L19*L9*L16 -> 0
A23: Gross profit including credits | C23: =C21+C22 -> 273 | D23: =D21+D22 -> 393.75 | E23: =E21+E22 -> 549.34819 | F23: =F21+F22 -> 741.09342 | G23: =G21+G22 -> 782.20095 | H23: =H21+H22 -> 767.15675 | I23: =I21+I22 -> 682.06846 | J23: =J21+J22 -> 520.65679 | ... L23: =L21+L22 -> 707.68973
A24: Cash opex (SG&A + R&D) | C24: =-C19*C10 -> -115.5 | D24: =-D19*D10 -> -148.8375 | E24: =-E19*E10 -> -185.86969 | F24: =-F19*F10 -> -224.69322 | G24: =-G19*G10 -> -262.62498 | H24: =-H19*H10 -> -296.40147 | I24: =-I19*I10 -> -322.55454 | J24: =-J19*J10 -> -337.92628 | ... L24: =-L19*L10 -> -328.57023
A25: Adjusted EBITDA | C25: =C23+C24 -> 157.5 | D25: =D23+D24 -> 244.9125 | E25: =E23+E24 -> 363.4785 | F25: =F23+F24 -> 516.4002 | G25: =G23+G24 -> 519.57597 | H25: =H23+H24 -> 470.75528 | I25: =I23+I24 -> 359.51392 | J25: =J23+J24 -> 182.73051 | ... L25: =L23+L24 -> 379.1195
A26: Stock-based compensation | C26: =-C19*C11 -> -21 | D26: =-D19*D11 -> -27.09 | E26: =-E19*E11 -> -33.869588 | F26: =-F19*F11 -> -40.996657 | G26: =-G19*G11 -> -47.985799 | H26: =-H19*H11 -> -54.243407 | I26: =-I19*I11 -> -59.135 | J26: =-J19*J11 -> -62.07831 | ... L26: =-L19*L11 -> -60.65912
A27: D&A | C27: =-C19*C12 -> -57.75 | D27: =-D19*D12 -> -77.175 | E27: =-E19*E12 -> -100.16311 | F27: =-F19*F12 -> -126.14356 | G27: =-G19*G12 -> -154.00848 | H27: =-H19*H12 -> -182.10287 | I27: =-I19*I12 -> -208.31648 | J27: =-J19*J12 -> -230.2905 | ... L27: =-L19*L12 -> -252.74633
A28: EBIT | C28: =C25+C26+C27 -> 78.75 | D28: =D25+D26+D27 -> 140.6475 | E28: =E25+E26+E27 -> 229.4458 | F28: =F25+F26+F27 -> 349.25999 | G28: =G25+G26+G27 -> 317.58169 | H28: =H25+H26+H27 -> 234.40901 | I28: =I25+I26+I27 -> 92.062443 | J28: =J25+J26+J27 -> -109.63831 | ... L28: =L25+L26+L27 -> 65.714046
A29: Interest income (on beginning cash) | C29: =B72*Assumptions!$B$34 -> 7 | D29: =C72*Assumptions!$B$34 -> 3.5 | E29: =D72*Assumptions!$B$34 -> 3.5 | F29: =E72*Assumptions!$B$34 -> 3.5 | G29: =F72*Assumptions!$B$34 -> 11.710645 | H29: =G72*Assumptions!$B$34 -> 21.047095 | I29: =H72*Assumptions!$B$34 -> 28.359637 | J29: =I72*Assumptions!$B$34 -> 32.02772 | ... L29: =K72*Assumptions!$B$34 -> 31.355132
A30: Interest expense (beginning debt) | C30: =-(B52*Assumptions!$B$39+B56*Assumptions!$B$35) -> -46.75 | D30: =-(C52*Assumptions!$B$39+C56*Assumptions!$B$35) -> -67.057192 | E30: =-(D52*Assumptions!$B$39+D56*Assumptions!$B$35) -> -76.554917 | F30: =-(E52*Assumptions!$B$39+E56*Assumptions!$B$35) -> -61.511693 | G30: =-(F52*Assumptions!$B$39+F56*Assumptions!$B$35) -> -56.95 | H30: =-(G52*Assumptions!$B$39+G56*Assumptions!$B$35) -> -56.95 | I30: =-(H52*Assumptions!$B$39+H56*Assumptions!$B$35) -> -56.95 | J30: =-(I52*Assumptions!$B$39+I56*Assumptions!$B$35) -> -56.95 | ... L30: =-(K52*Assumptions!$B$39+K56*Assumptions!$B$35) -> -56.95
A31: Pre-tax income | C31: =C28+C29+C30 -> 39 | D31: =D28+D29+D30 -> 77.090308 | E31: =E28+E29+E30 -> 156.39089 | F31: =F28+F29+F30 -> 291.24829 | G31: =G28+G29+G30 -> 272.34234 | H31: =H28+H29+H30 -> 198.5061 | I31: =I28+I29+I30 -> 63.472079 | J31: =J28+J29+J30 -> -134.56059 | ... L31: =L28+L29+L30 -> 40.119179
A32: Taxes (NOL-shielded early) | C32: =-MAX(0,C31)*C13 -> 0 | D32: =-MAX(0,D31)*D13 -> -1.5418062 | E32: =-MAX(0,E31)*E13 -> -6.2556354 | F32: =-MAX(0,F31)*F13 -> -17.474898 | G32: =-MAX(0,G31)*G13 -> -21.787387 | H32: =-MAX(0,H31)*H13 -> -19.85061 | I32: =-MAX(0,I31)*I13 -> -7.6166495 | J32: =-MAX(0,J31)*J13 -> 0 | ... L32: =-MAX(0,L31)*L13 -> -7.2214522
A33: Net income (loss) | C33: =C31+C32 -> 39 | D33: =D31+D32 -> 75.548502 | E33: =E31+E32 -> 150.13525 | F33: =F31+F32 -> 273.7734 | G33: =G31+G32 -> 250.55495 | H33: =H31+H32 -> 178.65549 | I33: =I31+I32 -> 55.85543 | J33: =J31+J32 -> -134.56059 | ... L33: =L31+L32 -> 32.897727
A34: Adj. EBITDA margin % | C34: =C25/C19 -> 0.15 | D34: =D25/D19 -> 0.17277778 | E34: =E25/E19 -> 0.19555556 | F34: =F25/F19 -> 0.21833333 | G34: =G25/G19 -> 0.17805556 | H34: =H25/H19 -> 0.135 | I34: =I25/I19 -> 0.089166667 | J34: =J25/J19 -> 0.040555556 | ... L34: =L25/L19 -> 0.075
A36: WORKING CAPITAL
A37: Accounts receivable | B37: 120 | C37: =C19*Assumptions!$B$27/365 -> 129.45205 | D37: =D19*Assumptions!$B$27/365 -> 174.76027 | E37: =E19*Assumptions!$B$27/365 -> 229.15441 | F37: =F19*Assumptions!$B$27/365 -> 291.59899 | G37: =G19*Assumptions!$B$27/365 -> 359.76025 | H37: =H19*Assumptions!$B$27/365 -> 429.9135 | I37: =I19*Assumptions!$B$27/365 -> 497.08748 | J37: =J19*Assumptions!$B$27/365 -> 555.49526 | ... L37: =L19*Assumptions!$B$27/365 -> 623.21013
A38: Inventory (panels, cells, polysilicon) | B38: 180 | C38: =-C20*Assumptions!$B$28/365 -> 209.28082 | D38: =-D20*Assumptions!$B$28/365 -> 278.96918 | E38: =-E20*Assumptions!$B$28/365 -> 361.13037 | F38: =-F20*Assumptions!$B$28/365 -> 453.59842 | G38: =-G20*Assumptions!$B$28/365 -> 552.2986 | H38: =-H20*Assumptions!$B$28/365 -> 651.23933 | I38: =-I20*Assumptions!$B$28/365 -> 742.86962 | J38: =-J20*Assumptions!$B$28/365 -> 818.84116 | ... L38: =-L20*Assumptions!$B$28/365 -> 893.26786
A39: Other current assets (incl. 45X receivable) | B39: 90 | C39: =C19*C14 -> 84 | D39: =D19*D14 -> 113.4 | E39: =E19*E14 -> 148.69575 | F39: =F19*F14 -> 189.21534 | G39: =G19*G14 -> 233.44443 | H39: =H19*H14 -> 278.96609 | I39: =I19*I14 -> 322.55454 | J39: =J19*J14 -> 360.4547 | ... L39: =L19*L14 -> 404.39413
A40: AP + accrued | B40: -160 | C40: =(C20+C24)*Assumptions!$B$29/365 -> -186.41096 | D40: =(D20+D24)*Assumptions!$B$29/365 -> -247.64178 | E40: =(E20+E24)*Assumptions!$B$29/365 -> -319.45822 | F40: =(F20+F24)*Assumptions!$B$29/365 -> -399.81461 | G40: =(G20+G24)*Assumptions!$B$29/365 -> -485.01011 | H40: =(H20+H24)*Assumptions!$B$29/365 -> -569.715 | I40: =(I20+I24)*Assumptions!$B$29/365 -> -647.31836 | J40: =(J20+J24)*Assumptions!$B$29/365 -> -710.62246 | ... L40: =(L20+L24)*Assumptions!$B$29/365 -> -768.62583
A41: Customer deposits / deferred revenue | B41: -50 | C41: =-C19*C15 -> -52.5 | D41: =-D19*D15 -> -70.875 | E41: =-E19*E15 -> -92.934844 | F41: =-F19*F15 -> -118.25959 | G41: =-G19*G15 -> -145.90277 | H41: =-H19*H15 -> -174.35381 | I41: =-I19*I15 -> -201.59659 | J41: =-J19*J15 -> -225.28419 | ... L41: =-L19*L15 -> -252.74633
A42: Net working capital | B42: =SUM(B37:B41) -> 180 | C42: =SUM(C37:C41) -> 183.82192 | D42: =SUM(D37:D41) -> 248.61267 | E42: =SUM(E37:E41) -> 326.58747 | F42: =SUM(F37:F41) -> 416.33855 | G42: =SUM(G37:G41) -> 514.5904 | H42: =SUM(H37:H41) -> 616.05012 | I42: =SUM(I37:I41) -> 713.5967 | ... L42: =SUM(L37:L41) -> 899.49996
A43: (Increase) / decrease in NWC — cash impact | C43: =-(C42-B42) -> -3.8219178 | D43: =-(D42-C42) -> -64.790753 | E43: =-(E42-D42) -> -77.974798 | F43: =-(F42-E42) -> -89.751083 | G43: =-(G42-F42) -> -98.251848 | H43: =-(H42-G42) -> -101.45972 | I43: =-(I42-H42) -> -97.546576 | J43: =-(J42-I42) -> -85.287785 | ... L43: =-(L42-K42) -> -36.149739
A45: CAPEX & PP&E (G2_Austin Phase 1 program, then maintenance)
...

Sheet WACC
A1: WEIGHTED AVERAGE COST OF CAPITAL — AUGUST 2026
A4: COST OF EQUITY (CAPM)
A5: Risk-free rate — 10Y UST | B5: 0.0455 | C5: tradingeconomics / FRED DGS10
A6: Levered beta | B6: 2.2 | C6: Small-cap solar manufacturer; post-pivot history is short — proxied high (e)
A7: Equity risk premium | B7: 0.0475 | C7: Damodaran implied ERP, mid-2026
A8: Company-specific premium | B8: 0.02 | C8: Added for policy dependence (45X), funding gap, single-plant concentration, short operating history
A9: Cost of equity | B9: =B5+B6*B7+B8 -> 0.17
A11: COST OF DEBT
A12: Pre-tax cost of debt | B12: 0.085 | C12: Convertible + project debt; high-yield territory
A13: Tax rate | B13: =Assumptions!B38 -> 0.21
A14: After-tax cost of debt | B14: =B12*(1-B13) -> 0.06715 | C14: Note: NOLs mean little near-term tax shield in practice
A16: CAPITAL STRUCTURE (market weights)
A17: Debt / total capitalization | B17: 0.26 | C17: ~$670mm debt vs ~$1.9B market cap
A18: Equity / total capitalization | B18: =1-B17 -> 0.74
A20: WACC | B20: =B18*B9+B17*B14 -> 0.143259
A22: WACC ≈ 13.5%. Sensitivity range in DCF: 11.5% – 15.5%. For a policy-dependent small-cap the discount rate is highly contestable — flex it.

Sheet DCF
A1: DISCOUNTED CASH FLOW — UNLEVERED FCF ($mm; valuation as of FY2026 year-end, mid-year convention)
B4: FY2027E | C4: FY2028E | D4: FY2029E | E4: FY2030E | F4: FY2031E | G4: FY2032E | H4: FY2033E | I4: FY2034E | J4: FY2035E
A5: EBIT | B5: =Model_3S!D28 -> 140.6475 | C5: =Model_3S!E28 -> 229.4458 | D5: =Model_3S!F28 -> 349.25999 | E5: =Model_3S!G28 -> 317.58169 | F5: =Model_3S!H28 -> 234.40901 | G5: =Model_3S!I28 -> 92.062443 | H5: =Model_3S!J28 -> -109.63831 | I5: =Model_3S!K28 -> -27.542869 | J5: =Model_3S!L28 -> 65.714046
A6: Cash taxes on EBIT | B6: =-MAX(0,B5)*Model_3S!D13 -> -2.81295 | C6: =-MAX(0,C5)*Model_3S!E13 -> -9.1778321 | D6: =-MAX(0,D5)*Model_3S!F13 -> -20.955599 | E6: =-MAX(0,E5)*Model_3S!G13 -> -25.406535 | F6: =-MAX(0,F5)*Model_3S!H13 -> -23.440901 | G6: =-MAX(0,G5)*Model_3S!I13 -> -11.047493 | H6: =-MAX(0,H5)*Model_3S!J13 -> 0 | I6: =-MAX(0,I5)*Model_3S!K13 -> 0 | J6: =-MAX(0,J5)*Model_3S!L13 -> -11.828528
A7: + D&A | B7: =-Model_3S!D27 -> 77.175 | C7: =-Model_3S!E27 -> 100.16311 | D7: =-Model_3S!F27 -> 126.14356 | E7: =-Model_3S!G27 -> 154.00848 | F7: =-Model_3S!H27 -> 182.10287 | G7: =-Model_3S!I27 -> 208.31648 | H7: =-Model_3S!J27 -> 230.2905 | I7: =-Model_3S!K27 -> 245.7256 | J7: =-Model_3S!L27 -> 252.74633
A8: − Capex | B8: =-Model_3S!D46 -> -210 | C8: =-Model_3S!E46 -> -55.760906 | D8: =-Model_3S!F46 -> -70.955753 | E8: =-Model_3S!G46 -> -87.541661 | F8: =-Model_3S!H46 -> -104.61228 | G8: =-Model_3S!I46 -> -120.95795 | H8: =-Model_3S!J46 -> -135.17051 | I8: =-Model_3S!K46 -> -145.81519 | J8: =-Model_3S!L46 -> -151.6478
A9: +/− Change in NWC | B9: =Model_3S!D43 -> -64.790753 | C9: =Model_3S!E43 -> -77.974798 | D9: =Model_3S!F43 -> -89.751083 | E9: =Model_3S!G43 -> -98.251848 | F9: =Model_3S!H43 -> -101.45972 | G9: =Model_3S!I43 -> -97.546576 | H9: =Model_3S!J43 -> -85.287785 | I9: =Model_3S!K43 -> -64.465739 | J9: =Model_3S!L43 -> -36.149739
A10: Unlevered free cash flow | B10: =SUM(B5:B9) -> -59.781203 | C10: =SUM(C5:C9) -> 186.69538 | D10: =SUM(D5:D9) -> 293.74111 | E10: =SUM(E5:E9) -> 260.39012 | F10: =SUM(F5:F9) -> 186.99897 | G10: =SUM(G5:G9) -> 70.826895 | H10: =SUM(H5:H9) -> -99.806099 | I10: =SUM(I5:I9) -> 7.9018001 | J10: =SUM(J5:J9) -> 118.83431
A11: Discount period (mid-year) | B11: 0.5 | C11: 1.5 | D11: 2.5 | E11: 3.5 | F11: 4.5 | G11: 5.5 | H11: 6.5 | I11: 7.5 | J11: 8.5
A12: Discount factor @ WACC | B12: =(1+$B$16)^-B11 -> 0.93524993 | C12: =(1+$B$16)^-C11 -> 0.81805604 | D12: =(1+$B$16)^-D11 -> 0.71554743 | E12: =(1+$B$16)^-E11 -> 0.62588393 | F12: =(1+$B$16)^-F11 -> 0.54745594 | G12: =(1+$B$16)^-G11 -> 0.47885557 | H12: =(1+$B$16)^-H11 -> 0.41885134 | I12: =(1+$B$16)^-I11 -> 0.3663661 | J12: =(1+$B$16)^-J11 -> 0.32045766
A13: PV of FCF | B13: =B10*B12 -> -55.910366 | C13: =C10*C12 -> 152.72728 | D13: =D10*D12 -> 210.1857 | E13: =E10*E12 -> 162.97399 | F13: =F10*F12 -> 102.3737 | G13: =G10*G12 -> 33.915853 | H13: =H10*H12 -> -41.803919 | I13: =I10*I12 -> 2.8949517 | J13: =J10*J12 -> 38.081365
A14: Watch the FY2030-33 columns: that's where the 45X step-down bites. If FCF turns negative there, the business never reached standalone viability.
A15: Sum of PV of explicit FCF (FY27–35) | B15: =SUM(B13:J13) -> 605.43855
A16: WACC | B16: =WACC!B20 -> 0.143259
A18: TERMINAL VALUE — METHOD 1: GORDON GROWTH
A19: Terminal growth g | B19: =Assumptions!B47 -> 0.02
A20: Terminal value | B20: =MAX(0,J10)*(1+B19)/(B16-B19) -> 983.38456 | C20: Floored at zero — a negative terminal FCF would imply a worthless (or liability) terminal business
A21: PV of terminal value (9.0 yrs) | B21: =B20/(1+B16)^9 -> 294.72822
A22: Implied exit EV/EBITDA | B22: =IFERROR(B20/Model_3S!L25,0) -> 2.5938644
A24: TERMINAL VALUE — METHOD 2: EXIT MULTIPLE
A25: Exit EV/Adj. EBITDA multiple | B25: =Assumptions!B48 -> 7
A26: Terminal value | B26: =MAX(0,B25*Model_3S!L25) -> 2653.8365
A27: PV of terminal value | B27: =B26/(1+B16)^9 -> 795.37603
A28: Implied perpetuity growth | B28: =IFERROR((B16*B26-J10)/(B26+J10),0) -> 0.094259892
A30: ENTERPRISE → EQUITY VALUE BRIDGE
A31: Net debt, FY2026E year-end (debt − cash) | B31: =Model_3S!C57-Model_3S!C72 -> 671.07192
A32: Diluted shares (mm) | B32: =Assumptions!B37 -> 279.3
B33: Gordon growth | C33: Exit multiple | D33: Average
A34: Enterprise value | B34: =B15+B21 -> 900.16678 | C34: =B15+B27 -> 1400.8146 | D34: =AVERAGE(B34:C34) -> 1150.4907
A35: − Net debt | B35: =-$B$31 -> -671.07192 | C35: =-$B$31 -> -671.07192 | D35: =-$B$31 -> -671.07192
A36: Equity value | B36: =B34+B35 -> 229.09486 | C36: =C34+C35 -> 729.74267 | D36: =D34+D35 -> 479.41876
A37: Implied value per share | B37: =MAX(0,B36)/$B$32 -> 0.82024654 | C37: =MAX(0,C36)/$B$32 -> 2.6127557 | D37: =MAX(0,D36)/$B$32 -> 1.7165011
A38: Upside / (downside) vs current price | B38: =B37/Assumptions!$B$49-1 -> -0.87955264 | C38: =C37/Assumptions!$B$49-1 -> -0.61633543 | D38: =D37/Assumptions!$B$49-1 -> -0.74794404
A40: Equity floored at zero: with ~$520mm net debt, a weak enough operating case wipes out the equity before the enterprise. That IS the bear case for a levered manufacturer.
A42: SENSITIVITY — VALUE PER SHARE: WACC × TERMINAL GROWTH (Gordon)
B43: WACC \ g | C43: 0.01 | D43: 0.015 | E43: 0.02 | F43: 0.025 | G43: 0.03
B44: 0.115 | C44: =MAX(0,SUMPRODUCT($B$10:$J$10,(1+$B$44)^-($B$11:$J$11))+MAX(0,$J$10)*(1+C$43)/($B$44-C$43)/(1+$B$44)^9-$B$31)/$B$32 -> 1.4915465 | D44: =MAX(0,SUMPRODUCT($B$10:$J$10,(1+$B$44)^-($B$11:$J$11))+MAX(0,$J$10)*(1+D$43)/($B$44-D$43)/(1+$B$44)^9-$B$31)/$B$32 -> 1.5763576 | E44: =MAX(0,SUMPRODUCT($B$10:$J$10,(1+$B$44)^-($B$11:$J$11))+MAX(0,$J$10)*(1+E$43)/($B$44-E$43)/(1+$B$44)^9-$B$31)/$B$32 -> 1.6700961 | F44: =MAX(0,SUMPRODUCT($B$10:$J$10,(1+$B$44)^-($B$11:$J$11))+MAX(0,$J$10)*(1+F$43)/($B$44-F$43)/(1+$B$44)^9-$B$31)/$B$32 -> 1.7742501 | G44: =MAX(0,SUMPRODUCT($B$10:$J$10,(1+$B$44)^-($B$11:$J$11))+MAX(0,$J$10)*(1+G$43)/($B$44-G$43)/(1+$B$44)^9-$B$31)/$B$32 -> 1.8906575
B45: 0.125 | C45: =MAX(0,SUMPRODUCT($B$10:$J$10,(1+$B$45)^-($B$11:$J$11))+MAX(0,$J$10)*(1+C$43)/($B$45-C$43)/(1+$B$45)^9-$B$31)/$B$32 -> 1.1796452 | D45: =MAX(0,SUMPRODUCT($B$10:$J$10,(1+$B$45)^-($B$11:$J$11))+MAX(0,$J$10)*(1+D$43)/($B$45-D$43)/(1+$B$45)^9-$B$31)/$B$32 -> 1.2451887 | E45: =MAX(0,SUMPRODUCT($B$10:$J$10,(1+$B$45)^-($B$11:$J$11))+MAX(0,$J$10)*(1+E$43)/($B$45-E$43)/(1+$B$45)^9-$B$31)/$B$32 -> 1.3169746 | F45: =MAX(0,SUMPRODUCT($B$10:$J$10,(1+$B$45)^-($B$11:$J$11))+MAX(0,$J$10)*(1+F$43)/($B$45-F$43)/(1+$B$45)^9-$B$31)/$B$32 -> 1.395939 | G45: =MAX(0,SUMPRODUCT($B$10:$J$10,(1+$B$45)^-($B$11:$J$11))+MAX(0,$J$10)*(1+G$43)/($B$45-G$43)/(1+$B$45)^9-$B$31)/$B$32 -> 1.4832155
B46: 0.135 | C46: =MAX(0,SUMPRODUCT($B$10:$J$10,(1+$B$46)^-($B$11:$J$11))+MAX(0,$J$10)*(1+C$43)/($B$46-C$43)/(1+$B$46)^9-$B$31)/$B$32 -> 0.91795599 | D46: =MAX(0,SUMPRODUCT($B$10:$J$10,(1+$B$46)^-($B$11:$J$11))+MAX(0,$J$10)*(1+D$43)/($B$46-D$43)/(1+$B$46)^9-$B$31)/$B$32 -> 0.96945309 | E46: =MAX(0,SUMPRODUCT($B$10:$J$10,(1+$B$46)^-($B$11:$J$11))+MAX(0,$J$10)*(1+E$43)/($B$46-E$43)/(1+$B$46)^9-$B$31)/$B$32 -> 1.0254282 | F46: =MAX(0,SUMPRODUCT($B$10:$J$10,(1+$B$46)^-($B$11:$J$11))+MAX(0,$J$10)*(1+F$43)/($B$46-F$43)/(1+$B$46)^9-$B$31)/$B$32 -> 1.086492 | G46: =MAX(0,SUMPRODUCT($B$10:$J$10,(1+$B$46)^-($B$11:$J$11))+MAX(0,$J$10)*(1+G$43)/($B$46-G$43)/(1+$B$46)^9-$B$31)/$B$32 -> 1.1533713
B47: 0.145 | C47: =MAX(0,SUMPRODUCT($B$10:$J$10,(1+$B$47)^-($B$11:$J$11))+MAX(0,$J$10)*(1+C$43)/($B$47-C$43)/(1+$B$47)^9-$B$31)/$B$32 -> 0.6950886 | D47: =MAX(0,SUMPRODUCT($B$10:$J$10,(1+$B$47)^-($B$11:$J$11))+MAX(0,$J$10)*(1+D$43)/($B$47-D$43)/(1+$B$47)^9-$B$31)/$B$32 -> 0.73612034 | E47: =MAX(0,SUMPRODUCT($B$10:$J$10,(1+$B$47)^-($B$11:$J$11))+MAX(0,$J$10)*(1+E$43)/($B$47-E$43)/(1+$B$47)^9-$B$31)/$B$32 -> 0.78043462 | F47: =MAX(0,SUMPRODUCT($B$10:$J$10,(1+$B$47)^-($B$11:$J$11))+MAX(0,$J$10)*(1+F$43)/($B$47-F$43)/(1+$B$47)^9-$B$31)/$B$32 -> 0.82844175 | G47: =MAX(0,SUMPRODUCT($B$10:$J$10,(1+$B$47)^-($B$11:$J$11))+MAX(0,$J$10)*(1+G$43)/($B$47-G$43)/(1+$B$47)^9-$B$31)/$B$32 -> 0.88062342
...

Sheet Comps
A1: TRADING COMPARABLES — SOLAR MANUFACTURING (Aug 2026; peer multiples estimated)
A4: Company | B4: Ticker | C4: EV/Revenue | D4: EV/EBITDA | E4: Note
A5: First Solar | B5: FSLR | C5: 3 | D5: 8 | E5: e — the US-manufacturing benchmark; thin-film, 45X beneficiary, profitable
A6: Canadian Solar | B6: CSIQ | C6: 0.4 | D6: 6 | E6: e — global module maker; commodity economics
A7: JinkoSolar | B7: JKS | C7: 0.3 | D7: 5 | E7: e — Chinese scale player; the pricing pressure source
A8: Array Technologies | B8: ARRY | C8: 1.2 | D8: 8 | E8: e — US solar equipment (trackers)
A9: T1 Energy (self) | B9: TE | C9: =(Assumptions!B49*Assumptions!B37+DCF!B31)/Model_3S!C19 -> 2.4505761 | D9: =IFERROR((Assumptions!B49*Assumptions!B37+DCF!B31)/Model_3S!C25,0) -> 16.337174 | E9: EV/EBITDA is meaningless while FY26E EBITDA is ~zero/negative — use EV/Revenue
A10: Peer median (ex-TE) | C10: =MEDIAN(C5:C8) -> 0.8 | D10: =MEDIAN(D5:D8) -> 7
A11: Solar manufacturing is a COMMODITY industry — module makers trade at fractions of revenue. Only FSLR earns a premium (differentiated thin-film + scale + credits). TE's valuation case rests on becoming FSLR-like, not CSIQ-like.
A13: IMPLIED VALUE PER SHARE
A14: Method | B14: Low x | C14: High x | D14: Metric | E14: $/sh low | F14: $/sh high
A15: EV/Revenue × FY2026E revenue | B15: 0.8 | C15: 2 | D15: =Model_3S!C19 -> 1050 | E15: =MAX(0,B15*D15-DCF!$B$31)/Assumptions!$B$37 -> 0.60482665 | F15: =MAX(0,C15*D15-DCF!$B$31)/Assumptions!$B$37 -> 5.1161048
A16: EV/EBITDA × FY2029E (post-ramp, pre-phase-out) | B16: 5 | C16: 8 | D16: =Model_3S!F25 -> 516.4002 | E16: =MAX(0,B16*D16-DCF!$B$31)/Assumptions!$B$37 -> 6.8418514 | F16: =MAX(0,C16*D16-DCF!$B$31)/Assumptions!$B$37 -> 12.388578
A18: FY2029E is used for the EBITDA method: it's the last year of full 45X before the step-down, i.e. peak reported profitability.

Sheet Precedents
A1: PRECEDENT TRANSACTIONS — SOLAR / CLEAN-ENERGY MANUFACTURING
A4: Date | B4: Acquirer | C4: Target | D4: EV ($mm) | E4: Basis | F4: Note
A5: Nov-2024 | B5: T1 Energy (FREYR) | C5: Trina Solar US assets (G1_Dallas) | D5: 340 | E5: ~$0.07/W capacity | F5: T1's own founding deal — 5 GW module plant
A6: 2026 | B6: T1 Energy | C6: KORE Power | E6: n/d | F6: Storage + AI data-center infrastructure ('T1 NRI')
A7: 2026 | B7: T1 Energy | C7: Evervolt solar patents | D7: 135 | E7: IP | F7: Foundational solar patents
A8: 2023-25 | B8: Qcells / Hanwha | C8: US manufacturing buildout | D8: 2500 | E8: capacity investment | F8: e — Georgia integrated plant; not an M&A comp but a capacity benchmark
A9: 2022 | B9: SK / others | C9: US cell capacity investments | E9: n/d | F9: Policy-driven capacity announcements post-IRA
A11: There is no clean M&A comp set for a sub-scale US solar manufacturer — most transactions are capacity investments or distressed asset purchases, and several US module ventures have failed outright. The band below is a CAPACITY-BASED framework ($/W of installed nameplate), which is how these assets actually change hands.
A13: APPLIED RANGE — $/W OF NAMEPLATE CAPACITY
B14: Low | C14: High
A15: Nameplate capacity (GW) — G1 modules (+G2 cells from 2027) | B15: 5 | C15: 8
A16: EV per watt ($/W) | B16: 0.07 | C16: 0.15
A17: Implied EV ($mm) | B17: =B15*1000*B16 -> 350 | C17: =C15*1000*C16 -> 1200
A18: Implied value per share | B18: =MAX(0,B17-DCF!$B$31)/Assumptions!$B$37 -> 0 | C18: =MAX(0,C17-DCF!$B$31)/Assumptions!$B$37 -> 1.8937633
A20: $0.07/W ≈ what T1 paid for Trina's G1 assets. $0.15/W reflects a strategic premium for a de-risked, credit-qualified US line. Note how sensitive the per-share result is to net debt — that's the leverage at work.

Sheet LBO
A1: LBO / CONTROL-BUYOUT ANALYSIS — 5-YEAR HOLD (ENTRY END-FY2026, EXIT END-FY2031) ($mm)
A2: A conventional LBO is NOT viable here: FY2026E EBITDA is ~zero/negative and the company already carries ~$670mm of debt against a $510mm capex program. Debt capacity is sized off FY2029E EBITDA (peak-45X) and the sponsor must FUND the buildout — this is a growth-equity / distressed-control structure, not a classic buyout.
A5: ENTRY & FINANCING
A6: Entry premium to current price | B6: 0.3
A7: Entry price per share | B7: =Assumptions!B49*(1+B6) -> 8.853
A8: Diluted shares (mm) | B8: =Assumptions!B37 -> 279.3
A9: Equity purchase price | B9: =B7*B8 -> 2472.6429
A10: Plus: net debt assumed/refinanced | B10: =DCF!B31 -> 671.07192
A11: Entry enterprise value | B11: =B9+B10 -> 3143.7148
A12: Transaction fees (% of EV) | B12: 0.02
A13: FY2029E Adj. EBITDA (debt-sizing basis, peak 45X) | B13: =Model_3S!F25 -> 516.4002
A14: Entry EV / FY2029E EBITDA | B14: =IFERROR(B11/B13,0) -> 6.087749
A15: Debt tranche | B15: Multiple (on FY29E) | C15: Rate | D15: Amount
A16: Term Loan B | B16: 3 | C16: 0.095 | D16: =MAX(0,B16*$B$13) -> 1549.2006
A17: Senior notes | B17: 1 | C17: 0.115 | D17: =MAX(0,B17*$B$13) -> 516.4002
A18: Total new debt | B18: =B16+B17 -> 4 | D18: =D16+D17 -> 2065.6008
A19: Sponsor equity = EV×(1+fees) − debt | B19: =B11*(1+B12)-D18 -> 1140.9883
A20: Plus: capex/burn funding during hold (negative FCF) | B20: =-SUMIF(DCF!B10:F10,"<0") -> 59.781203
A21: TOTAL SPONSOR COMMITMENT | B21: =B19+B20 -> 1200.7695
A23: DEBT PAYDOWN — 100% FCF SWEEP (post-funding)
B24: FY2027E | C24: FY2028E | D24: FY2029E | E24: FY2030E | F24: FY2031E
A25: Unlevered FCF (DCF sheet) | B25: =DCF!B10 -> -59.781203 | C25: =DCF!C10 -> 186.69538 | D25: =DCF!D10 -> 293.74111 | E25: =DCF!E10 -> 260.39012 | F25: =DCF!F10 -> 186.99897
A26: Cash interest — TLB (beginning) | B26: =-$D$16*$C$16 -> -147.17406 | C26: =-B32*$C$16 -> -147.17406 | D26: =-C32*$C$16 -> -144.94033 | E26: =-D32*$C$16 -> -132.36962 | F26: =-E32*$C$16 -> -122.02382
A27: Cash interest — notes | B27: =-$D$17*$C$17 -> -59.386023 | C27: =-$D$17*$C$17 -> -59.386023 | D27: =-$D$17*$C$17 -> -59.386023 | E27: =-$D$17*$C$17 -> -59.386023 | F27: =-$D$17*$C$17 -> -59.386023
A28: Interest tax shield | B28: =-(B26+B27)*Assumptions!$B$38 -> 43.377617 | C28: =-(C26+C27)*Assumptions!$B$38 -> 43.377617 | D28: =-(D26+D27)*Assumptions!$B$38 -> 42.908535 | E28: =-(E26+E27)*Assumptions!$B$38 -> 40.268685 | F28: =-(F26+F27)*Assumptions!$B$38 -> 38.096067
A29: Levered FCF for paydown | B29: =MAX(0,B25+B26+B27+B28) -> 0 | C29: =MAX(0,C25+C26+C27+C28) -> 23.512912 | D29: =MAX(0,D25+D26+D27+D28) -> 132.32329 | E29: =MAX(0,E25+E26+E27+E28) -> 108.90317 | F29: =MAX(0,F25+F26+F27+F28) -> 43.685194
A30: TLB — beginning | B30: =$D$16 -> 1549.2006 | C30: =B32 -> 1549.2006 | D30: =C32 -> 1525.6877 | E30: =D32 -> 1393.3644 | F30: =E32 -> 1284.4612
A31: TLB — (paydown) | B31: =-MIN(B30,B29) -> 0 | C31: =-MIN(C30,C29) -> -23.512912 | D31: =-MIN(D30,D29) -> -132.32329 | E31: =-MIN(E30,E29) -> -108.90317 | F31: =-MIN(F30,F29) -> -43.685194
A32: TLB — ending | B32: =B30+B31 -> 1549.2006 | C32: =C30+C31 -> 1525.6877 | D32: =D30+D31 -> 1393.3644 | E32: =E30+E31 -> 1284.4612 | F32: =F30+F31 -> 1240.776
A33: Notes — ending (bullet) | B33: =$D$17 -> 516.4002 | C33: =$D$17 -> 516.4002 | D33: =$D$17 -> 516.4002 | E33: =$D$17 -> 516.4002 | F33: =$D$17 -> 516.4002
A34: Total debt — ending | B34: =B32+B33 -> 2065.6008 | C34: =C32+C33 -> 2042.0879 | D34: =D32+D33 -> 1909.7646 | E34: =E32+E33 -> 1800.8614 | F34: =F32+F33 -> 1757.1763
A36: EXIT & RETURNS
A37: FY2031E Adj. EBITDA | B37: =Model_3S!H25 -> 470.75528
A38: Exit EV/EBITDA multiple | B38: 7
A39: Exit enterprise value | B39: =MAX(0,B37*B38) -> 3295.287
A40: Less: exit net debt | B40: =-F34 -> -1757.1763
A41: Exit equity value | B41: =MAX(0,B39+B40) -> 1538.1107
A42: MOIC | B42: =IFERROR(B41/B21,0) -> 1.2809375
A43: IRR (5-yr) | B43: =IFERROR(MAX(-0.99,(B42)^(1/5)-1),-0.99) -> 0.050764977 | C43: Note FY2031 sits INSIDE the 45X step-down — a sponsor exiting then sells a business whose credits are already fading
A45: MAXIMUM ENTRY PRICE AT TARGET IRR THRESHOLDS
...

Sheet Monte_Carlo
A1: MONTE CARLO SIMULATION — 500 LIVE TRIALS (press F9 / recalc to refresh)
A2: Four random variables including 45X SURVIVAL — the policy variable that dominates this equity. Value floored at zero (levered small-cap: the equity can go to zero while the plant still exists).
A4: Distribution parameters
A5: Variable | B5: Mean (linked) | C5: σ (input)
A6: FY2027 revenue growth | B6: =Assumptions!E12 -> 0.35 | C6: 0.15
A7: Terminal ex-45X gross margin | B7: =Assumptions!F17 -> 0.14 | C7: 0.05
A8: WACC | B8: =WACC!B20 -> 0.143259 | C8: 0.02
A9: 45X survival factor at FY2035 (0=full phase-out, 1=extended) | B9: 0.25 | C9: 0.25
A11: Calibration statics (linked)
A12: FY2026E revenue | B12: =Model_3S!C19 -> 1050
A13: Base PV of explicit FCF (DCF) | B13: =DCF!B15 -> 605.43855
A14: Net debt FY2026E | B14: =DCF!B31 -> 671.07192
A15: Diluted shares (mm) | B15: =Assumptions!B37 -> 279.3
A16: Current share price | B16: =Assumptions!B49 -> 6.81
A17: FY2035 growth (selected) | B17: =Assumptions!E13 -> 0.04
A18: Terminal opex % revenue | B18: =Assumptions!F19 -> 0.065
A19: 45X credit rate % revenue | B19: =Assumptions!F18 -> 0.28
A20: Exit multiple | B20: =Assumptions!B48 -> 7
A22: Simulation results ($/share)
A23: Mean | B23: =AVERAGE($K$41:$K$540) -> 6.8673325
A24: Median | B24: =MEDIAN($K$41:$K$540) -> 5.1265554
A25: Standard deviation | B25: =STDEV($K$41:$K$540) -> 6.2331412
A26: 5th percentile | B26: =PERCENTILE($K$41:$K$540,0.05) -> 0.39732199
A27: 25th percentile | B27: =PERCENTILE($K$41:$K$540,0.25) -> 2.7557878
A28: 75th percentile | B28: =PERCENTILE($K$41:$K$540,0.75) -> 9.303632
A29: 95th percentile | B29: =PERCENTILE($K$41:$K$540,0.95) -> 18.674883
A30: P(value > current price) | B30: =COUNTIF($K$41:$K$540,">"&B16)/500 -> 0.388
A31: P(equity ≈ zero) | B31: =COUNTIF($K$41:$K$540,"<0.5")/500 -> 0.056 | C31: The wipeout probability — the number that matters most for a levered, policy-dependent equity
A33: Scenario probability-weighted value
A34: Scenario | B34: Probability | C34: Value / share
A35: Base | B35: =Assumptions!B8 -> 0.4 | C35: =MAX(0,$B$13+MAX(0,$B$20*(($B$12*(1+(Assumptions!B12+Assumptions!B13)/2)^9)*(Assumptions!C17-Assumptions!C19+$B$19*0.25)))/(1+$B$8)^9-$B$14)/$B$15 -> 5.4482201
A36: Bull | B36: =Assumptions!C8 -> 0.2 | C36: =MAX(0,$B$13+MAX(0,$B$20*(($B$12*(1+(Assumptions!C12+Assumptions!C13)/2)^9)*(Assumptions!D17-Assumptions!D19+$B$19*0.6)))/(1+$B$8)^9-$B$14)/$B$15 -> 27.812933
A37: Bear | B37: =Assumptions!D8 -> 0.4 | C37: =MAX(0,$B$13+MAX(0,$B$20*(($B$12*(1+(Assumptions!D12+Assumptions!D13)/2)^9)*(Assumptions!E17-Assumptions!E19+$B$19*0)))/(1+$B$8)^9-$B$14)/$B$15 -> 0
A38: Probability-weighted value | C38: =SUMPRODUCT(B35:B37,C35:C37) -> 7.7418746
A39: Bear assumes ZERO 45X survival at FY35 with unimproved margins — the structural-unviability case.
A40: # | B40: g FY27 | C40: Term GM | D40: WACC | E40: 45X surv | F40: Rev FY35 | G40: EBITDA FY35 | H40: PV(TV) | I40: PV(FCF) | J40: Equity | K40: $ / share | N40: Bin ($/sh) | O40: low | P40: high | Q40: Count
A41: 1 | B41: =NORMINV(RAND(),$B$6,$C$6) -> 0.49740921 | C41: =MAX(-0.05,NORMINV(RAND(),$B$7,$C$7)) -> 0.17484364 | D41: =MAX(0.08,NORMINV(RAND(),$B$8,$C$8)) -> 0.11468295 | E41: =MEDIAN(0,NORMINV(RAND(),$B$9,$C$9),1) -> 0.53652888 | F41: =$B$12*(1+(B41+$B$17)/2)^9 -> 8941.9851 | G41: =F41*(C41-$B$18+$B$19*E41) -> 2325.5575 | H41: =MAX(0,$B$20*G41)/(1+D41)^9 -> 6127.2118 | I41: =$B$13*((1+$B$8)/(1+D41))^4.5 -> 678.48428 | J41: =H41+I41-$B$14 -> 6134.6242 | K41: =MAX(0,J41)/$B$15 -> 21.964283 | N41: 0-1 | O41: 0 | P41: 1 | Q41: =COUNTIFS($K$41:$K$540,">="&O41,$K$41:$K$540,"<"&P41) -> 43
A42: 2 | B42: =NORMINV(RAND(),$B$6,$C$6) -> 0.36159955 | C42: =MAX(-0.05,NORMINV(RAND(),$B$7,$C$7)) -> 0.10317627 | D42: =MAX(0.08,NORMINV(RAND(),$B$8,$C$8)) -> 0.12743126 | E42: =MEDIAN(0,NORMINV(RAND(),$B$9,$C$9),1) -> 0 | F42: =$B$12*(1+(B42+$B$17)/2)^9 -> 5450.3536 | G42: =F42*(C42-$B$18+$B$19*E42) -> 208.07418 | H42: =MAX(0,$B$20*G42)/(1+D42)^9 -> 494.88647 | I42: =$B$13*((1+$B$8)/(1+D42))^4.5 -> 644.63751 | J42: =H42+I42-$B$14 -> 468.45206 | K42: =MAX(0,J42)/$B$15 -> 1.6772362 | N42: 1-2 | O42: 1 | P42: 2 | Q42: =COUNTIFS($K$41:$K$540,">="&O42,$K$41:$K$540,"<"&P42) -> 45
A43: 3 | B43: =NORMINV(RAND(),$B$6,$C$6) -> 0.38820571 | C43: =MAX(-0.05,NORMINV(RAND(),$B$7,$C$7)) -> 0.15321545 | D43: =MAX(0.08,NORMINV(RAND(),$B$8,$C$8)) -> 0.12844315 | E43: =MEDIAN(0,NORMINV(RAND(),$B$9,$C$9),1) -> 0.3671748 | F43: =$B$12*(1+(B43+$B$17)/2)^9 -> 6018.505 | G43: =F43*(C43-$B$18+$B$19*E43) -> 1149.6812 | H43: =MAX(0,$B$20*G43)/(1+D43)^9 -> 2712.4287 | I43: =$B$13*((1+$B$8)/(1+D43))^4.5 -> 642.04035 | J43: =H43+I43-$B$14 -> 2683.3971 | K43: =MAX(0,J43)/$B$15 -> 9.60758 | N43: 2-3 | O43: 2 | P43: 3 | Q43: =COUNTIFS($K$41:$K$540,">="&O43,$K$41:$K$540,"<"&P43) -> 47
A44: 4 | B44: =NORMINV(RAND(),$B$6,$C$6) -> 0.36099193 | C44: =MAX(-0.05,NORMINV(RAND(),$B$7,$C$7)) -> 0.13756578 | D44: =MAX(0.08,NORMINV(RAND(),$B$8,$C$8)) -> 0.14555265 | E44: =MEDIAN(0,NORMINV(RAND(),$B$9,$C$9),1) -> 0.51060296 | F44: =$B$12*(1+(B44+$B$17)/2)^9 -> 5437.9555 | G44: =F44*(C44-$B$18+$B$19*E44) -> 1172.0676 | H44: =MAX(0,$B$20*G44)/(1+D44)^9 -> 2414.9892 | I44: =$B$13*((1+$B$8)/(1+D44))^4.5 -> 600.00262 | J44: =H44+I44-$B$14 -> 2343.9199 | K44: =MAX(0,J44)/$B$15 -> 8.3921227 | N44: 3-4 | O44: 3 | P44: 4 | Q44: =COUNTIFS($K$41:$K$540,">="&O44,$K$41:$K$540,"<"&P44) -> 56
...

Sheet Football_Field
A1: FOOTBALL FIELD — VALUATION SUMMARY ($ per share)
A2: =CONCATENATE("Current price: $",TEXT(Assumptions!B49,"0.00")," · Scenario: ",CHOOSE(Assumptions!B4,"BASE","BULL","BEAR")," · Probability-weighted value: $",TEXT(Monte_Carlo!C38,"0.00")) -> Current price: $6.81 · Scenario: BASE · Probability-weighted value: $7.74
A4: Methodology | B4: Low | C4: High | D4: (base) | E4: (span) | F4: Midpoint
A5: 52-week trading range (e) | B5: 3 | C5: 12 | D5: =MIN(B5,C5) -> 3 | E5: =ABS(C5-B5) -> 9 | F5: =(B5+C5)/2 -> 7.5
A6: Analyst targets (avg ~$10.07; low $7 Alliance Global) | B6: 7 | C6: 13 | D6: =MIN(B6,C6) -> 7 | E6: =ABS(C6-B6) -> 6 | F6: =(B6+C6)/2 -> 10
A7: DCF — Gordon growth (WACC ±2%, g 1.5-2.5%) | B7: =MAX(0,SUMPRODUCT(DCF!$B$10:$J$10,(1+(WACC!$B$20+0.02))^-DCF!$B$11:$J$11)+MAX(0,DCF!$J$10)*(1+0.015)/((WACC!$B$20+0.02)-0.015)/(1+(WACC!$B$20+0.02))^9-DCF!$B$31)/DCF!$B$32 -> 0.39067919 | C7: =MAX(0,SUMPRODUCT(DCF!$B$10:$J$10,(1+(WACC!$B$20-0.02))^-DCF!$B$11:$J$11)+MAX(0,DCF!$J$10)*(1+0.025)/((WACC!$B$20-0.02)-0.025)/(1+(WACC!$B$20-0.02))^9-DCF!$B$31)/DCF!$B$32 -> 1.456251 | D7: =MIN(B7,C7) -> 0.39067919 | E7: =ABS(C7-B7) -> 1.0655718 | F7: =(B7+C7)/2 -> 0.9234651
A8: DCF — exit multiple (5.5-8.5x, WACC ±2%) | B8: =MAX(0,SUMPRODUCT(DCF!$B$10:$J$10,(1+(WACC!$B$20+0.02))^-DCF!$B$11:$J$11)+MAX(0,5.5*Model_3S!$L$25)/(1+(WACC!$B$20+0.02))^9-DCF!$B$31)/DCF!$B$32 -> 1.5580064 | C8: =MAX(0,SUMPRODUCT(DCF!$B$10:$J$10,(1+(WACC!$B$20-0.02))^-DCF!$B$11:$J$11)+MAX(0,8.5*Model_3S!$L$25)/(1+(WACC!$B$20-0.02))^9-DCF!$B$31)/DCF!$B$32 -> 3.9503103 | D8: =MIN(B8,C8) -> 1.5580064 | E8: =ABS(C8-B8) -> 2.3923039 | F8: =(B8+C8)/2 -> 2.7541583
A9: Comps — EV/Revenue (0.8-2.0x FY26E) | B9: =Comps!E15 -> 0.60482665 | C9: =Comps!F15 -> 5.1161048 | D9: =MIN(B9,C9) -> 0.60482665 | E9: =ABS(C9-B9) -> 4.5112782 | F9: =(B9+C9)/2 -> 2.8604657
A10: Comps — EV/EBITDA (5-8x FY29E peak-45X) | B10: =Comps!E16 -> 6.8418514 | C10: =Comps!F16 -> 12.388578 | D10: =MIN(B10,C10) -> 6.8418514 | E10: =ABS(C10-B10) -> 5.5467261 | F10: =(B10+C10)/2 -> 9.6152145
A11: Precedent framework ($0.07-0.15/W capacity) | B11: =Precedents!B18 -> 0 | C11: =Precedents!C18 -> 1.8937633 | D11: =MIN(B11,C11) -> 0 | E11: =ABS(C11-B11) -> 1.8937633 | F11: =(B11+C11)/2 -> 0.94688164
A12: Buyout capacity (25% → 15% IRR) | B12: =LBO!D49 -> 0 | C12: =LBO!D47 -> 0.12123071 | D12: =MIN(B12,C12) -> 0 | E12: =ABS(C12-B12) -> 0.12123071 | F12: =(B12+C12)/2 -> 0.060615354
A13: Monte Carlo P25–P75 (live) | B13: =Monte_Carlo!B27 -> 2.7557878 | C13: =Monte_Carlo!B28 -> 9.303632 | D13: =MIN(B13,C13) -> 2.7557878 | E13: =ABS(C13-B13) -> 6.5478442 | F13: =(B13+C13)/2 -> 6.0297099
A14: Current price (marker) | B14: =Assumptions!B49-0.15 -> 6.66 | C14: =Assumptions!B49+0.15 -> 6.96 | D14: =MIN(B14,C14) -> 6.66 | E14: =ABS(C14-B14) -> 0.3 | F14: =(B14+C14)/2 -> 6.81
A16: 52-wk range estimated (post-rebrand ticker history is short). Analyst dispersion ($7 to $13+) is unusually wide — itself a signal that this is a binary, policy-dependent equity rather than a valuation debate.
