Workbook

Sheet Cover
A1: VISTRA CORP. (NYSE: VST) — DCF VALUATION & 3-STATEMENT OPERATING MODEL
A2: Prepared July 20, 2026 · $ millions except per-share · Calendar fiscal year · Data via Alpha Vantage (SEC-mapped financials) as of 7/17/2026
A4: CONTENTS
A5: Assumptions | C5: Scenario switch & levers (edit yellow cells)
A6: Historicals | C6: FY2021–FY2025 GAAP actuals, Q1-2026, FY2026E consensus build
A7: Model_3S | C7: Linked IS/BS/CF, working capital, capex, debt schedule, dividends & buybacks, FY2026E–FY2035E
A8: WACC | C8: CAPM with live market inputs (beta 1.41, 10Y 4.55%)
A9: DCF | C9: Unlevered FCF, Gordon + exit-multiple terminal values, sensitivities
A10: Comps | C10: IPP peer multiples (CEG, NRG, TLN) — pulled live from Alpha Vantage
A11: Precedents | C11: Power-generation M&A precedent transactions
A12: LBO | C12: Take-private analysis; max price at 15/20/25/30% IRR
A13: Monte_Carlo | C13: 500 live trials + scenario probability weights
A14: Football_Field | C14: Valuation summary chart vs. current price
A16: LEGEND
A17: Blue font / yellow fill | C17: Hardcoded input or scenario lever — edit these
A18: Black font | C18: Formula — do not overwrite
A19: Green font | C19: Link to another sheet
A20: 'e' | C20: Estimated (company adjusted measures, deal terms) — see notes
A22: KEY MODELING NOTES
A23: 1. | C23: VST GAAP results carry large non-cash commodity mark-to-market swings (Q4-25 gross profit was negative). The model anchors on adjusted EBITDA and analyst consensus; GAAP history is shown for reference.
A24: 2. | C24: FY2026E revenue $23.27B and adj. EPS $9.95 are analyst consensus (13 analysts, Alpha Vantage). Adj. EPS excludes MTM and other items, so it exceeds the model's GAAP-normalized EPS.
A25: 3. | C25: Total debt $20.4B is modeled as refinanced at maturity (constant unless the issuance row is edited); ~$2.0B preferred deducted in the equity bridge.
A27: KEY SOURCES
A28: Financial statements & ratios | C28: Alpha Vantage MCP: INCOME_STATEMENT / BALANCE_SHEET / CASH_FLOW / COMPANY_OVERVIEW / EARNINGS_ESTIMATES (VST, CEG, NRG, TLN), 7/17-20/2026
A29: Price & 52-wk range | C29: Alpha Vantage GLOBAL_QUOTE 7/17/2026: $155.44; 52-wk $132.48–$218.91
A30: 10Y UST 4.55% (7/17/2026) | C30: tradingeconomics.com / FRED DGS10
A31: Precedent transactions | C31: Public deal announcements; multiples approximate — see Precedents notes
A33: DISCLAIMER | C33: Educational model, not investment advice. Verify against Vistra filings before relying on any output.

Sheet Assumptions
A1: ASSUMPTIONS & SCENARIO LEVERS — VISTRA
A2: Edit yellow cells. Switch drives Model_3S, DCF, LBO, Monte Carlo.
A4: SCENARIO SWITCH (1 = Base, 2 = Bull, 3 = Bear) | B4: 1 | C4: =CHOOSE($B$4,"BASE — consensus trajectory","BULL — data-center demand upside","BEAR — power-price normalization") -> BASE — consensus trajectory
A6: Scenario probability weights
B7: Base | C7: Bull | D7: Bear | E7: Total
A8: Probability | B8: 0.5 | C8: 0.3 | D8: 0.2 | E8: =SUM(B8:D8) -> 1
A10: Revenue growth — decays linearly from FY2027 rate to FY2035 rate
B11: Base | C11: Bull | D11: Bear | E11: Selected
A12: FY2027 revenue growth | B12: 0.086 | C12: 0.126 | D12: 0.026 | E12: =CHOOSE($B$4,B12,C12,D12) -> 0.086
A13: FY2035 revenue growth (terminal-year) | B13: 0.025 | C13: 0.04 | D13: 0 | E13: =CHOOSE($B$4,B13,C13,D13) -> 0.025
A14: Base FY27 = consensus ($25.3B, +8.6%). Bull +4pp (accelerated data-center PPAs); Bear −6pp (commodity give-back). FY2026E revenue is consensus $23.27B.
A15: Operating drivers — FY2026 start ramps linearly to FY2035 target
A16: Driver | B16: FY26 start | C16: Base target | D16: Bull target | E16: Bear target | F16: Selected
A17: Gross margin (energy margin, excl. D&A) | B17: 0.375 | C17: 0.39 | D17: 0.42 | E17: 0.36 | F17: =CHOOSE($B$4,C17,D17,E17) -> 0.39
A18: SG&A / other opex (% revenue) | B18: 0.072 | C18: 0.065 | D18: 0.06 | E18: 0.08 | F18: =CHOOSE($B$4,C18,D18,E18) -> 0.065
A19: Stock-based compensation (% revenue) | B19: 0.005 | C19: 0.005 | D19: 0.005 | E19: 0.005 | F19: =CHOOSE($B$4,C19,D19,E19) -> 0.005
A20: D&A incl. nuclear fuel amortization (% revenue) | B20: 0.127 | C20: 0.115 | D20: 0.115 | E20: 0.125 | F20: =CHOOSE($B$4,C20,D20,E20) -> 0.115
A21: Capex incl. growth/solar/gas builds (% revenue) | B21: 0.17 | C21: 0.11 | D21: 0.13 | E21: 0.09 | F21: =CHOOSE($B$4,C21,D21,E21) -> 0.11
A22: Cash tax rate | B22: 0.21 | C22: 0.23 | D22: 0.23 | E22: 0.21 | F22: =CHOOSE($B$4,C22,D22,E22) -> 0.23
A23: Other current assets — margin deposits etc. (% rev) | B23: 0.216 | C23: 0.2 | D23: 0.2 | E23: 0.22 | F23: =CHOOSE($B$4,C23,D23,E23) -> 0.2
A24: Other current liabilities (% revenue) | B24: 0.255 | C24: 0.25 | D24: 0.25 | E24: 0.26 | F24: =CHOOSE($B$4,C24,D24,E24) -> 0.25
A25: Implied FY2026E Adj. EBITDA ≈ $7.0B (guidance $6.8–7.0B); terminal Adj. EBITDA margin: Base 32.5%, Bull 36%, Bear 28%.
A26: Working capital (held constant)
A27: Days sales outstanding (DSO) | B27: 50
A28: Days inventory — fuel & materials (DIO, on COGS) | B28: 26
A29: Days payable outstanding (DPO, on COGS) | B29: 43
A33: Capital & shareholder returns
A34: Interest earned on cash | B34: 0.035
A35: Revolver interest rate | B35: 0.065
A36: Minimum cash balance ($mm) | B36: 500
A37: Diluted shares outstanding (mm) | B37: 337.2
A38: Marginal tax rate (valuation) | B38: 0.23
A39: Average rate on existing debt (FY25 interest / debt) | B39: 0.058
A40: Common + preferred dividends, FY2026 ($mm) | B40: 520
A41: Dividend growth per year | B41: 0.05
A42: Share buybacks per year ($mm) | B42: 1100 | C42: FY24 $1,266mm / FY25 $1,028mm actual; share count held constant for simplicity — buybacks modeled as cash + equity reduction
A43: Preferred stock outstanding ($mm) | B43: 2000
A45: Terminal value & market inputs
A46: Terminal (perpetuity) growth rate g | B46: 0.025
A47: Exit EV / Adj. EBITDA multiple (FY2035) | B47: 10
...

Sheet Historicals
A1: HISTORICAL FINANCIALS ($mm; GAAP per SEC-mapped Alpha Vantage data)
B4: FY2021A | C4: FY2022A | D4: FY2023A | E4: FY2024A | F4: FY2025A | H4: Q1-26A | I4: FY2026E
A5: Revenue | B5: 13333 | C5: 17837 | D5: 15543 | E5: 19377 | F5: 16972 | H5: 4654 | I5: 23272 | J5: FY2026E = analyst consensus revenue (13 analysts, Alpha Vantage)
A6: Gross profit | B6: 60 | C6: 3814 | D6: 5171 | E6: 7693 | F6: 2974 | H6: 943
A7: Operating income | B7: -988 | C7: 2638 | D7: 3913 | E7: 6228 | F7: 1335 | H7: 527
A8: Net income | B8: -1274 | C8: -1227 | D8: 1493 | E8: 2659 | F8: 944 | H8: 159
A9: EBITDA (GAAP, incl. MTM) | B9: 852 | C9: 1287 | D9: 4616 | E9: 7192 | F9: 5252
A10: Operating cash flow | E10: 4563 | F10: 4070 | H10: 1199
A11: Capex | E11: 2078 | F11: 3941 | H11: 883
A12: Dividends paid | E12: 478 | F12: 498 | H12: 98
A13: Share buybacks | E13: 1266 | F13: 1028 | H13: 372
A15: Adjusted EBITDA (company measure, ongoing ops) e | D15: 4140 | E15: 5656 | F15: 5902 | I15: 6900
A16: Consensus adj. EPS | I16: 9.95
A17: FY2027E consensus: revenue / adj. EPS | I17: 25271 | J17: FY2027E adj. EPS consensus $11.28
A19: Balance sheet (FY2025A):
A20: Cash | B20: 816
A21: Receivables | B21: 2323
A22: Inventory | B22: 1016
A23: Other current assets | B23: 5024
A24: PP&E net | B24: 18514
A25: Goodwill+intangibles+nuclear trust+other LT | B25: 13857
A26: Accounts payable | B26: 1644
A27: Other current liabilities | B27: 5927
A28: Total debt | B28: 20395
A29: Other LT liabilities | B29: 8474
A30: Total equity | B30: 5110
A32: GAAP revenue/margins swing with non-cash commodity mark-to-market (FY2025 GAAP gross profit $2,974mm vs FY2024 $7,693mm is hedge MTM, not operations). Adjusted EBITDA is the planning metric.
A33: Adjusted EBITDA rows marked 'e': company-reported ongoing-operations adjusted EBITDA (FY25 within $5.7–5.9B raised guidance incl. nuclear PTC); FY2026E = guidance midpoint ~$6.9B.
A34: Q1-2026: revenue $4,654mm, GAAP net income $159mm, OCF $1,199mm, capex $883mm; cash $671mm, total debt $19,913mm, equity $5,597mm.
A35: Source: Alpha Vantage SEC-mapped statements (annual 2021-2025, Q1-2026), pulled 7/20/2026.

Sheet Model_3S
A1: 3-STATEMENT OPERATING MODEL — FY2026E–FY2035E ($mm)
A2: =CONCATENATE("Active scenario: ",CHOOSE(Assumptions!$B$4,"BASE","BULL","BEAR")) -> Active scenario: BASE
B4: FY2025A | C4: FY2026E | D4: FY2027E | E4: FY2028E | F4: FY2029E | G4: FY2030E | H4: FY2031E | I4: FY2032E | J4: FY2033E | K4: FY2034E | L4: FY2035E
A6: DRIVERS (linked to Assumptions; linear ramps FY26 → FY35)
A7: Revenue growth % | C7: =C18/B18-1 -> 0.37119962 | D7: =Assumptions!$E$12+(Assumptions!$E$13-Assumptions!$E$12)*0/8 -> 0.086 | E7: =Assumptions!$E$12+(Assumptions!$E$13-Assumptions!$E$12)*1/8 -> 0.078375 | F7: =Assumptions!$E$12+(Assumptions!$E$13-Assumptions!$E$12)*2/8 -> 0.07075 | G7: =Assumptions!$E$12+(Assumptions!$E$13-Assumptions!$E$12)*3/8 -> 0.063125 | H7: =Assumptions!$E$12+(Assumptions!$E$13-Assumptions!$E$12)*4/8 -> 0.0555 | I7: =Assumptions!$E$12+(Assumptions!$E$13-Assumptions!$E$12)*5/8 -> 0.047875 | J7: =Assumptions!$E$12+(Assumptions!$E$13-Assumptions!$E$12)*6/8 -> 0.04025 | K7: =Assumptions!$E$12+(Assumptions!$E$13-Assumptions!$E$12)*7/8 -> 0.032625 | L7: =Assumptions!$E$12+(Assumptions!$E$13-Assumptions!$E$12)*8/8 -> 0.025
A8: Gross margin % | C8: =Assumptions!$B$17 -> 0.375 | D8: =Assumptions!$B$17+(Assumptions!$F$17-Assumptions!$B$17)*1/9 -> 0.37666667 | E8: =Assumptions!$B$17+(Assumptions!$F$17-Assumptions!$B$17)*2/9 -> 0.37833333 | F8: =Assumptions!$B$17+(Assumptions!$F$17-Assumptions!$B$17)*3/9 -> 0.38 | G8: =Assumptions!$B$17+(Assumptions!$F$17-Assumptions!$B$17)*4/9 -> 0.38166667 | H8: =Assumptions!$B$17+(Assumptions!$F$17-Assumptions!$B$17)*5/9 -> 0.38333333 | I8: =Assumptions!$B$17+(Assumptions!$F$17-Assumptions!$B$17)*6/9 -> 0.385 | J8: =Assumptions!$B$17+(Assumptions!$F$17-Assumptions!$B$17)*7/9 -> 0.38666667 | K8: =Assumptions!$B$17+(Assumptions!$F$17-Assumptions!$B$17)*8/9 -> 0.38833333 | L8: =Assumptions!$B$17+(Assumptions!$F$17-Assumptions!$B$17)*9/9 -> 0.39
A9: SG&A % rev | C9: =Assumptions!$B$18 -> 0.072 | D9: =Assumptions!$B$18+(Assumptions!$F$18-Assumptions!$B$18)*1/9 -> 0.071222222 | E9: =Assumptions!$B$18+(Assumptions!$F$18-Assumptions!$B$18)*2/9 -> 0.070444444 | F9: =Assumptions!$B$18+(Assumptions!$F$18-Assumptions!$B$18)*3/9 -> 0.069666667 | G9: =Assumptions!$B$18+(Assumptions!$F$18-Assumptions!$B$18)*4/9 -> 0.068888889 | H9: =Assumptions!$B$18+(Assumptions!$F$18-Assumptions!$B$18)*5/9 -> 0.068111111 | I9: =Assumptions!$B$18+(Assumptions!$F$18-Assumptions!$B$18)*6/9 -> 0.067333333 | J9: =Assumptions!$B$18+(Assumptions!$F$18-Assumptions!$B$18)*7/9 -> 0.066555556 | K9: =Assumptions!$B$18+(Assumptions!$F$18-Assumptions!$B$18)*8/9 -> 0.065777778 | L9: =Assumptions!$B$18+(Assumptions!$F$18-Assumptions!$B$18)*9/9 -> 0.065
A10: SBC % rev | C10: =Assumptions!$B$19 -> 0.005 | D10: =Assumptions!$B$19+(Assumptions!$F$19-Assumptions!$B$19)*1/9 -> 0.005 | E10: =Assumptions!$B$19+(Assumptions!$F$19-Assumptions!$B$19)*2/9 -> 0.005 | F10: =Assumptions!$B$19+(Assumptions!$F$19-Assumptions!$B$19)*3/9 -> 0.005 | G10: =Assumptions!$B$19+(Assumptions!$F$19-Assumptions!$B$19)*4/9 -> 0.005 | H10: =Assumptions!$B$19+(Assumptions!$F$19-Assumptions!$B$19)*5/9 -> 0.005 | I10: =Assumptions!$B$19+(Assumptions!$F$19-Assumptions!$B$19)*6/9 -> 0.005 | J10: =Assumptions!$B$19+(Assumptions!$F$19-Assumptions!$B$19)*7/9 -> 0.005 | K10: =Assumptions!$B$19+(Assumptions!$F$19-Assumptions!$B$19)*8/9 -> 0.005 | L10: =Assumptions!$B$19+(Assumptions!$F$19-Assumptions!$B$19)*9/9 -> 0.005
A11: D&A % rev | C11: =Assumptions!$B$20 -> 0.127 | D11: =Assumptions!$B$20+(Assumptions!$F$20-Assumptions!$B$20)*1/9 -> 0.12566667 | E11: =Assumptions!$B$20+(Assumptions!$F$20-Assumptions!$B$20)*2/9 -> 0.12433333 | F11: =Assumptions!$B$20+(Assumptions!$F$20-Assumptions!$B$20)*3/9 -> 0.123 | G11: =Assumptions!$B$20+(Assumptions!$F$20-Assumptions!$B$20)*4/9 -> 0.12166667 | H11: =Assumptions!$B$20+(Assumptions!$F$20-Assumptions!$B$20)*5/9 -> 0.12033333 | I11: =Assumptions!$B$20+(Assumptions!$F$20-Assumptions!$B$20)*6/9 -> 0.119 | J11: =Assumptions!$B$20+(Assumptions!$F$20-Assumptions!$B$20)*7/9 -> 0.11766667 | K11: =Assumptions!$B$20+(Assumptions!$F$20-Assumptions!$B$20)*8/9 -> 0.11633333 | L11: =Assumptions!$B$20+(Assumptions!$F$20-Assumptions!$B$20)*9/9 -> 0.115
A12: Capex % rev | C12: =Assumptions!$B$21 -> 0.17 | D12: =Assumptions!$B$21+(Assumptions!$F$21-Assumptions!$B$21)*1/9 -> 0.16333333 | E12: =Assumptions!$B$21+(Assumptions!$F$21-Assumptions!$B$21)*2/9 -> 0.15666667 | F12: =Assumptions!$B$21+(Assumptions!$F$21-Assumptions!$B$21)*3/9 -> 0.15 | G12: =Assumptions!$B$21+(Assumptions!$F$21-Assumptions!$B$21)*4/9 -> 0.14333333 | H12: =Assumptions!$B$21+(Assumptions!$F$21-Assumptions!$B$21)*5/9 -> 0.13666667 | I12: =Assumptions!$B$21+(Assumptions!$F$21-Assumptions!$B$21)*6/9 -> 0.13 | J12: =Assumptions!$B$21+(Assumptions!$F$21-Assumptions!$B$21)*7/9 -> 0.12333333 | K12: =Assumptions!$B$21+(Assumptions!$F$21-Assumptions!$B$21)*8/9 -> 0.11666667 | L12: =Assumptions!$B$21+(Assumptions!$F$21-Assumptions!$B$21)*9/9 -> 0.11
A13: Cash tax rate % | C13: =Assumptions!$B$22 -> 0.21 | D13: =Assumptions!$B$22+(Assumptions!$F$22-Assumptions!$B$22)*1/9 -> 0.21222222 | E13: =Assumptions!$B$22+(Assumptions!$F$22-Assumptions!$B$22)*2/9 -> 0.21444444 | F13: =Assumptions!$B$22+(Assumptions!$F$22-Assumptions!$B$22)*3/9 -> 0.21666667 | G13: =Assumptions!$B$22+(Assumptions!$F$22-Assumptions!$B$22)*4/9 -> 0.21888889 | H13: =Assumptions!$B$22+(Assumptions!$F$22-Assumptions!$B$22)*5/9 -> 0.22111111 | I13: =Assumptions!$B$22+(Assumptions!$F$22-Assumptions!$B$22)*6/9 -> 0.22333333 | J13: =Assumptions!$B$22+(Assumptions!$F$22-Assumptions!$B$22)*7/9 -> 0.22555556 | K13: =Assumptions!$B$22+(Assumptions!$F$22-Assumptions!$B$22)*8/9 -> 0.22777778 | L13: =Assumptions!$B$22+(Assumptions!$F$22-Assumptions!$B$22)*9/9 -> 0.23
A14: Other current assets % rev | C14: =Assumptions!$B$23 -> 0.216 | D14: =Assumptions!$B$23+(Assumptions!$F$23-Assumptions!$B$23)*1/9 -> 0.21422222 | E14: =Assumptions!$B$23+(Assumptions!$F$23-Assumptions!$B$23)*2/9 -> 0.21244444 | F14: =Assumptions!$B$23+(Assumptions!$F$23-Assumptions!$B$23)*3/9 -> 0.21066667 | G14: =Assumptions!$B$23+(Assumptions!$F$23-Assumptions!$B$23)*4/9 -> 0.20888889 | H14: =Assumptions!$B$23+(Assumptions!$F$23-Assumptions!$B$23)*5/9 -> 0.20711111 | I14: =Assumptions!$B$23+(Assumptions!$F$23-Assumptions!$B$23)*6/9 -> 0.20533333 | J14: =Assumptions!$B$23+(Assumptions!$F$23-Assumptions!$B$23)*7/9 -> 0.20355556 | K14: =Assumptions!$B$23+(Assumptions!$F$23-Assumptions!$B$23)*8/9 -> 0.20177778 | L14: =Assumptions!$B$23+(Assumptions!$F$23-Assumptions!$B$23)*9/9 -> 0.2
A15: Other current liab % rev | C15: =Assumptions!$B$24 -> 0.255 | D15: =Assumptions!$B$24+(Assumptions!$F$24-Assumptions!$B$24)*1/9 -> 0.25444444 | E15: =Assumptions!$B$24+(Assumptions!$F$24-Assumptions!$B$24)*2/9 -> 0.25388889 | F15: =Assumptions!$B$24+(Assumptions!$F$24-Assumptions!$B$24)*3/9 -> 0.25333333 | G15: =Assumptions!$B$24+(Assumptions!$F$24-Assumptions!$B$24)*4/9 -> 0.25277778 | H15: =Assumptions!$B$24+(Assumptions!$F$24-Assumptions!$B$24)*5/9 -> 0.25222222 | I15: =Assumptions!$B$24+(Assumptions!$F$24-Assumptions!$B$24)*6/9 -> 0.25166667 | J15: =Assumptions!$B$24+(Assumptions!$F$24-Assumptions!$B$24)*7/9 -> 0.25111111 | K15: =Assumptions!$B$24+(Assumptions!$F$24-Assumptions!$B$24)*8/9 -> 0.25055556 | L15: =Assumptions!$B$24+(Assumptions!$F$24-Assumptions!$B$24)*9/9 -> 0.25
A17: INCOME STATEMENT
A18: Revenue | B18: =Historicals!F5 -> 16972 | C18: =Historicals!I5 -> 23272 | D18: =C18*(1+D7) -> 25273.392 | E18: =D18*(1+E7) -> 27254.194 | F18: =E18*(1+F7) -> 29182.428 | G18: =F18*(1+G7) -> 31024.569 | H18: =G18*(1+H7) -> 32746.433 | I18: =H18*(1+I7) -> 34314.168 | J18: =I18*(1+J7) -> 35695.313 | K18: =J18*(1+K7) -> 36859.873 | L18: =K18*(1+L7) -> 37781.37
A19: Cost of revenue — fuel & purchased power (excl. D&A) | C19: =-C18*(1-C8) -> -14545 | D19: =-D18*(1-D8) -> -15753.748 | E19: =-E18*(1-E8) -> -16943.024 | F19: =-F18*(1-F8) -> -18093.106 | G19: =-G18*(1-G8) -> -19183.525 | H19: =-H18*(1-H8) -> -20193.634 | I19: =-I18*(1-I8) -> -21103.213 | J19: =-J18*(1-J8) -> -21893.126 | ... L19: =-L18*(1-L8) -> -23046.636
A20: Gross (energy) margin | C20: =C18+C19 -> 8727 | D20: =D18+D19 -> 9519.6443 | E20: =E18+E19 -> 10311.17 | F20: =F18+F19 -> 11089.323 | G20: =G18+G19 -> 11841.044 | H20: =H18+H19 -> 12552.799 | I20: =I18+I19 -> 13210.955 | J20: =J18+J19 -> 13802.188 | ... L20: =L18+L19 -> 14734.734
A21: SG&A / other operating costs | C21: =-C18*C9 -> -1675.584 | D21: =-D18*D9 -> -1800.0271 | E21: =-E18*E9 -> -1919.9066 | F21: =-F18*F9 -> -2033.0425 | G21: =-G18*G9 -> -2137.2481 | H21: =-H18*H9 -> -2230.3959 | I21: =-I18*I9 -> -2310.4873 | J21: =-J18*J9 -> -2375.7214 | ... L21: =-L18*L9 -> -2455.789
A22: Adjusted EBITDA | C22: =C20+C21 -> 7051.416 | D22: =D20+D21 -> 7719.6172 | E22: =E20+E21 -> 8391.2635 | F22: =F20+F21 -> 9056.2803 | G22: =G20+G21 -> 9703.7958 | H22: =H20+H21 -> 10322.403 | I22: =I20+I21 -> 10900.467 | J22: =J20+J21 -> 11426.466 | ... L22: =L20+L21 -> 12278.945
A23: Stock-based compensation | C23: =-C18*C10 -> -116.36 | D23: =-D18*D10 -> -126.36696 | E23: =-E18*E10 -> -136.27097 | F23: =-F18*F10 -> -145.91214 | G23: =-G18*G10 -> -155.12285 | H23: =-H18*H10 -> -163.73216 | I23: =-I18*I10 -> -171.57084 | J23: =-J18*J10 -> -178.47657 | ... L23: =-L18*L10 -> -188.90685
A24: D&A incl. nuclear fuel amort. | C24: =-C18*C11 -> -2955.544 | D24: =-D18*D11 -> -3176.0229 | E24: =-E18*E11 -> -3388.6048 | F24: =-F18*F11 -> -3589.4387 | G24: =-G18*G11 -> -3774.6559 | H24: =-H18*H11 -> -3940.4874 | I24: =-I18*I11 -> -4083.386 | J24: =-J18*J11 -> -4200.1485 | ... L24: =-L18*L11 -> -4344.8575
A25: EBIT | C25: =C22+C23+C24 -> 3979.512 | D25: =D22+D23+D24 -> 4417.2273 | E25: =E22+E23+E24 -> 4866.3878 | F25: =F22+F23+F24 -> 5320.9294 | G25: =G22+G23+G24 -> 5774.017 | H25: =H22+H23+H24 -> 6218.1837 | I25: =I22+I23+I24 -> 6645.5106 | J25: =J22+J23+J24 -> 7047.8413 | ... L25: =L22+L23+L24 -> 7745.1808
A26: Interest income (on beginning cash) | C26: =B70*Assumptions!$B$34 -> 28.56 | D26: =C70*Assumptions!$B$34 -> 17.5 | E26: =D70*Assumptions!$B$34 -> 17.5 | F26: =E70*Assumptions!$B$34 -> 17.5 | G26: =F70*Assumptions!$B$34 -> 28.355824 | H26: =G70*Assumptions!$B$34 -> 72.950371 | I26: =H70*Assumptions!$B$34 -> 134.92539 | J26: =I70*Assumptions!$B$34 -> 214.89845 | ... L26: =K70*Assumptions!$B$34 -> 429.77155
A27: Interest expense (beginning debt balances) | C27: =-(B50*Assumptions!$B$39+B54*Assumptions!$B$35) -> -1182.91 | D27: =-(C50*Assumptions!$B$39+C54*Assumptions!$B$35) -> -1232.7882 | E27: =-(D50*Assumptions!$B$39+D54*Assumptions!$B$35) -> -1236.5649 | F27: =-(E50*Assumptions!$B$39+E54*Assumptions!$B$35) -> -1214.2076 | G27: =-(F50*Assumptions!$B$39+F54*Assumptions!$B$35) -> -1182.91 | H27: =-(G50*Assumptions!$B$39+G54*Assumptions!$B$35) -> -1182.91 | I27: =-(H50*Assumptions!$B$39+H54*Assumptions!$B$35) -> -1182.91 | J27: =-(I50*Assumptions!$B$39+I54*Assumptions!$B$35) -> -1182.91 | ... L27: =-(K50*Assumptions!$B$39+K54*Assumptions!$B$35) -> -1182.91
A28: Pre-tax income | C28: =C25+C26+C27 -> 2825.162 | D28: =D25+D26+D27 -> 3201.9391 | E28: =E25+E26+E27 -> 3647.3229 | F28: =F25+F26+F27 -> 4124.2218 | G28: =G25+G26+G27 -> 4619.4629 | H28: =H25+H26+H27 -> 5108.2241 | I28: =I25+I26+I27 -> 5597.526 | J28: =J25+J26+J27 -> 6079.8298 | ... L28: =L25+L26+L27 -> 6992.0424
A29: Taxes | C29: =-MAX(0,C28)*C13 -> -593.28402 | D29: =-MAX(0,D28)*D13 -> -679.52263 | E29: =-MAX(0,E28)*E13 -> -782.14814 | F29: =-MAX(0,F28)*F13 -> -893.5814 | G29: =-MAX(0,G28)*G13 -> -1011.1491 | H29: =-MAX(0,H28)*H13 -> -1129.4851 | I29: =-MAX(0,I28)*I13 -> -1250.1141 | J29: =-MAX(0,J28)*J13 -> -1371.3394 | ... L29: =-MAX(0,L28)*L13 -> -1608.1697
A30: Net income (GAAP-normalized, ex-MTM) | C30: =C28+C29 -> 2231.878 | D30: =D28+D29 -> 2522.4165 | E30: =E28+E29 -> 2865.1748 | F30: =F28+F29 -> 3230.6404 | G30: =G28+G29 -> 3608.3138 | H30: =H28+H29 -> 3978.739 | I30: =I28+I29 -> 4347.4118 | J30: =J28+J29 -> 4708.4904 | ... L30: =L28+L29 -> 5383.8726
A31: EPS (constant share count; adj-EPS consensus is higher) | C31: =C30/Assumptions!$B$37 -> 6.6188552 | D31: =D30/Assumptions!$B$37 -> 7.4804759 | E31: =E30/Assumptions!$B$37 -> 8.4969596 | F31: =F30/Assumptions!$B$37 -> 9.5807842 | G31: =G30/Assumptions!$B$37 -> 10.700812 | H31: =H30/Assumptions!$B$37 -> 11.799345 | I31: =I30/Assumptions!$B$37 -> 12.89268 | J31: =J30/Assumptions!$B$37 -> 13.963495 | ... L31: =L30/Assumptions!$B$37 -> 15.966408
A32: Adj. EBITDA margin % | C32: =C22/C18 -> 0.303 | D32: =D22/D18 -> 0.30544444 | E32: =E22/E18 -> 0.30788889 | F32: =F22/F18 -> 0.31033333 | G32: =G22/G18 -> 0.31277778 | H32: =H22/H18 -> 0.31522222 | I32: =I22/I18 -> 0.31766667 | J32: =J22/J18 -> 0.32011111 | ... L32: =L22/L18 -> 0.325
A34: WORKING CAPITAL
A35: Accounts receivable | B35: 2323 | C35: =C18*Assumptions!$B$27/365 -> 3187.9452 | D35: =D18*Assumptions!$B$27/365 -> 3462.1085 | E35: =E18*Assumptions!$B$27/365 -> 3733.4512 | F35: =F18*Assumptions!$B$27/365 -> 3997.5929 | G35: =G18*Assumptions!$B$27/365 -> 4249.941 | H35: =H18*Assumptions!$B$27/365 -> 4485.8127 | I35: =I18*Assumptions!$B$27/365 -> 4700.571 | J35: =J18*Assumptions!$B$27/365 -> 4889.769 | ... L35: =L18*Assumptions!$B$27/365 -> 5175.5301
A36: Fuel & materials inventory | B36: 1016 | C36: =-C19*Assumptions!$B$28/365 -> 1036.0822 | D36: =-D19*Assumptions!$B$28/365 -> 1122.1848 | E36: =-E19*Assumptions!$B$28/365 -> 1206.9003 | F36: =-F19*Assumptions!$B$28/365 -> 1288.824 | G36: =-G19*Assumptions!$B$28/365 -> 1366.4977 | H36: =-H19*Assumptions!$B$28/365 -> 1438.4506 | I36: =-I19*Assumptions!$B$28/365 -> 1503.2426 | J36: =-J19*Assumptions!$B$28/365 -> 1559.5103 | ... L36: =-L19*Assumptions!$B$28/365 -> 1641.6782
A37: Other current assets (margin deposits, derivatives) | B37: 5024 | C37: =C18*C14 -> 5026.752 | D37: =D18*D14 -> 5414.1222 | E37: =E18*E14 -> 5790.0021 | F37: =F18*F14 -> 6147.7649 | G37: =G18*G14 -> 6480.6878 | H37: =H18*H14 -> 6782.1501 | I37: =I18*I14 -> 7045.8425 | J37: =J18*J14 -> 7265.9794 | ... L37: =L18*L14 -> 7556.274
A38: Accounts payable | B38: -1644 | C38: =C19*Assumptions!$B$29/365 -> -1713.5205 | D38: =D19*Assumptions!$B$29/365 -> -1855.921 | E38: =E19*Assumptions!$B$29/365 -> -1996.0275 | F38: =F19*Assumptions!$B$29/365 -> -2131.5165 | G38: =G19*Assumptions!$B$29/365 -> -2259.9769 | H38: =H19*Assumptions!$B$29/365 -> -2378.976 | I38: =I19*Assumptions!$B$29/365 -> -2486.132 | J38: =J19*Assumptions!$B$29/365 -> -2579.1901 | ... L38: =L19*Assumptions!$B$29/365 -> -2715.0831
A39: Other current liabilities | B39: -5927 | C39: =-C18*C15 -> -5934.36 | D39: =-D18*D15 -> -6430.6742 | E39: =-E18*E15 -> -6919.5371 | F39: =-F18*F15 -> -7392.8818 | G39: =-G18*G15 -> -7842.3216 | H39: =-H18*H15 -> -8259.378 | I39: =-I18*I15 -> -8635.7323 | J39: =-J18*J15 -> -8963.4898 | ... L39: =-L18*L15 -> -9445.3425
A40: Net working capital | B40: =SUM(B35:B39) -> 792 | C40: =SUM(C35:C39) -> 1602.8988 | D40: =SUM(D35:D39) -> 1711.8203 | E40: =SUM(E35:E39) -> 1814.7892 | F40: =SUM(F35:F39) -> 1909.7834 | G40: =SUM(G35:G39) -> 1994.8279 | H40: =SUM(H35:H39) -> 2068.0593 | I40: =SUM(I35:I39) -> 2127.7918 | ... L40: =SUM(L35:L39) -> 2213.0567
A41: (Increase) / decrease in NWC — cash impact | C41: =-(C40-B40) -> -810.89885 | D41: =-(D40-C40) -> -108.92146 | E41: =-(E40-D40) -> -102.96886 | F41: =-(F40-E40) -> -94.994224 | G41: =-(G40-F40) -> -85.044459 | H41: =-(H40-G40) -> -73.231488 | I41: =-(I40-H40) -> -59.732459 | J41: =-(J40-I40) -> -44.786884 | ... L41: =-(L40-K40) -> -11.787305
A43: CAPEX & PP&E
A44: Capex | C44: =C18*C12 -> 3956.24 | D44: =D18*D12 -> 4127.9874 | E44: =E18*E12 -> 4269.8237 | F44: =F18*F12 -> 4377.3642 | G44: =G18*G12 -> 4446.8549 | H44: =H18*H12 -> 4475.3458 | I44: =I18*I12 -> 4460.8419 | J44: =J18*J12 -> 4402.422 | ... L44: =L18*L12 -> 4155.9507
A45: PP&E, net | B45: 18514 | C45: =B45+C44+C24 -> 19514.696 | D45: =C45+D44+D24 -> 20466.66 | E45: =D45+E44+E24 -> 21347.879 | F45: =E45+F44+F24 -> 22135.805 | G45: =F45+G44+G24 -> 22808.004 | H45: =G45+H44+H24 -> 23342.862 | I45: =H45+I44+I24 -> 23720.318 | J45: =I45+J44+J24 -> 23922.592 | ... L45: =K45+L44+L24 -> 23745.971
...

Sheet WACC
A1: WEIGHTED AVERAGE COST OF CAPITAL — CURRENT MARKET DATA (JULY 2026)
A4: COST OF EQUITY (CAPM)
A5: Risk-free rate — 10Y UST, 7/17/2026 | B5: 0.0455 | C5: tradingeconomics.com / FRED DGS10
A6: Levered beta | B6: 1.409 | C6: Alpha Vantage COMPANY_OVERVIEW (VST), 7/17/2026
A7: Equity risk premium | B7: 0.0475 | C7: Damodaran implied ERP, mid-2026
A8: Company-specific premium | B8: 0 | C8: Optional adder (commodity & regulatory risk already in beta)
A9: Cost of equity | B9: =B5+B6*B7+B8 -> 0.1124275
A11: COST OF DEBT
A12: Pre-tax cost of debt | B12: 0.058 | C12: FY2025 interest expense $1,179mm / avg total debt ~$20.4B
A13: Tax rate | B13: =Assumptions!B38 -> 0.23
A14: After-tax cost of debt | B14: =B12*(1-B13) -> 0.04466
A16: CAPITAL STRUCTURE (market weights)
A17: Debt + preferred / total capitalization | B17: 0.3 | C17: Net debt ~$19.6B + $2.0B preferred vs. $52.4B market cap
A18: Equity / total capitalization | B18: =1-B17 -> 0.7
A20: WACC | B20: =B18*B9+B17*B14 -> 0.09209725
A22: Cost of equity ≈ 11.2%; WACC ≈ 9.2–9.5%. Sensitivity range in DCF tables: 8.4% – 10.4%.

Sheet DCF
A1: DISCOUNTED CASH FLOW — UNLEVERED FCF ($mm; valuation as of FY2026 year-end, mid-year convention)
B4: FY2027E | C4: FY2028E | D4: FY2029E | E4: FY2030E | F4: FY2031E | G4: FY2032E | H4: FY2033E | I4: FY2034E | J4: FY2035E
A5: EBIT | B5: =Model_3S!D25 -> 4417.2273 | C5: =Model_3S!E25 -> 4866.3878 | D5: =Model_3S!F25 -> 5320.9294 | E5: =Model_3S!G25 -> 5774.017 | F5: =Model_3S!H25 -> 6218.1837 | G5: =Model_3S!I25 -> 6645.5106 | H5: =Model_3S!J25 -> 7047.8413 | I5: =Model_3S!K25 -> 7417.0256 | J5: =Model_3S!L25 -> 7745.1808
A6: Cash taxes on EBIT | B6: =-MAX(0,B5)*Model_3S!D13 -> -937.43379 | C6: =-MAX(0,C5)*Model_3S!E13 -> -1043.5698 | D6: =-MAX(0,D5)*Model_3S!F13 -> -1152.868 | E6: =-MAX(0,E5)*Model_3S!G13 -> -1263.8682 | F6: =-MAX(0,F5)*Model_3S!H13 -> -1374.9095 | G6: =-MAX(0,G5)*Model_3S!I13 -> -1484.164 | H6: =-MAX(0,H5)*Model_3S!J13 -> -1589.6798 | I6: =-MAX(0,I5)*Model_3S!K13 -> -1689.4336 | J6: =-MAX(0,J5)*Model_3S!L13 -> -1781.3916
A7: + D&A | B7: =-Model_3S!D24 -> 3176.0229 | C7: =-Model_3S!E24 -> 3388.6048 | D7: =-Model_3S!F24 -> 3589.4387 | E7: =-Model_3S!G24 -> 3774.6559 | F7: =-Model_3S!H24 -> 3940.4874 | G7: =-Model_3S!I24 -> 4083.386 | H7: =-Model_3S!J24 -> 4200.1485 | I7: =-Model_3S!K24 -> 4288.0319 | J7: =-Model_3S!L24 -> 4344.8575
A8: − Capex | B8: =-Model_3S!D44 -> -4127.9874 | C8: =-Model_3S!E44 -> -4269.8237 | D8: =-Model_3S!F44 -> -4377.3642 | E8: =-Model_3S!G44 -> -4446.8549 | F8: =-Model_3S!H44 -> -4475.3458 | G8: =-Model_3S!I44 -> -4460.8419 | H8: =-Model_3S!J44 -> -4402.422 | I8: =-Model_3S!K44 -> -4300.3185 | J8: =-Model_3S!L44 -> -4155.9507
A9: +/− Change in NWC | B9: =Model_3S!D41 -> -108.92146 | C9: =Model_3S!E41 -> -102.96886 | D9: =Model_3S!F41 -> -94.994224 | E9: =Model_3S!G41 -> -85.044459 | F9: =Model_3S!H41 -> -73.231488 | G9: =Model_3S!I41 -> -59.732459 | H9: =Model_3S!J41 -> -44.786884 | I9: =Model_3S!K41 -> -28.690692 | J9: =Model_3S!L41 -> -11.787305
A10: Unlevered free cash flow | B10: =SUM(B5:B9) -> 2418.9076 | C10: =SUM(C5:C9) -> 2838.6301 | D10: =SUM(D5:D9) -> 3285.1416 | E10: =SUM(E5:E9) -> 3752.9054 | F10: =SUM(F5:F9) -> 4235.1843 | G10: =SUM(G5:G9) -> 4724.1582 | H10: =SUM(H5:H9) -> 5211.1012 | I10: =SUM(I5:I9) -> 5686.6146 | J10: =SUM(J5:J9) -> 6140.9088
A11: Discount period (mid-year) | B11: 0.5 | C11: 1.5 | D11: 2.5 | E11: 3.5 | F11: 4.5 | G11: 5.5 | H11: 6.5 | I11: 7.5 | J11: 8.5
A12: Discount factor @ WACC | B12: =(1+$B$16)^-B11 -> 0.95690614 | C12: =(1+$B$16)^-C11 -> 0.87620965 | D12: =(1+$B$16)^-D11 -> 0.80231833 | E12: =(1+$B$16)^-E11 -> 0.73465832 | F12: =(1+$B$16)^-F11 -> 0.67270412 | G12: =(1+$B$16)^-G11 -> 0.61597456 | H12: =(1+$B$16)^-H11 -> 0.56402904 | I12: =(1+$B$16)^-I11 -> 0.51646411 | J12: =(1+$B$16)^-J11 -> 0.47291037
A13: PV of FCF | B13: =B10*B12 -> 2314.6676 | C13: =C10*C12 -> 2487.2351 | D13: =D10*D12 -> 2635.7293 | E13: =E10*E12 -> 2757.1032 | F13: =F10*F12 -> 2849.026 | G13: =G10*G12 -> 2909.9613 | H13: =H10*H12 -> 2939.2124 | I13: =I10*I12 -> 2936.9324 | J13: =J10*J12 -> 2904.0994
A15: Sum of PV of explicit FCF (FY27–35) | B15: =SUM(B13:J13) -> 24733.967
A16: WACC | B16: =WACC!B20 -> 0.09209725
A18: TERMINAL VALUE — METHOD 1: GORDON GROWTH
A19: Terminal growth g | B19: =Assumptions!B46 -> 0.025
A20: Terminal value = FCF35 × (1+g) / (WACC − g) | B20: =J10*(1+B19)/(B16-B19) -> 93810.573
A21: PV of terminal value (9.0 yrs) | B21: =B20/(1+B16)^9 -> 42452.177
A22: Implied exit EV/EBITDA on FY35 Adj. EBITDA | B22: =B20/Model_3S!L22 -> 7.6399537
A24: TERMINAL VALUE — METHOD 2: EXIT MULTIPLE
A25: Exit EV/Adj. EBITDA multiple | B25: =Assumptions!B47 -> 10
A26: Terminal value = multiple × FY35 Adj. EBITDA | B26: =B25*Model_3S!L22 -> 122789.45
A27: PV of terminal value | B27: =B26/(1+B16)^9 -> 55566.013
A28: Implied perpetuity growth from exit TV | B28: =(B16*B26-J10)/(B26+J10) -> 0.040081033
A30: ENTERPRISE → EQUITY VALUE BRIDGE
A31: Net debt, FY2026E year-end (debt − cash) | B31: =Model_3S!C55-Model_3S!C70 -> 20662.357
A32: Preferred stock | B32: =Assumptions!B43 -> 2000
A33: Diluted shares (mm) | B33: =Assumptions!B37 -> 337.2
B34: Gordon growth | C34: Exit multiple | D34: Average
A35: Enterprise value | B35: =B15+B21 -> 67186.144 | C35: =B15+B27 -> 80299.98 | D35: =AVERAGE(B35:C35) -> 73743.062
A36: − Net debt − preferred | B36: =-$B$31-$B$32 -> -22662.357 | C36: =-$B$31-$B$32 -> -22662.357 | D36: =-$B$31-$B$32 -> -22662.357
A37: Equity value | B37: =B35+B36 -> 44523.787 | C37: =C35+C36 -> 57637.623 | D37: =D35+D36 -> 51080.705
A38: Implied value per share | B38: =B37/$B$33 -> 132.0397 | C38: =C37/$B$33 -> 170.93008 | D38: =D37/$B$33 -> 151.48489
A39: Upside / (downside) vs current price | B39: =B38/Assumptions!$B$48-1 -> -0.15054233 | C39: =C38/Assumptions!$B$48-1 -> 0.099653119 | D39: =D38/Assumptions!$B$48-1 -> -0.025444605
A42: SENSITIVITY — VALUE PER SHARE: WACC × TERMINAL GROWTH (Gordon)
B43: WACC \ g | C43: 0.015 | D43: 0.02 | E43: 0.025 | F43: 0.03 | G43: 0.035
B44: 0.084 | C44: =(SUMPRODUCT($B$10:$J$10,(1+$B$44)^-($B$11:$J$11))+$J$10*(1+C$43)/($B$44-C$43)/(1+$B$44)^9-$B$31-$B$32)/$B$33 -> 138.38508 | D44: =(SUMPRODUCT($B$10:$J$10,(1+$B$44)^-($B$11:$J$11))+$J$10*(1+D$43)/($B$44-D$43)/(1+$B$44)^9-$B$31-$B$32)/$B$33 -> 149.20071 | E44: =(SUMPRODUCT($B$10:$J$10,(1+$B$44)^-($B$11:$J$11))+$J$10*(1+E$43)/($B$44-E$43)/(1+$B$44)^9-$B$31-$B$32)/$B$33 -> 161.8495 | F44: =(SUMPRODUCT($B$10:$J$10,(1+$B$44)^-($B$11:$J$11))+$J$10*(1+F$43)/($B$44-F$43)/(1+$B$44)^9-$B$31-$B$32)/$B$33 -> 176.84065 | G44: =(SUMPRODUCT($B$10:$J$10,(1+$B$44)^-($B$11:$J$11))+$J$10*(1+G$43)/($B$44-G$43)/(1+$B$44)^9-$B$31-$B$32)/$B$33 -> 194.89122
B45: 0.089 | C45: =(SUMPRODUCT($B$10:$J$10,(1+$B$45)^-($B$11:$J$11))+$J$10*(1+C$43)/($B$45-C$43)/(1+$B$45)^9-$B$31-$B$32)/$B$33 -> 123.0925 | D45: =(SUMPRODUCT($B$10:$J$10,(1+$B$45)^-($B$11:$J$11))+$J$10*(1+D$43)/($B$45-D$43)/(1+$B$45)^9-$B$31-$B$32)/$B$33 -> 132.10844 | E45: =(SUMPRODUCT($B$10:$J$10,(1+$B$45)^-($B$11:$J$11))+$J$10*(1+E$43)/($B$45-E$43)/(1+$B$45)^9-$B$31-$B$32)/$B$33 -> 142.53313 | F45: =(SUMPRODUCT($B$10:$J$10,(1+$B$45)^-($B$11:$J$11))+$J$10*(1+F$43)/($B$45-F$43)/(1+$B$45)^9-$B$31-$B$32)/$B$33 -> 154.72471 | G45: =(SUMPRODUCT($B$10:$J$10,(1+$B$45)^-($B$11:$J$11))+$J$10*(1+G$43)/($B$45-G$43)/(1+$B$45)^9-$B$31-$B$32)/$B$33 -> 169.17399
B46: 0.094 | C46: =(SUMPRODUCT($B$10:$J$10,(1+$B$46)^-($B$11:$J$11))+$J$10*(1+C$43)/($B$46-C$43)/(1+$B$46)^9-$B$31-$B$32)/$B$33 -> 109.78755 | D46: =(SUMPRODUCT($B$10:$J$10,(1+$B$46)^-($B$11:$J$11))+$J$10*(1+D$43)/($B$46-D$43)/(1+$B$46)^9-$B$31-$B$32)/$B$33 -> 117.37887 | E46: =(SUMPRODUCT($B$10:$J$10,(1+$B$46)^-($B$11:$J$11))+$J$10*(1+E$43)/($B$46-E$43)/(1+$B$46)^9-$B$31-$B$32)/$B$33 -> 126.07039 | F46: =(SUMPRODUCT($B$10:$J$10,(1+$B$46)^-($B$11:$J$11))+$J$10*(1+F$43)/($B$46-F$43)/(1+$B$46)^9-$B$31-$B$32)/$B$33 -> 136.11996 | G46: =(SUMPRODUCT($B$10:$J$10,(1+$B$46)^-($B$11:$J$11))+$J$10*(1+G$43)/($B$46-G$43)/(1+$B$46)^9-$B$31-$B$32)/$B$33 -> 147.87285
B47: 0.099 | C47: =(SUMPRODUCT($B$10:$J$10,(1+$B$47)^-($B$11:$J$11))+$J$10*(1+C$43)/($B$47-C$43)/(1+$B$47)^9-$B$31-$B$32)/$B$33 -> 98.11304 | D47: =(SUMPRODUCT($B$10:$J$10,(1+$B$47)^-($B$11:$J$11))+$J$10*(1+D$43)/($B$47-D$43)/(1+$B$47)^9-$B$31-$B$32)/$B$33 -> 104.56107 | E47: =(SUMPRODUCT($B$10:$J$10,(1+$B$47)^-($B$11:$J$11))+$J$10*(1+E$43)/($B$47-E$43)/(1+$B$47)^9-$B$31-$B$32)/$B$33 -> 111.88046 | F47: =(SUMPRODUCT($B$10:$J$10,(1+$B$47)^-($B$11:$J$11))+$J$10*(1+F$43)/($B$47-F$43)/(1+$B$47)^9-$B$31-$B$32)/$B$33 -> 120.26063 | G47: =(SUMPRODUCT($B$10:$J$10,(1+$B$47)^-($B$11:$J$11))+$J$10*(1+G$43)/($B$47-G$43)/(1+$B$47)^9-$B$31-$B$32)/$B$33 -> 129.9502
B48: 0.104 | C48: =(SUMPRODUCT($B$10:$J$10,(1+$B$48)^-($B$11:$J$11))+$J$10*(1+C$43)/($B$48-C$43)/(1+$B$48)^9-$B$31-$B$32)/$B$33 -> 87.792173 | D48: =(SUMPRODUCT($B$10:$J$10,(1+$B$48)^-($B$11:$J$11))+$J$10*(1+D$43)/($B$48-D$43)/(1+$B$48)^9-$B$31-$B$32)/$B$33 -> 93.31159 | E48: =(SUMPRODUCT($B$10:$J$10,(1+$B$48)^-($B$11:$J$11))+$J$10*(1+E$43)/($B$48-E$43)/(1+$B$48)^9-$B$31-$B$32)/$B$33 -> 99.529667 | F48: =(SUMPRODUCT($B$10:$J$10,(1+$B$48)^-($B$11:$J$11))+$J$10*(1+F$43)/($B$48-F$43)/(1+$B$48)^9-$B$31-$B$32)/$B$33 -> 106.58803 | G48: =(SUMPRODUCT($B$10:$J$10,(1+$B$48)^-($B$11:$J$11))+$J$10*(1+G$43)/($B$48-G$43)/(1+$B$48)^9-$B$31-$B$32)/$B$33 -> 114.66933
...

Sheet Comps
A1: TRADING COMPARABLES — INDEPENDENT POWER PRODUCERS (Alpha Vantage, July 2026)
A4: Company | B4: Ticker | C4: EV/Revenue | D4: EV/EBITDA (LTM) | E4: Beta | F4: Note
A5: Constellation Energy | B5: CEG | C5: 3.74 | D5: 13.58 | E5: 1.12 | F5: Nuclear fleet premium; Calpine deal closed
A6: NRG Energy | B6: NRG | C6: 1.58 | D6: 19.59 | E6: 1.2 | F6: LTM EBITDA depressed by MTM; fwd P/E 13.6x
A7: Talen Energy | B7: TLN | C7: 7.29 | D7: 28.86 | E7: 1.62 | F7: LTM heavily MTM-distorted; AWS nuclear PPA
A8: Vistra (self, for reference) | B8: VST | C8: 3.81 | D8: 11.14 | E8: 1.41 | F8: Current multiples
A9: Peer median (ex-VST) | C9: =MEDIAN(C5:C7) -> 3.74 | D9: =MEDIAN(D5:D7) -> 19.59
A11: LTM GAAP EBITDA multiples are distorted by commodity mark-to-market for the whole sector; the applied bands below are set on a forward adjusted-EBITDA basis (~9–14x, VST currently ~10.6x FY26E guidance).
A13: IMPLIED VALUE PER SHARE
A14: Method | B14: Low x | C14: High x | D14: Metric | E14: $/sh low | F14: $/sh high
A15: EV/Adj. EBITDA × FY2026E ($mm) | B15: 9 | C15: 14 | D15: =Model_3S!C22 -> 7051.416 | E15: =(B15*D15-DCF!$B$31-DCF!$B$32)/Assumptions!$B$37 -> 120.99759 | F15: =(C15*D15-DCF!$B$31-DCF!$B$32)/Assumptions!$B$37 -> 225.55595
A16: P/E × FY2026E consensus adj. EPS | B16: 14 | C16: 20 | D16: =Historicals!I16 -> 9.95 | E16: =B16*D16 -> 139.3 | F16: =C16*D16 -> 199
A18: P/E band: VST fwd P/E 16.9x vs CEG 21.4x, NRG 13.6x, TLN 15.9x (Alpha Vantage forward P/E).

Sheet Precedents
A1: PRECEDENT TRANSACTIONS — US POWER GENERATION M&A
A4: Date | B4: Acquirer | C4: Target | D4: EV ($mm) | E4: EV/EBITDA | F4: Note
A5: Jan-2025 | B5: Constellation Energy | C5: Calpine | D5: 29100 | E5: 7.9 | F5: ~7.9x 2026E EBITDA incl. synergies (announced value $26.6B + debt adj)
A6: Mar-2023 | B6: Vistra | C6: Energy Harbor | D6: 3430 | E6: 6.1 | F6: e — nuclear + retail; multiple estimated on ~$560mm EBITDA
A7: Aug-2017 | B7: Energy Capital Partners | C7: Calpine | D7: 17100 | E7: 7.4 | F7: take-private
A8: Oct-2017 | B8: Vistra | C8: Dynegy | D8: 10700 | E8: 7.5 | F8: e — all-stock merger, pre-synergy
A9: Feb-2007 | B9: KKR / TPG / GS | C9: TXU (Energy Future) | D9: 45000 | E9: 8.5 | F9: e — largest LBO in history; later restructured
A10: May-2025 | B10: LS Power | C10: Talen ERCOT assets | D10: 2600 | E10: 7 | F10: e — gas fleet portfolio deals cluster ~6-8x
A11: Median EV/EBITDA | E11: =MEDIAN(E5:E10) -> 7.45
A13: APPLIED RANGE
A14: Generation M&A has consistently cleared at 6–9x EBITDA — well below today's public trading multiples, which embed data-center growth optionality. A control transaction for VST would likely price between the two.
B15: Low | C15: High
A16: EV/Adj. EBITDA applied to FY2026E | B16: 7 | C16: 9
A17: Implied EV | B17: =B16*Model_3S!C22 -> 49359.912 | C17: =C16*Model_3S!C22 -> 63462.744
A18: Implied value per share | B18: =(B17-DCF!$B$31-DCF!$B$32)/Assumptions!$B$37 -> 79.174244 | C18: =(C17-DCF!$B$31-DCF!$B$32)/Assumptions!$B$37 -> 120.99759

Sheet LBO
A1: LBO ANALYSIS — 5-YEAR HOLD (ENTRY END-FY2026, EXIT END-FY2031) ($mm)
A4: ENTRY & FINANCING
A5: Entry premium to current price | B5: 0.2
A6: Entry price per share | B6: =Assumptions!B48*(1+B5) -> 186.528
A7: Diluted shares (mm) | B7: =Assumptions!B37 -> 337.2
A8: Equity purchase price | B8: =B6*B7 -> 62897.242
A9: Plus: net debt assumed/refinanced + preferred redeemed | B9: =DCF!B31+DCF!B32 -> 22662.357
A10: Entry enterprise value | B10: =B8+B9 -> 85559.598
A11: Transaction fees (% of EV) | B11: 0.02
A12: FY2026E Adj. EBITDA (debt sizing basis) | B12: =Model_3S!C22 -> 7051.416
A13: Entry EV / EBITDA | B13: =B10/B12 -> 12.133676
A14: Debt tranche | B14: Multiple | C14: Rate | D14: Amount
A15: Term Loan B | B15: 4 | C15: 0.08 | D15: =B15*$B$12 -> 28205.664
A16: Secured / unsecured notes | B16: 1.5 | C16: 0.095 | D16: =B16*$B$12 -> 10577.124
A17: Total new debt | B17: =B15+B16 -> 5.5 | D17: =D15+D16 -> 38782.788
A18: Sponsor equity = EV×(1+fees) − debt | B18: =B10*(1+B11)-D17 -> 48488.002
A20: DEBT PAYDOWN — 100% FCF SWEEP
B21: FY2027E | C21: FY2028E | D21: FY2029E | E21: FY2030E | F21: FY2031E
A22: Unlevered FCF (DCF sheet) | B22: =DCF!B10 -> 2418.9076 | C22: =DCF!C10 -> 2838.6301 | D22: =DCF!D10 -> 3285.1416 | E22: =DCF!E10 -> 3752.9054 | F22: =DCF!F10 -> 4235.1843
A23: Cash interest — TLB (beginning balance) | B23: =-$D$15*$C$15 -> -2256.4531 | C23: =-B29*$C$15 -> -2256.4531 | D23: =-C29*$C$15 -> -2230.2576 | E23: =-D29*$C$15 -> -2166.7274 | F23: =-E29*$C$15 -> -2061.8627
A24: Cash interest — notes | B24: =-$D$16*$C$16 -> -1004.8268 | C24: =-$D$16*$C$16 -> -1004.8268 | D24: =-$D$16*$C$16 -> -1004.8268 | E24: =-$D$16*$C$16 -> -1004.8268 | F24: =-$D$16*$C$16 -> -1004.8268
A25: Interest tax shield | B25: =-(B23+B24)*Assumptions!$B$38 -> 750.09438 | C25: =-(C23+C24)*Assumptions!$B$38 -> 750.09438 | D25: =-(D23+D24)*Assumptions!$B$38 -> 744.0694 | E25: =-(E23+E24)*Assumptions!$B$38 -> 729.45747 | F25: =-(F23+F24)*Assumptions!$B$38 -> 705.33859
A26: Levered FCF for paydown | B26: =MAX(0,B22+B23+B24+B25) -> 0 | C26: =MAX(0,C22+C23+C24+C25) -> 327.44462 | D26: =MAX(0,D22+D23+D24+D25) -> 794.12667 | E26: =MAX(0,E22+E23+E24+E25) -> 1310.8087 | F26: =MAX(0,F22+F23+F24+F25) -> 1873.8334
A27: TLB — beginning | B27: =$D$15 -> 28205.664 | C27: =B29 -> 28205.664 | D27: =C29 -> 27878.219 | E27: =D29 -> 27084.093 | F27: =E29 -> 25773.284
A28: TLB — (paydown) | B28: =-MIN(B27,B26) -> 0 | C28: =-MIN(C27,C26) -> -327.44462 | D28: =-MIN(D27,D26) -> -794.12667 | E28: =-MIN(E27,E26) -> -1310.8087 | F28: =-MIN(F27,F26) -> -1873.8334
A29: TLB — ending | B29: =B27+B28 -> 28205.664 | C29: =C27+C28 -> 27878.219 | D29: =D27+D28 -> 27084.093 | E29: =E27+E28 -> 25773.284 | F29: =F27+F28 -> 23899.451
A30: Notes — ending (bullet) | B30: =$D$16 -> 10577.124 | C30: =$D$16 -> 10577.124 | D30: =$D$16 -> 10577.124 | E30: =$D$16 -> 10577.124 | F30: =$D$16 -> 10577.124
A31: Total debt — ending | B31: =B29+B30 -> 38782.788 | C31: =C29+C30 -> 38455.343 | D31: =D29+D30 -> 37661.217 | E31: =E29+E30 -> 36350.408 | F31: =F29+F30 -> 34476.575
A33: EXIT & RETURNS
A34: FY2031E Adj. EBITDA | B34: =Model_3S!H22 -> 10322.403
A35: Exit EV/EBITDA multiple | B35: 10
A36: Exit enterprise value | B36: =B34*B35 -> 103224.03
A37: Less: exit net debt | B37: =-F31 -> -34476.575
A38: Exit equity value | B38: =B36+B37 -> 68747.458
A39: MOIC | B39: =B38/B18 -> 1.4178241
A40: IRR (5-yr) | B40: =(B38/B18)^(1/5)-1 -> 0.072320159
A42: MAXIMUM ENTRY PRICE AT TARGET IRR THRESHOLDS (exit equity constant — debt sized on EBITDA, not price)
A43: Target IRR | B43: Max sponsor equity | C43: Implied entry EV | D43: Implied price/share | E43: Prem/(disc) to market
A44: 0.15 | B44: =$B$38/(1+A44)^5 -> 34179.637 | C44: =(B44+$D$17)/(1+$B$11) -> 71531.789 | D44: =(C44-$B$9)/$B$7 -> 144.92714 | E44: =D44/Assumptions!$B$48-1 -> -0.067632902
A45: 0.2 | B45: =$B$38/(1+A45)^5 -> 27628.062 | C45: =(B45+$D$17)/(1+$B$11) -> 65108.676 | D45: =(C45-$B$9)/$B$7 -> 125.87876 | E45: =D45/Assumptions!$B$48-1 -> -0.19017779
...

Sheet Monte_Carlo
A1: MONTE CARLO SIMULATION — 500 LIVE TRIALS (press F9 / recalc to refresh draws)
A2: Compact DCF per trial calibrated to the DCF sheet at base inputs; equity = PV(TV) + PV(FCF) − net debt − preferred.
A4: Distribution parameters — Normal(mean, σ)
A5: Variable | B5: Mean (linked) | C5: σ (input)
A6: FY2027 revenue growth | B6: =Assumptions!E12 -> 0.086 | C6: 0.03
A7: Terminal Adj. EBITDA margin (FY35) | B7: =Assumptions!F17-Assumptions!F18 -> 0.325 | C7: 0.025
A8: WACC | B8: =WACC!B20 -> 0.09209725 | C8: 0.0075
A9: Exit EV/EBITDA multiple | B9: =Assumptions!B47 -> 10 | C9: 1.5
A11: Calibration statics (linked)
A12: Base FY2035 Adj. EBITDA | B12: =Model_3S!L22 -> 12278.945
A13: Base PV of explicit FCF (DCF) | B13: =DCF!B15 -> 24733.967
A14: Net debt FY2026E | B14: =DCF!B31 -> 20662.357
A15: Diluted shares (mm) | B15: =Assumptions!B37 -> 337.2
A16: Current share price | B16: =Assumptions!B48 -> 155.44
A17: FY2035 growth (selected) | B17: =Assumptions!E13 -> 0.025
A18: FY2026E revenue | B18: =Model_3S!C18 -> 23272
A19: Preferred stock | B19: =DCF!B32 -> 2000
A20: Simulation results ($/share)
A21: Mean | B21: =AVERAGE($K$41:$K$540) -> 169.634
A22: Median | B22: =MEDIAN($K$41:$K$540) -> 167.39462
A23: Standard deviation | B23: =STDEV($K$41:$K$540) -> 45.561616
A24: 5th percentile | B24: =PERCENTILE($K$41:$K$540,0.05) -> 98.113469
A25: 25th percentile | B25: =PERCENTILE($K$41:$K$540,0.25) -> 135.31043
A26: 75th percentile | B26: =PERCENTILE($K$41:$K$540,0.75) -> 200.52867
A27: 95th percentile | B27: =PERCENTILE($K$41:$K$540,0.95) -> 245.57405
A28: P(value > current price) | B28: =COUNTIF($K$41:$K$540,">"&B16)/500 -> 0.582
A30: Scenario probability-weighted value (compact DCF per scenario)
A31: Scenario | B31: Probability | C31: Value / share
A32: Base | B32: =Assumptions!B8 -> 0.5 | C32: =($B$13*($B$18*(1+(Assumptions!B12+Assumptions!B13)/2)^9*(Assumptions!C17-Assumptions!C18))/$B$12+Assumptions!$B$47*($B$18*(1+(Assumptions!B12+Assumptions!B13)/2)^9*(Assumptions!C17-Assumptions!C18))/(1+$B$8)^9-$B$14-$B$19)/$B$15 -> 171.30332
A33: Bull | B33: =Assumptions!C8 -> 0.3 | C33: =($B$13*($B$18*(1+(Assumptions!C12+Assumptions!C13)/2)^9*(Assumptions!D17-Assumptions!D18))/$B$12+Assumptions!$B$47*($B$18*(1+(Assumptions!C12+Assumptions!C13)/2)^9*(Assumptions!D17-Assumptions!D18))/(1+$B$8)^9-$B$14-$B$19)/$B$15 -> 265.80396
A34: Bear | B34: =Assumptions!D8 -> 0.2 | C34: =($B$13*($B$18*(1+(Assumptions!D12+Assumptions!D13)/2)^9*(Assumptions!E17-Assumptions!E18))/$B$12+Assumptions!$B$47*($B$18*(1+(Assumptions!D12+Assumptions!D13)/2)^9*(Assumptions!E17-Assumptions!E18))/(1+$B$8)^9-$B$14-$B$19)/$B$15 -> 74.745204
A35: Probability-weighted value | C35: =SUMPRODUCT(B32:B34,C32:C34) -> 180.34189
A36: Compact approximation; PV-of-FCF scaling calibrated on the active scenario (most accurate with switch = 1/Base).
A39: TRIALS
A40: # | B40: g FY27 | C40: Term margin | D40: WACC | E40: Exit x | F40: Rev FY35 | G40: EBITDA FY35 | H40: PV(TV) | I40: PV(FCF) | J40: Equity | K40: $ / share | N40: Bin ($/sh) | O40: low | P40: high | Q40: Count
A41: 1 | B41: =NORMINV(RAND(),$B$6,$C$6) -> 0.042798954 | C41: =MAX(0.15,NORMINV(RAND(),$B$7,$C$7)) -> 0.29129389 | D41: =MAX(0.06,NORMINV(RAND(),$B$8,$C$8)) -> 0.079268604 | E41: =MAX(5,NORMINV(RAND(),$B$9,$C$9)) -> 8.6007562 | F41: =$B$18*(1+(B41+$B$17)/2)^9 -> 31415.107 | G41: =F41*C41 -> 9151.0289 | H41: =E41*G41/(1+D41)^9 -> 39613.268 | I41: =$B$13*G41/$B$12*((1+$B$8)/(1+D41))^4.5 -> 19439.971 | J41: =H41+I41-$B$14-$B$19 -> 36390.882 | K41: =J41/$B$15 -> 107.92077 | N41: <70 | O41: 60 | P41: 70 | Q41: =COUNTIF($K$41:$K$540,"<"&P41) -> 2
A42: 2 | B42: =NORMINV(RAND(),$B$6,$C$6) -> 0.037691814 | C42: =MAX(0.15,NORMINV(RAND(),$B$7,$C$7)) -> 0.32217545 | D42: =MAX(0.06,NORMINV(RAND(),$B$8,$C$8)) -> 0.085309174 | E42: =MAX(5,NORMINV(RAND(),$B$9,$C$9)) -> 11.079451 | F42: =$B$18*(1+(B42+$B$17)/2)^9 -> 30723.653 | G42: =F42*C42 -> 9898.4069 | H42: =E42*G42/(1+D42)^9 -> 52493.107 | I42: =$B$13*G42/$B$12*((1+$B$8)/(1+D42))^4.5 -> 20506.11 | J42: =H42+I42-$B$14-$B$19 -> 50336.86 | K42: =J42/$B$15 -> 149.27894 | N42: 70-80 | O42: 70 | P42: 80 | Q42: =COUNTIFS($K$41:$K$540,">="&O42,$K$41:$K$540,"<"&P42) -> 3
A43: 3 | B43: =NORMINV(RAND(),$B$6,$C$6) -> 0.098635623 | C43: =MAX(0.15,NORMINV(RAND(),$B$7,$C$7)) -> 0.29545386 | D43: =MAX(0.06,NORMINV(RAND(),$B$8,$C$8)) -> 0.086571782 | E43: =MAX(5,NORMINV(RAND(),$B$9,$C$9)) -> 6.5928786 | F43: =$B$18*(1+(B43+$B$17)/2)^9 -> 39928.571 | G43: =F43*C43 -> 11797.05 | H43: =E43*G43/(1+D43)^9 -> 36840.262 | I43: =$B$13*G43/$B$12*((1+$B$8)/(1+D43))^4.5 -> 24311.914 | J43: =H43+I43-$B$14-$B$19 -> 38489.82 | K43: =J43/$B$15 -> 114.14537 | N43: 80-90 | O43: 80 | P43: 90 | Q43: =COUNTIFS($K$41:$K$540,">="&O43,$K$41:$K$540,"<"&P43) -> 9
A44: 4 | B44: =NORMINV(RAND(),$B$6,$C$6) -> 0.093259401 | C44: =MAX(0.15,NORMINV(RAND(),$B$7,$C$7)) -> 0.27757984 | D44: =MAX(0.06,NORMINV(RAND(),$B$8,$C$8)) -> 0.10125118 | E44: =MAX(5,NORMINV(RAND(),$B$9,$C$9)) -> 7.9119635 | F44: =$B$18*(1+(B44+$B$17)/2)^9 -> 39027.976 | G44: =F44*C44 -> 10833.379 | H44: =E44*G44/(1+D44)^9 -> 35980.794 | I44: =$B$13*G44/$B$12*((1+$B$8)/(1+D44))^4.5 -> 21017.634 | J44: =H44+I44-$B$14-$B$19 -> 34336.072 | K44: =J44/$B$15 -> 101.82702 | N44: 90-100 | O44: 90 | P44: 100 | Q44: =COUNTIFS($K$41:$K$540,">="&O44,$K$41:$K$540,"<"&P44) -> 17
A45: 5 | B45: =NORMINV(RAND(),$B$6,$C$6) -> 0.09040466 | C45: =MAX(0.15,NORMINV(RAND(),$B$7,$C$7)) -> 0.3466497 | D45: =MAX(0.06,NORMINV(RAND(),$B$8,$C$8)) -> 0.094970066 | E45: =MAX(5,NORMINV(RAND(),$B$9,$C$9)) -> 7.4732002 | F45: =$B$18*(1+(B45+$B$17)/2)^9 -> 38557.144 | G45: =F45*C45 -> 13365.822 | H45: =E45*G45/(1+D45)^9 -> 44145.057 | I45: =$B$13*G45/$B$12*((1+$B$8)/(1+D45))^4.5 -> 26606.895 | J45: =H45+I45-$B$14-$B$19 -> 48089.595 | K45: =J45/$B$15 -> 142.61446 | N45: 100-110 | O45: 100 | P45: 110 | Q45: =COUNTIFS($K$41:$K$540,">="&O45,$K$41:$K$540,"<"&P45) -> 17
...

Sheet Football_Field
A1: FOOTBALL FIELD — VALUATION SUMMARY ($ per share)
A2: =CONCATENATE("Current price: $",TEXT(Assumptions!B48,"0.00")," · Scenario: ",CHOOSE(Assumptions!B4,"BASE","BULL","BEAR")," · Probability-weighted value: $",TEXT(Monte_Carlo!C35,"0.00")) -> Current price: $155.44 · Scenario: BASE · Probability-weighted value: $180.34
A4: Methodology | B4: Low | C4: High | D4: (base) | E4: (span) | F4: Midpoint
A5: 52-week trading range | B5: 132.48 | C5: 218.91 | D5: =B5 -> 132.48 | E5: =C5-B5 -> 86.43 | F5: =(B5+C5)/2 -> 175.695
A6: Analyst targets (avg $223, 20 analysts) e | B6: 190 | C6: 255 | D6: =B6 -> 190 | E6: =C6-B6 -> 65 | F6: =(B6+C6)/2 -> 222.5
A7: DCF — Gordon growth (WACC ±0.5%, g 2.0–3.0%) | B7: =(SUMPRODUCT(DCF!$B$10:$J$10,(1+(WACC!$B$20+0.005))^-DCF!$B$11:$J$11)+DCF!$J$10*(1+0.02)/((WACC!$B$20+0.005)-0.02)/(1+(WACC!$B$20+0.005))^9-DCF!$B$31-DCF!$B$32)/DCF!$B$33 -> 109.23737 | C7: =(SUMPRODUCT(DCF!$B$10:$J$10,(1+(WACC!$B$20-0.005))^-DCF!$B$11:$J$11)+DCF!$J$10*(1+0.03)/((WACC!$B$20-0.005)-0.03)/(1+(WACC!$B$20-0.005))^9-DCF!$B$31-DCF!$B$32)/DCF!$B$33 -> 162.67688 | D7: =B7 -> 109.23737 | E7: =C7-B7 -> 53.439515 | F7: =(B7+C7)/2 -> 135.95712
A8: DCF — exit multiple (9–11x, WACC ±0.5%) | B8: =(SUMPRODUCT(DCF!$B$10:$J$10,(1+(WACC!$B$20+0.005))^-DCF!$B$11:$J$11)+9*Model_3S!$L$22/(1+(WACC!$B$20+0.005))^9-DCF!$B$31-DCF!$B$32)/DCF!$B$33 -> 146.93116 | C8: =(SUMPRODUCT(DCF!$B$10:$J$10,(1+(WACC!$B$20-0.005))^-DCF!$B$11:$J$11)+11*Model_3S!$L$22/(1+(WACC!$B$20-0.005))^9-DCF!$B$31-DCF!$B$32)/DCF!$B$33 -> 196.64928 | D8: =B8 -> 146.93116 | E8: =C8-B8 -> 49.718116 | F8: =(B8+C8)/2 -> 171.79022
A9: Trading comps — EV/EBITDA (9–14x FY26E) | B9: =Comps!E15 -> 120.99759 | C9: =Comps!F15 -> 225.55595 | D9: =B9 -> 120.99759 | E9: =C9-B9 -> 104.55836 | F9: =(B9+C9)/2 -> 173.27677
A10: Trading comps — P/E (14–20x FY26E adj. EPS) | B10: =Comps!E16 -> 139.3 | C10: =Comps!F16 -> 199 | D10: =B10 -> 139.3 | E10: =C10-B10 -> 59.7 | F10: =(B10+C10)/2 -> 169.15
A11: Precedent transactions (7–9x FY26E EBITDA) | B11: =Precedents!B18 -> 79.174244 | C11: =Precedents!C18 -> 120.99759 | D11: =B11 -> 79.174244 | E11: =C11-B11 -> 41.823345 | F11: =(B11+C11)/2 -> 100.08592
A12: LBO capacity (25% → 15% IRR) | B12: =LBO!D46 -> 111.04817 | C12: =LBO!D44 -> 144.92714 | D12: =B12 -> 111.04817 | E12: =C12-B12 -> 33.878974 | F12: =(B12+C12)/2 -> 127.98765
A13: Monte Carlo P25–P75 (live) | B13: =Monte_Carlo!B25 -> 135.31043 | C13: =Monte_Carlo!B26 -> 200.52867 | D13: =B13 -> 135.31043 | E13: =C13-B13 -> 65.218239 | F13: =(B13+C13)/2 -> 167.91955
A14: Current price (marker) | B14: =Assumptions!B48-1.5 -> 153.94 | C14: =Assumptions!B48+1.5 -> 156.94 | D14: =B14 -> 153.94 | E14: =C14-B14 -> 3 | F14: =(B14+C14)/2 -> 155.44
A16: 52-wk range & analyst target: Alpha Vantage (target band ±~15%, estimated spread). All other rows are live model outputs.
